Workbook
Name _DLX1.USE: #REF!
Name _DLX2.USE: 'Monthly Haver'!$1:$4
Name _DLX3.USE: 'Quarterly Haver'!$A$1:$W$3

Sheet GDS_Monthly
A1: EcDatabase | B1: ID:GDS_LIVE | C1: ID:GDS_LIVE | D1: ID:GDS_LIVE | E1: ID:GDS_LIVE | F1: ID:GDS_LIVE | G1: ID:GDS_LIVE | H1: ID:GDS_LIVE | I1: ID:GDS_LIVE | J1: ID:GDS_LIVE | K1: ID:GDS_LIVE | L1: ID:GDS_LIVE | M1: ID:GDS_LIVE | N1: ID:GDS_LIVE | O1: ID:GDS_LIVE | P1: ID:GDS_LIVE | Q1: ID:GDS_LIVE | R1: ID:GDS_LIVE | S1: ID:GDS_LIVE | T1: ID:GDS_LIVE | U1: ID:GDS_LIVE | V1: ID:GDS_LIVE | W1: ID:GDS_LIVE | X1: ID:GDS_LIVE | Y1: ID:GDS_LIVE | Z1: ID:GDS_LIVE | AA1: ID:GDS_LIVE | AB1: ID:GDS_LIVE | AC1: ID:GDS_LIVE | AD1: ID:GDS_LIVE | AE1: ID:GDS_LIVE | AF1: ID:GDS_LIVE | AG1: ID:GDS_LIVE | AH1: ID:GDS_LIVE | AI1: ID:GDS_LIVE
A2: Series_code | B2: 001ACC_PPPWGT.M | C2: 001ACC.M | D2: 001AIP.M | E2: 001AIP_GDPWGT.M | F2: 001FIGB.M | G2: 001FIPR.M | H2: 001FISI.M | I2: 001FMB.M | J2: 001FMN.M | K2: 001FMSCID.M | L2: 001FMSCIL.M | M2: 001LE.M | N2: 001LUR.M | O2: 001NRS.M | P2: 001PALLFNFW.M | Q2: 001PBEVEW.M | R2: 001PCOALW.M | S2: 001PCPI.M | T2: 001PCPI_GDPWGT.M | U2: 001PCPIX.M | V2: 001.M | W2: 001PFOODW.M | X2: 001PMETAW.M | Y2: 001PMI.M | Z2: 001PMI_PPPWGT.M | AA2: 001PNFUELW.M | AB2: 001PNGASW.M | AC2: 001PNRGW.M | AD2: 001POILAPSP.M | AE2: 001POILAPSPW.M | AF2: 001PRAWMW.M | AG2: 001TG.M | AH2: 001TMG.M | AI2: 001TXG.M
A3: Country | B3: World | C3: World | D3: World | E3: World | F3: World | G3: World | H3: World | I3: World | J3: World | K3: World | L3: World | M3: World | N3: World | O3: World | P3: World | Q3: World | R3: World | S3: World | T3: World | U3: World | V3: World | W3: World | X3: World | Y3: World | Z3: World | AA3: World | AB3: World | AC3: World | AD3: World | AE3: World | AF3: World | AG3: World | AH3: World | AI3: World
A4: Country.Name | B4: World | C4: World | D4: World | E4: World | F4: World | G4: World | H4: World | I4: World | J4: World | K4: World | L4: World | M4: World | N4: World | O4: World | P4: World | Q4: World | R4: World | S4: World | T4: World | U4: World | V4: World | W4: World | X4: World | Y4: World | Z4: World | AA4: World | AB4: World | AC4: World | AD4: World | AE4: World | AF4: World | AG4: World | AH4: World | AI4: World
A5: Indicator | B5: ACC_PPPWGT | C5: ACC | D5: AIP | E5: AIP_GDPWGT | F5: FIGB | G5: FIPR | H5: FISI | I5: FMB | J5: FMN | K5: FMSCID | L5: FMSCIL | M5: LE | N5: LUR | O5: NRS | P5: PALLFNFW | Q5: PBEVEW | R5: PCOALW | S5: PCPI | T5: PCPI_GDPWGT | U5: PCPIX | V5: PCPIX_GDPWGT | W5: PFOODW | X5: PMETAW | Y5: PMI | Z5: PMI_PPPWGT | AA5: PNFUELW | AB5: PNGASW | AC5: PNRGW | AD5: POILAPSP | AE5: POILAPSPW | AF5: PRAWMW | AG5: TG | AH5: TMG | AI5: TXG
A6: Indicator.Code | B6: ACC_PPPWGT | C6: ACC | D6: AIP | E6: AIP_GDPWGT | F6: FIGB | G6: FIPR | H6: FISI | I6: FMB | J6: FMN | K6: FMSCID | L6: FMSCIL | M6: LE | N6: LUR | O6: NRS | P6: PALLFNFW | Q6: PBEVEW | R6: PCOALW | S6: PCPI | T6: PCPI_GDPWGT | U6: PCPIX | V6: PCPIX_GDPWGT | W6: PFOODW | X6: PMETAW | Y6: PMI | Z6: PMI_PPPWGT | AA6: PNFUELW | AB6: PNGASW | AC6: PNRGW | AD6: POILAPSP | AE6: POILAPSPW | AF6: PRAWMW | AG6: TG | AH6: TMG | AI6: TXG
A7: Indicator.Descriptor | B7: Consumer confidence, PPP weighted | C7: Consumer confidence | D7: Industrial production | E7: Industrial production, MER weighted | F7: Long-term interest rate | G7: Policy-related interest rate | H7: Benchmark stock market index | I7: Broad money | J7: Narrow money | K7: Morgan Stanley MSCI stock price index in US dollars | L7: Morgan Stanley MSCI stock price index in national currency | M7: Employment | N7: Unemployment rate | O7: Retail sales | P7: Commodity price: all primary commodities | Q7: Commodity price: beverage | R7: Commodity price: coal | S7: Consumer price index | T7: Consumer price index, MER weighted | U7: Core consumer price index | V7: Core consumer price index, GDP weighted | W7: Commodity price: food | X7: Commodity price: metals | Y7: Manufacturing PMI | Z7: Manufacturing PMI, PPP weighted | AA7: Commodity price: non-fuel primary commodities | AB7: Commodity price: natural gas | AC7: Commodity price: energy | AD7: Commodity price: petroleum, US dollar per barrel | AE7: Commodity price: petroleum | AF7: Commodity price: raw materials | AG7: Merchandise trade balance | AH7: Merchandise imports | AI7: Merchandise exports
A8: Frequency | B8: Monthly | C8: Monthly | D8: Monthly | E8: Monthly | F8: Monthly | G8: Monthly | H8: Monthly | I8: Monthly | J8: Monthly | K8: Monthly | L8: Monthly | M8: Monthly | N8: Monthly | O8: Monthly | P8: Monthly | Q8: Monthly | R8: Monthly | S8: Monthly | T8: Monthly | U8: Monthly | V8: Monthly | W8: Monthly | X8: Monthly | Y8: Monthly | Z8: Monthly | AA8: Monthly | AB8: Monthly | AC8: Monthly | AD8: Monthly | AE8: Monthly | AF8: Monthly | AG8: Monthly | AH8: Monthly | AI8: Monthly
A9: Scale | B9: Units | C9: Units | D9: Units | E9: Units | F9: Units | G9: Units | H9: Units | I9: Units | J9: Units | K9: Units | L9: Units | M9: Units | N9: Units | O9: Units | P9: Units | Q9: Units | R9: Units | S9: Units | T9: Units | U9: Units | V9: Units | W9: Units | X9: Units | Y9: Units | Z9: Units | AA9: Units | AB9: Units | AC9: Units | AD9: Units | AE9: Units | AF9: Units | AG9: Billions | AH9: Billions | AI9: Billions
A10: Display_scale | B10: Units | C10: Units | D10: Units | E10: Units | F10: Units | G10: Units | H10: Units | I10: Units | J10: Units | K10: Units | L10: Units | M10: Units | N10: Units | O10: Units | P10: Units | Q10: Units | R10: Units | S10: Units | T10: Units | U10: Units | V10: Units | W10: Units | X10: Units | Y10: Units | Z10: Units | AA10: Units | AB10: Units | AC10: Units | AD10: Units | AE10: Units | AF10: Units | AG10: Billions | AH10: Billions | AI10: Billions
A11: 1990M1 | B11: 114.51447 | C11: 123.71968 | D11: 49.314021 | E11: 63.283681 | F11: 8.3226593 | G11: 12.045953 | H11: 23.824297 | I11: 9.7869901 | J11: 10.812177 | K11: 27.286642 | L11: 17.279753 | N11: 3.3681693 | O11: 29.881555 | Q11: 49.20388 | R11: 51.172528 | S11: 11.330093 | T11: 29.868828 | U11: 46.254719 | V11: 57.548318 | AD11: 20.59 | AF11: 72.855085 | AG11: -5.0989287 | AH11: 196.4791 | AI11: 191.38017
A12: 1990M2 | B12: 114.56883 | C12: 123.76391 | D12: 49.545754 | E12: 63.624021 | F12: 8.5690154 | G12: 12.81087 | H12: 23.578783 | I12: 9.9383907 | J12: 10.892539 | K12: 26.768089 | L12: 17.860288 | N12: 3.3647859 | O12: 29.773219 | Q12: 49.947777 | R12: 51.172528 | S12: 11.459084 | T12: 30.157159 | U12: 46.445228 | V12: 57.787069 | AD12: 19.68 | AF12: 73.449658 | AG12: -2.6458987 | AH12: 193.39879 | AI12: 190.75289
A13: 1990M3 | B13: 115.36045 | C13: 125.23019 | D13: 49.770933 | E13: 64.172551 | F13: 8.8628869 | G13: 13.736319 | H13: 23.145268 | I13: 10.025448 | J13: 11.045264 | K13: 25.142776 | L13: 17.109457 | N13: 3.3460685 | O13: 30.118877 | Q13: 54.434712 | R13: 51.172528 | S13: 12.108967 | T13: 31.348698 | U13: 46.659986 | V13: 58.058774 | AD13: 18.12 | AF13: 74.172077 | AG13: -4.3970504 | AH13: 195.45892 | AI13: 191.06187
A14: 1990M4 | B14: 114.40041 | C14: 123.47383 | D14: 49.2027 | E14: 63.628984 | F14: 9.0530661 | G14: 10.215748 | H14: 22.576919 | I14: 10.161297 | J14: 11.194639 | K14: 25.180263 | L14: 17.192183 | N14: 3.39898 | O14: 29.971872 | Q14: 56.292064 | R14: 51.172528 | S14: 12.206263 | T14: 31.54256 | U14: 46.862083 | V14: 58.285526 | AD14: 16.32 | AF14: 76.022077 | AG14: -4.9160552 | AH14: 193.01728 | AI14: 188.10122
A15: 1990M5 | B15: 114.28377 | C15: 123.30754 | D15: 49.81236 | E15: 64.208728 | F15: 8.8850104 | G15: 9.8632439 | H15: 24.766186 | I15: 10.22205 | J15: 11.257825 | K15: 27.694036 | L15: 18.723435 | N15: 3.4184704 | O15: 30.197059 | Q15: 55.920823 | R15: 54.120417 | S15: 12.317709 | T15: 31.781257 | U15: 47.043499 | V15: 58.479016 | AD15: 16.21 | AF15: 75.418959 | AG15: -5.4187923 | AH15: 200.10086 | AI15: 194.68207
A16: 1990M6 | B16: 113.07135 | C16: 121.14802 | D16: 49.878132 | E16: 64.441221 | F16: 8.6778093 | G16: 10.141767 | H16: 24.52828 | I16: 10.313142 | J16: 11.35778 | K16: 27.336733 | L16: 18.433619 | N16: 3.406569 | O16: 30.460312 | Q16: 53.061015 | R16: 55.284677 | S16: 12.435436 | T16: 32.039774 | U16: 47.274781 | V16: 58.742454 | AD16: 14.93 | AF16: 75.563455 | AG16: -1.0477499 | AH16: 194.0062 | AI16: 192.95845
A17: 1990M7 | B17: 113.03171 | C17: 121.02093 | D17: 49.968687 | E17: 64.443695 | F17: 8.7393347 | G17: 9.9570955 | H17: 24.725588 | I17: 10.396776 | J17: 11.394999 | K17: 27.747213 | L17: 18.522206 | N17: 3.4265965 | O17: 30.542755 | Q17: 52.830834 | R17: 55.284677 | S17: 12.811723 | T17: 32.731921 | U17: 47.47904 | V17: 59.005804 | AD17: 16.81 | AF17: 76.236284 | AG17: -4.545488 | AH17: 199.83838 | AI17: 195.29289
A18: 1990M8 | B18: 108.35276 | C18: 112.91167 | D18: 50.208904 | E18: 64.729208 | F18: 9.1108035 | G18: 9.7702121 | H18: 22.248447 | I18: 10.492068 | J18: 11.497265 | K18: 25.111373 | L18: 16.691811 | N18: 3.4585306 | O18: 30.707238 | Q18: 54.507742 | R18: 55.284677 | S18: 13.09815 | T18: 33.404447 | U18: 47.729603 | V18: 59.320537 | AD18: 26.54 | AF18: 73.868209 | AG18: -7.586449 | AH18: 209.52499 | AI18: 202.41924
A19: 1990M9 | B19: 108.06044 | C19: 113.24927 | D19: 50.250207 | E19: 64.604251 | F19: 9.3294111 | G19: 10.46494 | H19: 20.322 | I19: 10.58601 | J19: 11.564105 | K19: 22.81548 | L19: 15.093753 | N19: 3.5072531 | O19: 30.819715 | Q19: 56.439606 | R19: 55.284677 | S19: 13.418738 | T19: 33.998772 | U19: 47.946922 | V19: 59.545981 | AD19: 33.62 | AF19: 73.204601 | AG19: -4.7038541 | AH19: 208.21249 | AI19: 203.97223
A20: 1990M10 | B20: 101.78818 | C20: 102.33262 | D20: 50.333904 | E20: 64.725252 | F20: 9.1281229 | G20: 9.8990985 | H20: 21.412596 | I20: 10.651504 | J20: 11.621382 | K20: 24.125008 | L20: 15.74034 | N20: 3.5349291 | O20: 31.008903 | Q20: 56.63649 | R20: 55.284677 | S20: 13.564987 | T20: 34.330378 | U20: 48.174506 | V20: 59.77075 | AD20: 34.85 | AF20: 73.155127 | AG20: -11.467118 | AH20: 224.83538 | AI20: 213.84766
A21: 1990M11 | B21: 101.68224 | C21: 101.92072 | D21: 49.957397 | E21: 64.289731 | F21: 8.7570808 | G21: 9.4100861 | H21: 21.392254 | I21: 10.699151 | J21: 11.715121 | K21: 24.145783 | L21: 16.023042 | N21: 3.5749406 | O21: 31.303291 | Q21: 55.621551 | R21: 55.284677 | S21: 13.810246 | T21: 34.781365 | U21: 48.374754 | V21: 59.974347 | AD21: 31.54 | AF21: 73.029421 | AG21: -12.769871 | AH21: 226.23958 | AI21: 213.89971
A22: 1990M12 | B22: 101.82957 | C22: 102.11802 | D22: 49.836694 | E22: 63.94567 | F22: 8.3653919 | G22: 9.1414919 | H22: 22.023779 | I22: 10.770466 | J22: 11.834423 | K22: 24.648403 | L22: 16.536699 | N22: 3.58973 | O22: 31.070077 | Q22: 55.882156 | R22: 55.284677 | S22: 14.026271 | T22: 35.171117 | U22: 48.597067 | V22: 60.224917 | AD22: 26.61 | AF22: 72.658165 | AG22: -6.735854 | AH22: 214.51252 | AI22: 208.21067
A23: 1991M1 | B23: 99.960835 | C23: 99.091477 | D23: 50.690885 | E23: 63.863824 | F23: 8.3127577 | G23: 9.4109205 | H23: 22.204286 | I23: 10.845284 | J23: 11.924376 | K23: 25.859673 | L23: 17.532073 | N23: 3.8666487 | O23: 31.097388 | Q23: 54.152241 | R23: 55.284677 | S23: 14.238246 | T23: 35.622741 | U23: 48.915663 | V23: 60.632197 | AD23: 22.81 | AE23: 51.895164 | AF23: 71.245906 | AG23: -10.098748 | AH23: 225.31323 | AI23: 215.61888
A24: 1991M2 | B24: 101.03893 | C24: 101.0196 | D24: 50.492965 | E24: 63.736862 | F24: 8.0389408 | G24: 9.5803252 | H24: 24.214526 | I24: 10.916885 | J24: 12.072768 | K24: 28.235656 | L24: 19.274861 | N24: 3.9289311 | O24: 31.377597 | Q24: 52.871024 | R24: 55.284677 | S24: 14.465398 | T24: 36.049568 | U24: 49.158243 | V24: 60.915172 | AD24: 18.53 | AE24: 41.623317 | AF24: 72.488907 | AG24: -8.1623706 | AH24: 218.7352 | AI24: 210.92063
A25: 1991M3 | B25: 107.20276 | C25: 111.48343 | D25: 50.251606 | E25: 63.402296 | F25: 8.2382637 | G25: 9.1798236 | H25: 24.496246 | I25: 10.984087 | J25: 12.154684 | K25: 28.011989 | L25: 19.681913 | N25: 4.016352 | O25: 31.549621 | Q25: 53.016481 | R25: 52.242706 | S25: 14.631409 | T25: 36.346553 | U25: 49.326401 | V25: 61.099826 | AD25: 18.21 | AE25: 42.713082 | AF25: 71.063991 | AG25: -4.8204298 | AH25: 210.00065 | AI25: 205.54752
A26: 1991M4 | B26: 106.66854 | C26: 110.68466 | D26: 50.221557 | E26: 63.513692 | F26: 8.1907168 | G26: 7.9350571 | H26: 24.51462 | I26: 11.055672 | J26: 12.235676 | K26: 28.234682 | L26: 19.83188 | N26: 4.033192 | O26: 31.913959 | Q26: 52.103358 | R26: 52.242706 | S26: 14.812783 | T26: 36.689325 | U26: 49.487843 | V26: 61.238237 | AD26: 18.49 | AE26: 44.273197 | AF26: 71.897367 | AG26: -5.2155274 | AH26: 206.23704 | AI26: 201.35451
A27: 1991M5 | B27: 105.86811 | C27: 109.12219 | D27: 50.431897 | E27: 64.015328 | F27: 8.1924619 | G27: 7.7615281 | H27: 25.179714 | I27: 11.138187 | J27: 12.38858 | K27: 29.220117 | L27: 20.666074 | N27: 4.076692 | O27: 32.011864 | Q27: 48.774236 | R27: 52.242706 | S27: 14.924991 | T27: 36.915591 | U27: 49.747303 | V27: 61.491385 | AD27: 18.72 | AE27: 45.108066 | AF27: 72.823651 | AG27: -5.3642246 | AH27: 210.08883 | AI27: 205.10011
A28: 1991M6 | B28: 106.18169 | C28: 109.95012 | D28: 50.63893 | E28: 63.818321 | F28: 8.381082 | G28: 7.7948896 | H28: 23.917544 | I28: 11.203662 | J28: 12.516554 | K28: 27.643224 | L28: 19.752751 | N28: 4.022414 | O28: 32.074732 | Q28: 47.46047 | R28: 52.242706 | S28: 15.102044 | T28: 37.22634 | U28: 49.974251 | V28: 61.729571 | AD28: 17.78 | AE28: 43.608103 | AF28: 74.039224 | AG28: -2.8746617 | AH28: 204.50807 | AI28: 201.93531
A29: 1991M7 | B29: 105.88541 | C29: 109.83381 | D29: 50.809317 | E29: 64.360601 | F29: 8.3325159 | G29: 7.6141335 | H29: 25.057386 | I29: 11.261497 | J29: 12.609906 | K29: 28.954028 | L29: 20.668506 | N29: 3.9265021 | O29: 32.333574 | Q29: 45.930383 | R29: 52.242706 | S29: 15.340976 | T29: 37.603533 | U29: 50.218062 | V29: 61.963891 | AD29: 19.02 | AE29: 46.598285 | AF29: 72.267005 | AG29: -6.6202743 | AH29: 211.16653 | AI29: 204.86976
A30: 1991M8 | B30: 105.43865 | C30: 109.20281 | D30: 50.642768 | E30: 64.104194 | F30: 8.040318 | G30: 7.4911521 | H30: 25.020917 | I30: 11.294781 | J30: 12.744968 | K30: 29.009034 | L30: 20.776685 | N30: 3.9748681 | O30: 32.368659 | Q30: 47.387427 | R30: 52.242706 | S30: 15.543876 | T30: 37.96973 | U30: 50.395713 | V30: 62.163604 | AD30: 19.3 | AE30: 46.77816 | AF30: 71.029708 | AG30: -4.4308916 | AH30: 210.98184 | AI30: 206.86245
A31: 1991M9 | B31: 104.8829 | C31: 107.9292 | D31: 50.759856 | E31: 64.363144 | F31: 7.7839714 | G31: 7.1515831 | H31: 25.319556 | I31: 11.350167 | J31: 12.851402 | K31: 29.226159 | L31: 20.828689 | N31: 4.0137633 | O31: 32.238535 | Q31: 50.699127 | R31: 52.242706 | S31: 15.704071 | T31: 38.241923 | U31: 50.594096 | V31: 62.411444 | AD31: 19.95 | AE31: 47.725344 | AF31: 71.490928 | AG31: -4.6822569 | AH31: 213.89908 | AI31: 209.49943
A32: 1991M10 | B32: 101.47869 | C32: 102.02613 | D32: 50.954508 | E32: 64.432804 | F32: 7.6423132 | G32: 7.0088647 | H32: 26.083115 | I32: 11.419729 | J32: 13.112368 | K32: 29.761164 | L32: 21.347691 | N32: 4.0191231 | O32: 32.422264 | Q32: 49.690825 | R32: 52.242706 | S32: 16.011123 | T32: 38.781758 | U32: 50.80609 | V32: 62.592083 | AD32: 21.56 | AE32: 51.2623 | AF32: 70.083241 | AG32: -3.9720873 | AH32: 217.37481 | AI32: 213.69783
A33: 1991M11 | B33: 99.476793 | C33: 98.517708 | D33: 50.948449 | E33: 64.369259 | F33: 7.5587706 | G33: 6.7459753 | H33: 24.611455 | I33: 11.487376 | J33: 13.288647 | K33: 28.427307 | L33: 20.461845 | N33: 4.0445707 | O33: 32.675094 | Q33: 51.331064 | R33: 52.242706 | S33: 16.270673 | T33: 39.286515 | U33: 51.024322 | V33: 62.82661 | AD33: 20.41 | AE33: 47.715173 | AF33: 68.819061 | AG33: -1.2702288 | AH33: 220.30186 | AI33: 219.36413
A34: 1991M12 | B34: 99.17882 | C34: 98.230013 | D34: 50.550454 | E34: 63.8663 | F34: 7.3015267 | G34: 6.4390198 | H34: 26.040758 | I34: 11.56187 | J34: 13.443819 | K34: 30.888271 | L34: 22.173155 | N34: 4.0659031 | O34: 32.366365 | Q34: 51.101844 | R34: 52.242706 | S34: 16.499304 | T34: 39.654581 | U34: 51.207614 | V34: 63.009806 | AD34: 17.63 | AE34: 40.52036 | AF34: 68.755252 | AG34: -2.0773755 | AH34: 220.15934 | AI34: 218.53137
A35: 1992M1 | B35: 98.43744 | C35: 96.893226 | D35: 50.816128 | E35: 63.778893 | F35: 7.1707613 | G35: 6.1287495 | H35: 26.528001 | I35: 11.614751 | J35: 13.649309 | K35: 30.935051 | L35: 22.628232 | N35: 4.1340025 | O35: 33.063355 | P35: 50.724146 | Q35: 48.467677 | R35: 52.242706 | S35: 18.915604 | T35: 39.996447 | U35: 51.373227 | V35: 63.176637 | W35: 67.512992 | X35: 46.948673 | AA35: 54.673375 | AB35: 54.51602 | AC35: 45.011688 | AD35: 17.52 | AE35: 40.225371 | AF35: 67.201791 | AG35: -3.5530929 | AH35: 223.10482 | AI35: 219.79732
A36: 1992M2 | B36: 97.922398 | C36: 95.813936 | D36: 51.013894 | E36: 63.993521 | F36: 7.3542937 | G36: 6.146693 | H36: 26.58258 | I36: 11.688174 | J36: 13.83816 | K36: 30.20739 | L36: 22.483462 | N36: 4.2763571 | O36: 33.548092 | P36: 50.722601 | Q36: 44.121634 | R36: 52.242706 | S36: 19.510749 | T36: 40.414001 | U36: 51.519711 | V36: 63.338763 | W36: 68.127248 | X36: 48.319412 | AA36: 55.120695 | AB36: 49.91186 | AC36: 44.36087 | AD36: 17.65 | AE36: 41.089686 | AF36: 68.202929 | AG36: -0.23245782 | AH36: 226.38648 | AI36: 226.50532
A37: 1992M3 | B37: 100.29176 | C37: 100.20242 | D37: 51.080618 | E37: 64.082475 | F37: 7.4881734 | G37: 6.131411 | H37: 25.969368 | I37: 11.738885 | J37: 14.005233 | K37: 29.051359 | L37: 21.988755 | N37: 4.2955163 | O37: 33.187242 | P37: 50.748701 | Q37: 44.006519 | R37: 52.242706 | S37: 20.135137 | T37: 40.80532 | U37: 51.756851 | V37: 63.590036 | W37: 69.04621 | X37: 48.220121 | AA37: 55.400467 | AB37: 50.533712 | AC37: 44.020041 | AD37: 17.35 | AE37: 41.165326 | AF37: 68.573076 | AG37: -2.960825 | AH37: 222.51376 | AI37: 219.88733
A38: 1992M4 | B38: 102.60534 | C38: 104.40873 | D38: 51.168299 | E38: 64.314997 | F38: 7.4644856 | G38: 5.7836822 | H38: 25.938185 | I38: 11.778921 | J38: 14.140455 | K38: 29.217931 | L38: 22.262401 | N38: 4.2812865 | O38: 33.384379 | P38: 51.1747 | Q38: 42.97254 | R38: 52.242706 | S38: 20.692425 | T38: 41.208527 | U38: 51.933629 | V38: 63.769895 | W38: 66.211724 | X38: 48.628629 | AA38: 54.364444 | AB38: 51.972758 | AC38: 46.560816 | AD38: 18.65 | AE38: 44.087573 | AF38: 72.508877 | AG38: -4.2078461 | AH38: 227.29775 | AI38: 223.4572
A39: 1992M5 | B39: 104.41226 | C39: 107.62821 | D39: 50.909706 | E39: 63.897892 | F39: 7.3533654 | G39: 5.7156343 | H39: 26.340449 | I39: 11.818255 | J39: 14.286668 | K39: 30.002591 | L39: 22.667576 | N39: 4.3508526 | O39: 33.433189 | P39: 52.635726 | Q39: 40.89879 | R39: 52.242706 | S39: 21.291126 | T39: 41.675494 | U39: 52.132857 | V39: 63.966218 | W39: 68.556314 | X39: 48.605568 | AA39: 55.424397 | AB39: 54.754973 | AC39: 48.601984 | AD39: 19.52 | AE39: 45.566176 | AF39: 72.273732 | AG39: -2.7445031 | AH39: 226.48888 | AI39: 224.05928
A40: 1992M6 | B40: 104.55227 | C40: 107.72247 | D40: 51.036245 | E40: 64.354112 | F40: 7.2689456 | G40: 5.702697 | H40: 24.879787 | I40: 11.858085 | J40: 14.372014 | K40: 28.651934 | L40: 21.559301 | N40: 4.2646222 | O40: 33.545854 | P40: 52.852571 | Q40: 39.672732 | R40: 50.690361 | S40: 21.928336 | T40: 42.082036 | U40: 52.299533 | V40: 64.14325 | W40: 65.571299 | X40: 48.725491 | AA40: 54.07814 | AB40: 55.870772 | AC40: 51.079817 | AD40: 20.88 | AE40: 47.918269 | AF40: 72.802168 | AG40: -6.8749301 | AH40: 236.27184 | AI40: 229.39691
...

Sheet OECD
B1: OECDCLI | C1: CHEM
A2: ='Monthly Haver'!A5 -> Jan-1999 | B2: 99.47476 | C2: 95.61
A3: ='Monthly Haver'!A6 -> Feb-1999 | B3: 99.66687 | C3: 96.34
A4: ='Monthly Haver'!A7 -> Mar-1999 | B4: 99.85615 | C4: 96.64
A5: ='Monthly Haver'!A8 -> Apr-1999 | B5: 100.0378 | C5: 97.25
A6: ='Monthly Haver'!A9 -> May-1999 | B6: 100.2077 | C6: 98.12
A7: ='Monthly Haver'!A10 -> Jun-1999 | B7: 100.3658 | C7: 98.7
A8: ='Monthly Haver'!A11 -> Jul-1999 | B8: 100.5119 | C8: 98.78
A9: ='Monthly Haver'!A12 -> Aug-1999 | B9: 100.6493 | C9: 98.8
A10: ='Monthly Haver'!A13 -> Sep-1999 | B10: 100.7834 | C10: 98.59
A11: ='Monthly Haver'!A14 -> Oct-1999 | B11: 100.92 | C11: 99.03
A12: ='Monthly Haver'!A15 -> Nov-1999 | B12: 101.0557 | C12: 100.26
A13: ='Monthly Haver'!A16 -> Dec-1999 | B13: 101.1789 | C13: 100.67
... A246: ='Monthly Haver'!A249 -> May-2019 | B246: 99.0301 | C246: 122.38
A247: ='Monthly Haver'!A250 -> Jun-2019 | C247: 122.19

Sheet GDS_Quarterly
A1: EcDatabase | B1: ID:GDS_LIVE | C1: ID:GDS_LIVE | D1: ID:GDS_LIVE | E1: ID:GDS_LIVE | F1: ID:GDS_LIVE | G1: ID:GDS_LIVE | H1: ID:GDS_LIVE | I1: ID:GDS_LIVE | J1: ID:GDS_LIVE | K1: ID:GDS_LIVE | L1: ID:GDS_LIVE | M1: ID:GDS_LIVE | N1: ID:GDS_LIVE | O1: ID:GDS_LIVE | P1: ID:GDS_LIVE | Q1: ID:GDS_LIVE | R1: ID:GDS_LIVE | S1: ID:GDS_LIVE | T1: ID:GDS_LIVE | U1: ID:GDS_LIVE | V1: ID:GDS_LIVE | W1: ID:GDS_LIVE | X1: ID:GDS_LIVE | Y1: ID:GDS_LIVE | Z1: ID:GDS_LIVE | AA1: ID:GDS_LIVE | AB1: ID:GDS_LIVE | AC1: ID:GDS_LIVE | AD1: ID:GDS_LIVE | AE1: ID:GDS_LIVE | AF1: ID:GDS_LIVE | AG1: ID:GDS_LIVE | AH1: ID:GDS_LIVE | AI1: ID:GDS_LIVE | AJ1: ID:GDS_LIVE | AK1: ID:GDS_LIVE | AL1: ID:GDS_LIVE | AM1: ID:GDS_LIVE | AN1: ID:GDS_LIVE | AO1: ID:GDS_LIVE | AP1: ID:GDS_LIVE | AQ1: ID:GDS_LIVE | AR1: ID:GDS_LIVE | AS1: ID:GDS_LIVE | AT1: ID:GDS_LIVE | AU1: ID:GDS_LIVE | AV1: ID:GDS_LIVE | AW1: ID:GDS_LIVE | AX1: ID:GDS_LIVE | AY1: ID:GDS_LIVE | AZ1: ID:GDS_LIVE | BA1: ID:GDS_LIVE | BB1: ID:GDS_LIVE | BC1: ID:GDS_LIVE
A2: Series_code | B2: 001ACC_PPPWGT.Q | C2: 001ACC.Q | D2: 001AIP.Q | E2: 001AIP_GDPWGT.Q | F2: 001BCA.Q | G2: 001BCA_GDP.Q | H2: 001FIGB.Q | I2: 001FIPR.Q | J2: 001FISI.Q | K2: 001FMB.Q | L2: 001FMN.Q | M2: 001FMSCID.Q | N2: 001FMSCIL.Q | O2: 001LE.Q | P2: 001LUR.Q | Q2: 001NCP_R.Q | R2: 001NCP_R_GDPWGT.Q | S2: 001NFI_R.Q | T2: 001NFI_R_GDPWGT.Q | U2: 001NGDP_R.Q | V2: 001NGDP_R_GDPWGT.Q | W2: 001NGDP_RF.Q | X2: 001NGDP_RF_GDPWGT.Q | Y2: 001NGDPD.Q | Z2: 001NM_R.Q | AA2: 001NM_R_GDPWGT.Q | AB2: 001NM_R_TMWGT.Q | AC2: 001NRS.Q | AD2: 001NTDD_R.Q | AE2: 001NTDD_R_GDPWGT.Q | AF2: 001NX_R.Q | AG2: 001NX_R_GDPWGT.Q | AH2: 001NX_R_TXWGT.Q | AI2: 001PALLFNFW.Q | AJ2: 001PBEVEW.Q | AK2: 001PCOALW.Q | AL2: 001PCPI.Q | AM2: 001PCPI_GDPWGT.Q | AN2: 001PCPIF.Q | AO2: 001PCPIX.Q | AP2: 001.Q | AQ2: 001PFOODW.Q | AR2: 001PMETAW.Q | AS2: 001PMI.Q | AT2: 001PMI_PPPWGT.Q | AU2: 001PNFUELW.Q | AV2: 001PNGASW.Q | AW2: 001PNRGW.Q | AX2: 001POILAPSP.Q | AY2: 001POILAPSPW.Q | AZ2: 001PRAWMW.Q | BA2: 001TG.Q | BB2: 001TMG.Q | BC2: 001TXG.Q
A3: Country | B3: World | C3: World | D3: World | E3: World | F3: World | G3: World | H3: World | I3: World | J3: World | K3: World | L3: World | M3: World | N3: World | O3: World | P3: World | Q3: World | R3: World | S3: World | T3: World | U3: World | V3: World | W3: World | X3: World | Y3: World | Z3: World | AA3: World | AB3: World | AC3: World | AD3: World | AE3: World | AF3: World | AG3: World | AH3: World | AI3: World | AJ3: World | AK3: World | AL3: World | AM3: World | AN3: World | AO3: World | AP3: World | AQ3: World | AR3: World | AS3: World | AT3: World | AU3: World | AV3: World | AW3: World | AX3: World | AY3: World | AZ3: World | BA3: World | BB3: World | BC3: World
A4: Indicator | B4: ACC_PPPWGT | C4: ACC | D4: AIP | E4: AIP_GDPWGT | F4: BCA | G4: BCA_GDP | H4: FIGB | I4: FIPR | J4: FISI | K4: FMB | L4: FMN | M4: FMSCID | N4: FMSCIL | O4: LE | P4: LUR | Q4: NCP_R | R4: NCP_R_GDPWGT | S4: NFI_R | T4: NFI_R_GDPWGT | U4: NGDP_R | V4: NGDP_R_GDPWGT | W4: NGDP_RF | X4: NGDP_RF_GDPWGT | Y4: NGDPD | Z4: NM_R | AA4: NM_R_GDPWGT | AB4: NM_R_TMWGT | AC4: NRS | AD4: NTDD_R | AE4: NTDD_R_GDPWGT | AF4: NX_R | AG4: NX_R_GDPWGT | AH4: NX_R_TXWGT | AI4: PALLFNFW | AJ4: PBEVEW | AK4: PCOALW | AL4: PCPI | AM4: PCPI_GDPWGT | AN4: PCPIF | AO4: PCPIX | AP4: PCPIX_GDPWGT | AQ4: PFOODW | AR4: PMETAW | AS4: PMI | AT4: PMI_PPPWGT | AU4: PNFUELW | AV4: PNGASW | AW4: PNRGW | AX4: POILAPSP | AY4: POILAPSPW | AZ4: PRAWMW | BA4: TG | BB4: TMG | BC4: TXG
A5: Indicator.Descriptor | B5: Consumer confidence, PPP weighted | C5: Consumer confidence | D5: Industrial production | E5: Industrial production, MER weighted | F5: Current account balance | G5: Current account balance, percent of GDP | H5: Long-term interest rate | I5: Policy-related interest rate | J5: Benchmark stock market index | K5: Broad money | L5: Narrow money | M5: Morgan Stanley MSCI stock price index in US dollars | N5: Morgan Stanley MSCI stock price index in national currency | O5: Employment | P5: Unemployment rate | Q5: Real private consumption | R5: Real private consumption, MER weighted | S5: Real gross fixed capital formation | T5: Real gross fixed capital formation, MER weighted | U5: Real gross domestic product | V5: Real gross domestic product, MER weighted | W5: Real gross domestic product, with projections from WEO | X5: Real gross domestic product, with projections from WEO, MER weighted | Y5: Nominal gross domestic product, US dollars | Z5: Real imports | AA5: Real imports, MER weighted | AB5: Real imports, imports weighted | AC5: Retail sales | AD5: Real total domestic demand | AE5: Real total domestic demand, MER weighted | AF5: Real exports | AG5: Real exports, MER weighted | AH5: Real exports, exports weighted | AI5: Commodity price: all primary commodities | AJ5: Commodity price: beverage | AK5: Commodity price: coal | AL5: Consumer price index | AM5: Consumer price index, MER weighted | AN5: Consumer price index, with projections from WEO | AO5: Core consumer price index | AP5: Core consumer price index, GDP weighted | AQ5: Commodity price: food | AR5: Commodity price: metals | AS5: Manufacturing PMI | AT5: Manufacturing PMI, PPP weighted | AU5: Commodity price: non-fuel primary commodities | AV5: Commodity price: natural gas | AW5: Commodity price: energy | AX5: Commodity price: petroleum, US dollar per barrel | AY5: Commodity price: petroleum | AZ5: Commodity price: raw materials | BA5: Merchandise trade balance | BB5: Merchandise imports | BC5: Merchandise exports
A6: Frequency | B6: Quarterly | C6: Quarterly | D6: Quarterly | E6: Quarterly | F6: Quarterly | G6: Quarterly | H6: Quarterly | I6: Quarterly | J6: Quarterly | K6: Quarterly | L6: Quarterly | M6: Quarterly | N6: Quarterly | O6: Quarterly | P6: Quarterly | Q6: Quarterly | R6: Quarterly | S6: Quarterly | T6: Quarterly | U6: Quarterly | V6: Quarterly | W6: Quarterly | X6: Quarterly | Y6: Quarterly | Z6: Quarterly | AA6: Quarterly | AB6: Quarterly | AC6: Quarterly | AD6: Quarterly | AE6: Quarterly | AF6: Quarterly | AG6: Quarterly | AH6: Quarterly | AI6: Quarterly | AJ6: Quarterly | AK6: Quarterly | AL6: Quarterly | AM6: Quarterly | AN6: Quarterly | AO6: Quarterly | AP6: Quarterly | AQ6: Quarterly | AR6: Quarterly | AS6: Quarterly | AT6: Quarterly | AU6: Quarterly | AV6: Quarterly | AW6: Quarterly | AX6: Quarterly | AY6: Quarterly | AZ6: Quarterly | BA6: Quarterly | BB6: Quarterly | BC6: Quarterly
A7: Scale | B7: Units | C7: Units | D7: Units | E7: Units | F7: Billions | G7: Units | H7: Units | I7: Units | J7: Units | K7: Units | L7: Units | M7: Units | N7: Units | O7: Units | P7: Units | Q7: Units | R7: Units | S7: Units | T7: Units | U7: Units | V7: Units | W7: Units | X7: Units | Y7: Billions | Z7: Units | AA7: Units | AB7: Units | AC7: Units | AD7: Units | AE7: Units | AF7: Units | AG7: Units | AH7: Units | AI7: Units | AJ7: Units | AK7: Units | AL7: Units | AM7: Units | AN7: Units | AO7: Units | AP7: Units | AQ7: Units | AR7: Units | AS7: Units | AT7: Units | AU7: Units | AV7: Units | AW7: Units | AX7: Units | AY7: Units | AZ7: Units | BA7: Billions | BB7: Billions | BC7: Billions
A8: Display_scale | B8: Units | C8: Units | D8: Units | E8: Units | F8: Billions | G8: Units | H8: Units | I8: Units | J8: Units | K8: Units | L8: Units | M8: Units | N8: Units | O8: Units | P8: Units | Q8: Units | R8: Units | S8: Units | T8: Units | U8: Units | V8: Units | W8: Units | X8: Units | Y8: Billions | Z8: Units | AA8: Units | AB8: Units | AC8: Units | AD8: Units | AE8: Units | AF8: Units | AG8: Units | AH8: Units | AI8: Units | AJ8: Units | AK8: Units | AL8: Units | AM8: Units | AN8: Units | AO8: Units | AP8: Units | AQ8: Units | AR8: Units | AS8: Units | AT8: Units | AU8: Units | AV8: Units | AW8: Units | AX8: Units | AY8: Units | AZ8: Units | BA8: Billions | BB8: Billions | BC8: Billions
A9: 1990Q1 | B9: 114.81458 | C9: 124.23793 | D9: 49.543569 | E9: 63.693418 | F9: -39.255759 | G9: -1.1070738 | H9: 8.5848539 | I9: 12.864381 | J9: 23.145268 | K9: 10.025448 | L9: 11.045264 | M9: 25.142776 | N9: 17.109457 | P9: 3.3596746 | Q9: 47.213154 | R9: 56.509996 | S9: 43.033553 | T9: 60.016458 | U9: 48.867596 | V9: 58.366689 | W9: 49.847183 | X9: 58.892925 | Y9: 3545.9027 | Z9: 22.176265 | AA9: 30.685512 | AB9: 29.593931 | AC9: 29.924551 | AD9: 48.72105 | AE9: 58.87154 | AF9: 24.032993 | AG9: 30.286245 | AH9: 29.10378 | AJ9: 51.195456 | AK9: 51.172528 | AL9: 11.632715 | AM9: 30.458228 | AN9: 4.4961391 | AO9: 46.453311 | AP9: 57.798054 | AX9: 19.463333 | AZ9: 73.492273 | BA9: -12.141878 | BB9: 585.33681 | BC9: 573.19493
A10: 1990Q2 | B10: 113.91851 | C10: 122.64313 | D10: 49.631064 | E10: 64.092978 | F10: -31.430276 | G10: -0.88760047 | H10: 8.8719619 | I10: 10.073586 | J10: 24.52828 | K10: 10.313142 | L10: 11.35778 | M10: 27.336733 | N10: 18.433619 | P10: 3.4080065 | Q10: 47.754054 | R10: 57.172254 | S10: 42.616422 | T10: 59.619449 | U10: 49.095601 | V10: 58.814317 | W10: 50.04317 | X10: 59.334551 | Y10: 3541.0387 | Z10: 22.257271 | AA10: 30.836931 | AB10: 29.805988 | AC10: 30.209748 | AD10: 49.140282 | AE10: 59.414058 | AF10: 24.166015 | AG10: 30.66399 | AH10: 29.386309 | AJ10: 55.091301 | AK10: 53.525874 | AL10: 12.319803 | AM10: 31.787864 | AN10: 4.8678908 | AO10: 47.060121 | AP10: 58.502332 | AX10: 15.82 | AZ10: 75.668164 | BA10: -11.382597 | BB10: 587.12433 | BC10: 575.74174
A11: 1990Q3 | B11: 109.81497 | C11: 115.72729 | D11: 50.142599 | E11: 64.592385 | F11: -31.237681 | G11: -0.84665026 | H11: 9.0598497 | I11: 10.064082 | J11: 20.322 | K11: 10.58601 | L11: 11.564105 | M11: 22.81548 | N11: 15.093753 | P11: 3.4641267 | Q11: 48.061523 | R11: 57.488324 | S11: 44.237978 | T11: 60.369761 | U11: 49.478952 | V11: 59.170489 | W11: 50.414594 | X11: 59.675153 | Y11: 3689.5614 | Z11: 22.433731 | AA11: 30.718787 | AB11: 29.656426 | AC11: 30.689903 | AD11: 49.28461 | AE11: 59.528847 | AF11: 24.666766 | AG11: 30.955463 | AH11: 29.688249 | AJ11: 54.592727 | AK11: 55.284677 | AL11: 13.109537 | AM11: 33.37838 | AN11: 5.4112631 | AO11: 47.718522 | AP11: 59.290774 | AX11: 25.656667 | AZ11: 74.436365 | BA11: -16.835791 | BB11: 617.57585 | BC11: 601.68436
A12: 1990Q4 | B12: 101.76666 | C12: 102.12379 | D12: 50.042665 | E12: 64.320218 | F12: -33.159288 | G12: -0.86638058 | H12: 8.7501985 | I12: 9.4835588 | J12: 22.023779 | K12: 10.770466 | L12: 11.834423 | M12: 24.648403 | N12: 16.536699 | P12: 3.5665332 | Q12: 47.922831 | R12: 57.245434 | S12: 43.876755 | T12: 59.939964 | U12: 49.558716 | V12: 59.085121 | W12: 50.421766 | X12: 59.537559 | Y12: 3827.3351 | Z12: 22.495745 | AA12: 30.784818 | AB12: 29.751411 | AC12: 31.127424 | AD12: 49.275118 | AE12: 59.29664 | AF12: 25.074553 | AG12: 31.489048 | AH12: 30.169817 | AJ12: 56.046732 | AK12: 55.284677 | AL12: 13.800501 | AM12: 34.760953 | AN12: 5.7936466 | AO12: 48.382109 | AP12: 59.990004 | AX12: 31 | AZ12: 72.947571 | BA12: -30.972843 | BB12: 665.58748 | BC12: 635.95803
A13: 1991Q1 | B13: 102.73417 | C13: 103.86483 | D13: 50.478485 | E13: 63.667661 | F13: -4.1932369 | G13: -0.10919638 | H13: 8.1966541 | I13: 9.3903565 | J13: 24.496246 | K13: 10.984087 | L13: 12.154684 | M13: 28.011989 | N13: 19.681913 | P13: 3.9373106 | Q13: 47.980265 | R13: 57.182458 | S13: 43.300805 | T13: 59.222435 | U13: 49.404762 | V13: 58.978466 | W13: 50.239496 | X13: 59.420541 | Y13: 3840.0878 | Z13: 22.095941 | AA13: 30.111318 | AB13: 29.389667 | AC13: 31.341535 | AD13: 49.093789 | AE13: 59.151987 | AF13: 25.366421 | AG13: 31.611776 | AH13: 30.243687 | AJ13: 53.346582 | AK13: 54.270686 | AL13: 14.445018 | AM13: 36.006287 | AN13: 6.2272566 | AO13: 49.133436 | AP13: 60.882398 | AX13: 19.85 | AY13: 45.410521 | AZ13: 71.599601 | BA13: -23.081549 | BB13: 654.04908 | BC13: 632.08703
A14: 1991Q2 | B14: 106.23945 | C14: 109.91899 | D14: 50.430795 | E14: 63.782447 | F14: 3.4235451 | G14: 0.089640492 | H14: 8.2547536 | I14: 7.8304916 | J14: 23.917544 | K14: 11.203662 | L14: 12.516554 | M14: 27.643224 | N14: 19.752751 | P14: 4.0440994 | Q14: 48.676546 | R14: 57.860738 | S14: 43.523647 | T14: 59.157494 | U14: 49.993065 | V14: 59.508944 | W14: 50.776754 | X14: 59.913956 | Y14: 3819.1949 | Z14: 22.753903 | AA14: 30.717096 | AB14: 29.907087 | AC14: 32.000185 | AD14: 49.458381 | AE14: 59.539585 | AF14: 26.167902 | AG14: 32.485815 | AH14: 31.195026 | AJ14: 49.446021 | AK14: 52.242706 | AL14: 14.946606 | AM14: 36.943752 | AN14: 6.5482095 | AO14: 49.736466 | AP14: 61.486397 | AX14: 18.33 | AY14: 44.329788 | AZ14: 72.920081 | BA14: -13.454414 | BB14: 620.83394 | BC14: 608.38993
A15: 1991Q3 | B15: 105.40232 | C15: 108.9886 | D15: 50.737314 | E15: 64.27598 | F15: -5.9988232 | G15: -0.15490388 | H15: 8.0522684 | I15: 7.4189562 | J15: 25.319556 | K15: 11.350167 | L15: 12.851402 | M15: 29.226159 | N15: 20.828689 | P15: 3.9717112 | Q15: 49.175219 | R15: 58.240522 | S15: 43.865126 | T15: 59.378974 | U15: 50.447177 | V15: 59.840195 | W15: 51.105778 | X15: 60.172062 | Y15: 3872.61 | Z15: 23.386984 | AA15: 31.50917 | AB15: 30.64075 | AC15: 32.313589 | AD15: 50.016138 | AE15: 59.906659 | AF15: 26.346602 | AG15: 32.954794 | AH15: 31.570362 | AJ15: 48.005646 | AK15: 52.242706 | AL15: 15.529641 | AM15: 37.938395 | AN15: 6.928802 | AO15: 50.402624 | AP15: 62.179646 | AX15: 19.423333 | AY15: 47.03393 | AZ15: 71.59588 | BA15: -15.733423 | BB15: 636.04746 | BC15: 621.23164
A16: 1991Q4 | B16: 100.04477 | C16: 99.591284 | D16: 50.817804 | E16: 64.222788 | F16: 6.3305686 | G16: 0.15824233 | H16: 7.5008702 | I16: 6.7312866 | J16: 26.040758 | K16: 11.56187 | L16: 13.443819 | M16: 30.888271 | N16: 22.173155 | P16: 4.043199 | Q16: 49.389551 | R16: 58.475583 | S16: 44.024761 | T16: 59.480259 | U16: 50.755856 | V16: 60.145983 | W16: 51.264521 | X16: 60.402676 | Y16: 4000.5532 | Z16: 24.004902 | AA16: 32.11125 | AB16: 31.073851 | AC16: 32.487908 | AD16: 50.258247 | AE16: 60.147382 | AF16: 27.076521 | AG16: 33.726313 | AH16: 32.165116 | AJ16: 50.707911 | AK16: 52.242706 | AL16: 16.260367 | AM16: 39.240951 | AN16: 7.4683642 | AO16: 51.012675 | AP16: 62.8095 | AX16: 19.866667 | AY16: 46.499278 | AZ16: 69.219185 | BA16: -7.3196917 | BB16: 657.83602 | BC16: 651.59333
A17: 1992Q1 | B17: 98.883867 | C17: 97.636527 | D17: 50.970213 | E17: 63.95163 | F17: -0.55699872 | G17: -0.01376483 | H17: 7.3377428 | I17: 6.1356179 | J17: 25.969368 | K17: 11.738885 | L17: 14.005233 | M17: 29.051359 | N17: 21.988755 | P17: 4.235292 | Q17: 49.707166 | R17: 59.080594 | S17: 44.474776 | T17: 59.642454 | U17: 51.303559 | V17: 60.674661 | W17: 51.700956 | X17: 60.877891 | Y17: 4046.5353 | Z17: 24.410789 | AA17: 32.417886 | AB17: 31.535796 | AC17: 33.26623 | AD17: 50.700822 | AE17: 60.594367 | AF17: 27.734928 | AG17: 34.368537 | AH17: 32.847723 | AI17: 50.731816 | AJ17: 45.531943 | AK17: 52.242706 | AL17: 19.520497 | AM17: 40.405256 | AN17: 10.328507 | AO17: 51.54993 | AP17: 63.368479 | AQ17: 68.228817 | AR17: 47.829402 | AU17: 55.064845 | AV17: 51.653864 | AW17: 44.4642 | AX17: 17.506667 | AY17: 40.826794 | AZ17: 67.992599 | BA17: -6.7463757 | BB17: 672.00505 | BC17: 666.18998
A18: 1992Q2 | B18: 103.85662 | C18: 106.58647 | D18: 51.038083 | E18: 64.189 | F18: -8.1588637 | G18: -0.19927004 | H18: 7.3622655 | I18: 5.7340045 | J18: 24.879787 | K18: 11.858085 | L18: 14.372014 | M18: 28.651934 | N18: 21.559301 | P18: 4.2989204 | Q18: 50.248779 | R18: 59.453362 | S18: 45.318427 | T18: 60.572698 | U18: 51.70608 | V18: 61.045247 | W18: 52.095497 | X18: 61.242742 | Y18: 4094.3756 | Z18: 24.941736 | AA18: 32.955228 | AB18: 32.136411 | AC18: 33.454474 | AD18: 51.251135 | AE18: 61.067545 | AF18: 27.770895 | AG18: 34.506094 | AH18: 33.058597 | AI18: 52.220999 | AJ18: 41.181354 | AK18: 51.725258 | AL18: 21.303963 | AM18: 41.655352 | AN18: 11.881795 | AO18: 52.122006 | AP18: 63.959788 | AQ18: 66.779779 | AR18: 48.653229 | AU18: 54.622327 | AV18: 54.199501 | AW18: 48.747539 | AX18: 19.683333 | AY18: 45.857339 | AZ18: 72.528259 | BA18: -13.827279 | BB18: 690.05847 | BC18: 676.91339
A19: 1992Q3 | B19: 100.93323 | C19: 101.15397 | D19: 51.060217 | E19: 64.541654 | F19: -12.519936 | G19: -0.29603088 | H19: 6.8119417 | I19: 5.2009416 | J19: 25.090362 | K19: 12.012471 | L19: 14.851905 | M19: 29.106346 | N19: 22.245608 | P19: 4.2712 | Q19: 50.733559 | R19: 59.91778 | S19: 45.659699 | T19: 60.681714 | U19: 52.226489 | V19: 61.564755 | W19: 52.609751 | X19: 61.757173 | Y19: 4229.267 | Z19: 25.162273 | AA19: 33.124311 | AB19: 32.319471 | AC19: 33.829943 | AD19: 51.586703 | AE19: 61.447461 | AF19: 28.412891 | AG19: 35.081155 | AH19: 33.524871 | AI19: 52.702734 | AJ19: 41.845637 | AK19: 49.138015 | AL19: 23.027261 | AM19: 42.909358 | AN19: 13.432753 | AO19: 52.640988 | AP19: 64.4507 | AQ19: 65.123837 | AR19: 50.141161 | AU19: 54.133223 | AV19: 61.388955 | AW19: 50.633568 | AX19: 19.996667 | AY19: 44.615931 | AZ19: 72.227941 | BA19: -11.471184 | BB19: 721.87484 | BC19: 710.40366
A20: 1992Q4 | B20: 102.33896 | C20: 104.14419 | D20: 51.187015 | E20: 64.680283 | F20: -7.9097396 | G20: -0.18856099 | H20: 6.7309871 | I20: 4.8720293 | J20: 25.648165 | K20: 12.178758 | L20: 15.354187 | M20: 29.420044 | N20: 23.843613 | P20: 4.270111 | Q20: 51.279695 | R20: 60.348071 | S20: 46.04224 | T20: 60.893651 | U20: 52.542999 | V20: 61.879444 | W20: 52.900559 | X20: 62.059262 | Y20: 4194.7911 | Z20: 25.808859 | AA20: 33.644294 | AB20: 32.775308 | AC20: 34.517759 | AD20: 51.825889 | AE20: 61.727352 | AF20: 29.160345 | AG20: 35.700995 | AH20: 34.211445 | AI20: 51.095287 | AJ20: 46.601668 | AK20: 46.462571 | AL20: 25.070438 | AM20: 44.385589 | AN20: 15.414476 | AO20: 53.191377 | AP20: 65.006593 | AQ20: 63.174161 | AR20: 44.892083 | AU20: 52.254426 | AV20: 65.947681 | AW20: 49.418622 | AX20: 18.956667 | AY20: 43.745614 | AZ20: 72.125898 | BA20: -9.5389812 | BB20: 705.7245 | BC20: 696.18552
A21: 1993Q1 | B21: 103.28358 | C21: 105.50307 | D21: 51.456025 | E21: 65.206656 | F21: -5.7889336 | G21: -0.13270668 | H21: 6.2886614 | I21: 4.5051941 | J21: 27.216309 | K21: 12.521533 | L21: 16.261236 | M21: 31.640155 | N21: 25.823279 | P21: 4.9578331 | Q21: 52.38473 | R21: 61.180688 | S21: 47.257362 | T21: 61.643774 | U21: 53.058638 | V21: 62.276622 | W21: 53.425308 | X21: 62.454339 | Y21: 4362.2022 | Z21: 26.773131 | AA21: 34.484987 | AB21: 33.599607 | AC21: 35.084701 | AD21: 52.43743 | AE21: 62.118957 | AF21: 30.676384 | AG21: 36.882946 | AH21: 35.402158 | AI21: 50.644328 | AJ21: 45.135889 | AK21: 44.024943 | AL21: 27.077135 | AM21: 46.239148 | AN21: 17.395715 | AO21: 53.802632 | AP21: 65.551842 | AQ21: 65.013755 | AR21: 43.882471 | AU21: 53.071062 | AV21: 63.018192 | AW21: 47.13412 | AX21: 17.99 | AY21: 42.3372 | AZ21: 76.160493 | BA21: -0.13737414 | BB21: 688.28771 | BC21: 688.15033
A22: 1993Q2 | B22: 101.70071 | C22: 102.80689 | D22: 51.759427 | E22: 65.620864 | F22: -18.902314 | G22: -0.41735363 | H22: 6.1333659 | I22: 4.2824862 | J22: 28.614134 | K22: 17.900804 | L22: 17.405939 | M22: 33.813582 | N22: 27.905879 | P22: 4.9799711 | Q22: 52.955516 | R22: 61.602848 | S22: 47.947664 | T22: 62.104034 | U22: 53.561063 | V22: 62.636205 | W22: 53.903603 | X22: 62.798067 | Y22: 4529.0881 | Z22: 27.350709 | AA22: 35.007546 | AB22: 34.097449 | AC22: 35.840682 | AD22: 53.043257 | AE22: 62.557418 | AF22: 30.629767 | AG22: 36.913983 | AH22: 35.596648 | AI22: 51.610714 | AJ22: 42.162183 | AK22: 43.073674 | AL22: 29.623242 | AM22: 48.860628 | AN22: 20.209737 | AO22: 54.479092 | AP22: 66.17047 | AQ22: 66.540142 | AR22: 40.780315 | AU22: 54.410937 | AV22: 65.690285 | AW22: 47.560264 | AX22: 17.993333 | AY22: 41.253286 | AZ22: 86.622907 | BA22: -3.2751474 | BB22: 718.27794 | BC22: 715.00279
A23: 1993Q3 | B23: 101.37593 | C23: 102.20039 | D23: 52.10847 | E23: 65.993367 | F23: -18.38323 | G23: -0.39848368 | H23: 5.6764784 | I23: 4.246356 | J23: 29.842721 | K23: 21.897411 | L23: 18.632359 | M23: 35.582017 | N23: 30.294617 | P23: 4.9859578 | Q23: 53.612658 | R23: 62.208647 | S23: 48.548322 | T23: 62.424253 | U23: 54.00852 | V23: 62.988877 | W23: 54.326158 | X23: 63.136903 | Y23: 4613.2957 | Z23: 28.398042 | AA23: 35.798385 | AB23: 34.745763 | AC23: 36.287346 | AD23: 53.586082 | AE23: 62.95204 | AF23: 31.106428 | AG23: 37.22398 | AH23: 35.96091 | AI23: 50.169321 | AJ23: 50.310757 | AK23: 43.073674 | AL23: 33.020855 | AM23: 52.204397 | AN23: 24.321191 | AO23: 55.107824 | AP23: 66.692189 | AQ23: 65.741628 | AR23: 39.651704 | AU23: 54.181431 | AV23: 65.329983 | AW23: 44.365908 | AX23: 16.2 | AY23: 37.405873 | AZ23: 85.740496 | BA23: -0.9280207 | BB23: 719.4434 | BC23: 718.51538
A24: 1993Q4 | B24: 104.09099 | C24: 106.88906 | D24: 52.795506 | E24: 66.506168 | F24: -22.242136 | G24: -0.47595198 | H24: 5.396311 | I24: 4.0308559 | J24: 31.980782 | K24: 22.915175 | L24: 25.702131 | M24: 37.688247 | N24: 33.521877 | P24: 4.9895965 | Q24: 54.39721 | R24: 63.01843 | S24: 49.633712 | T24: 63.570415 | U24: 54.618373 | V24: 63.642574 | W24: 54.922415 | X24: 63.784469 | Y24: 4673.189 | Z24: 29.19429 | AA24: 36.793748 | AB24: 35.637924 | AC24: 36.775133 | AD24: 54.233206 | AE24: 63.650822 | AF24: 31.96819 | AG24: 37.997081 | AH24: 36.678928 | AI24: 49.13424 | AJ24: 54.312888 | AK24: 42.944312 | AL24: 36.627997 | AM24: 55.444831 | AN24: 29.102519 | AO24: 55.68689 | AP24: 67.220069 | AQ24: 66.977366 | AR24: 37.491932 | AU24: 54.302194 | AV24: 63.126565 | AW24: 41.658927 | AX24: 14.963333 | AY24: 34.768052 | AZ24: 83.352583 | BA24: 2.0472488 | BB24: 733.10339 | BC24: 735.15063
A25: 1994Q1 | B25: 107.27148 | C25: 107.3545 | D25: 53.601973 | E25: 67.352393 | F25: -8.9315559 | G25: -0.19016194 | H25: 6.0862052 | I25: 3.9692599 | J25: 31.719941 | K25: 26.998908 | L25: 26.418419 | M25: 37.403979 | N25: 33.964043 | P25: 5.317353 | Q25: 54.757301 | R25: 63.567442 | S25: 50.412085 | T25: 64.22534 | U25: 55.303131 | V25: 64.409459 | W25: 55.60729 | X25: 64.550487 | Y25: 4696.8156 | Z25: 29.714035 | AA25: 37.749846 | AB25: 36.603148 | AC25: 37.815973 | AD25: 54.979944 | AE25: 64.474649 | AF25: 32.423018 | AG25: 38.822519 | AH25: 37.370013 | AI25: 50.282822 | AJ25: 54.613994 | AK25: 42.716948 | AL25: 39.558836 | AM25: 57.599749 | AN25: 33.071157 | AO25: 56.291453 | AP25: 67.691988 | AQ25: 70.659261 | AR25: 41.210151 | AU25: 57.408866 | AV25: 63.361327 | AW25: 39.975184 | AX25: 13.87 | AY25: 32.400629 | AZ25: 87.670608 | BA25: -2.4439925 | BB25: 749.68625 | BC25: 747.24225
A26: 1994Q2 | B26: 108.78786 | C26: 109.62817 | D26: 54.70511 | E26: 68.757297 | F26: -13.87402 | G26: -0.28658773 | H26: 6.9594424 | I26: 4.3601309 | J26: 31.767208 | K26: 27.577798 | L26: 26.863127 | M26: 37.903152 | N26: 34.995558 | P26: 5.2586965 | Q26: 55.30653 | R26: 64.080239 | S26: 51.502182 | T26: 65.395034 | U26: 55.922723 | V26: 64.974598 | W26: 56.199111 | X26: 65.101822 | Y26: 4841.1076 | Z26: 30.808043 | AA26: 38.956784 | AB26: 37.920106 | AC26: 38.664271 | AD26: 55.586186 | AE26: 65.132176 | AF26: 33.980877 | AG26: 40.050873 | AH26: 38.598788 | AI26: 52.232472 | AJ26: 73.330981 | AK26: 43.818486 | AL26: 42.837971 | AM26: 59.648523 | AN26: 38.038283 | AO26: 56.867237 | AP26: 68.188581 | AQ26: 69.144028 | AR26: 44.029156 | AU26: 58.609812 | AV26: 57.867371 | AW26: 43.007813 | AX26: 16.27 | AY26: 37.247286 | AZ26: 96.131796 | BA26: 1.4201055 | BB26: 797.51042 | BC26: 798.93053
A27: 1994Q3 | B27: 107.85237 | C27: 109.41571 | D27: 55.748458 | E27: 69.829727 | F27: -11.437137 | G27: -0.22712719 | H27: 7.5206977 | I27: 4.6276801 | J27: 33.978356 | K27: 28.158165 | L27: 27.85068 | M27: 40.162714 | N27: 36.801173 | P27: 5.2480264 | Q27: 56.128652 | R27: 64.758026 | S27: 52.255412 | T27: 66.180033 | U27: 56.634995 | V27: 65.657659 | W27: 56.883526 | X27: 65.770746 | Y27: 5035.565 | Z27: 31.637741 | AA27: 39.930079 | AB27: 38.773522 | AC27: 39.729414 | AD27: 56.167379 | AE27: 65.692271 | AF27: 35.040536 | AG27: 41.213674 | AH27: 39.588877 | AI27: 53.91198 | AJ27: 118.69993 | AK27: 45.865544 | AL27: 45.176338 | AM27: 61.148659 | AN27: 40.890376 | AO27: 57.490943 | AP27: 68.697638 | AQ27: 67.821314 | AR27: 48.093674 | AU27: 60.666079 | AV27: 56.124686 | AW27: 44.142348 | AX27: 17.05 | AY27: 37.902343 | AZ27: 96.457375 | BA27: -3.3813787 | BB27: 845.66779 | BC27: 842.28642
A28: 1994Q4 | B28: 109.9953 | C28: 111.51628 | D28: 56.956952 | E28: 71.301774 | F28: -28.986087 | G28: -0.56370965 | H28: 7.8541827 | I28: 5.0660336 | J28: 33.331333 | K28: 28.576711 | L28: 27.972456 | M28: 38.558486 | N28: 35.743483 | P28: 5.0784233 | Q28: 56.817735 | R28: 65.359892 | S28: 53.455595 | T28: 67.249669 | U28: 57.345192 | V28: 66.284697 | W28: 57.56994 | X28: 66.384972 | Y28: 5142.0242 | Z28: 33.477235 | AA28: 41.550376 | AB28: 40.398274 | AC28: 40.522081 | AD28: 56.888589 | AE28: 66.342279 | AF28: 36.310414 | AG28: 42.35062 | AH28: 40.796405 | AI28: 54.580459 | AJ28: 105.66132 | AK28: 48.454747 | AL28: 47.089031 | AM28: 62.235434 | AN28: 43.450604 | AO28: 58.135099 | AP28: 69.219334 | AQ28: 68.562837 | AR28: 55.404847 | AU28: 62.153231 | AV28: 54.790314 | AW28: 43.626638 | AX28: 16.603333 | AY28: 36.697972 | AZ28: 95.652185 | BA28: -10.495864 | BB28: 895.80915 | BC28: 885.31328
... A38: 1997Q2 | B38: 116.06652 | C38: 117.89883 | D38: 63.357631 | E38: 77.818757 | F38: 0.52341606 | G38: 0.0069140625 | H38: 5.8706682 | I38: 5.58432 | J38: 57.456233 | K38: 34.870722 | L38: 33.329097 | M38: 56.54891 | N38: 58.313681 | P38: 5.6105066 | Q38: 61.764066 | R38: 70.040299 | S38: 59.632372 | T38: 74.305234 | U38: 62.887893 | V38: 71.76666 | W38: 62.899902 | X38: 71.78101 | Y38: 7570.3113 | Z38: 41.547776 | AA38: 50.845788 | AB38: 49.859182 | AC38: 44.357988 | AD38: 61.870472 | AE38: 71.416414 | AF38: 45.613633 | AG38: 52.553432 | AH38: 50.645277 | AI38: 56.892477 | AJ38: 96.610058 | AK38: 50.423874 | AL38: 58.564063 | AM38: 69.592334 | AN38: 57.342509 | AO38: 66.717359 | AP38: 75.665273 | AQ38: 72.986216 | AR38: 52.592666 | AU38: 62.24462 | AV38: 66.16305 | AW38: 49.150741 | AX38: 18.49 | AY38: 43.384475 | AZ38: 90.148852 | BA38: -5.0194138 | BB38: 1082.1384 | BC38: 1077.119
A39: 1997Q3 | B39: 116.74654 | C39: 118.75788 | D39: 64.320185 | E39: 78.960612 | F39: -2.0100424 | G39: -0.026580674 | H39: 5.4684462 | I39: 5.5469793 | J39: 58.327669 | K39: 35.514006 | L39: 33.913264 | M39: 57.365629 | N39: 60.551396 | P39: 5.5914841 | Q39: 62.460022 | R39: 70.668505 | S39: 60.546939 | T39: 75.3007 | U39: 63.517771 | V39: 72.398492 | W39: 63.527267 | X39: 72.411293 | Y39: 7562.0446 | Z39: 42.778286 | AA39: 52.13647 | AB39: 51.1386 | AC39: 44.897648 | AD39: 62.495887 | AE39: 72.04954 | AF39: 46.698594 | AG39: 53.561238 | AH39: 51.478765 | AI39: 55.421054 | AJ39: 86.421071 | AK39: 49.790313 | AL39: 59.357239 | AM39: 70.170165 | AN39: 58.179666 | AO39: 67.430375 | AP39: 76.167763 | AQ39: 69.525948 | AR39: 51.426611 | AS39: 55.065976 | AT39: 55.030458 | AU39: 59.157591 | AV39: 68.77176 | AW39: 50.016249 | AX39: 18.656667 | AY39: 44.372457 | AZ39: 85.728892 | BA39: -3.3739371 | BB39: 1094.6884 | BC39: 1091.3144
A40: 1997Q4 | B40: 117.00344 | C40: 119.18052 | D40: 64.947609 | E40: 79.56948 | F40: -5.6756858 | G40: -0.075168145 | H40: 5.1664437 | I40: 5.8805319 | J40: 54.710325 | K40: 36.229611 | L40: 34.526461 | M40: 52.501067 | N40: 57.750608 | O40: 98.076323 | P40: 5.5068026 | Q40: 63.052588 | R40: 71.230959 | S40: 61.03468 | T40: 75.921291 | U40: 64.135767 | V40: 72.978584 | W40: 64.143883 | X40: 72.9903 | Y40: 7550.653 | Z40: 43.847486 | AA40: 52.869778 | AB40: 51.762054 | AC40: 45.31877 | AD40: 63.104429 | AE40: 72.604537 | AF40: 47.456861 | AG40: 54.306939 | AH40: 52.430769 | AI40: 55.064417 | AJ40: 83.096329 | AK40: 46.139714 | AL40: 60.254975 | AM40: 70.757039 | AN40: 59.158614 | AO40: 68.365906 | AP40: 76.805074 | AQ40: 71.183447 | AR40: 47.113442 | AS40: 55.395096 | AT40: 55.143188 | AU40: 58.123292 | AV40: 71.967076 | AW40: 50.639834 | AX40: 18.84 | AY40: 44.710486 | AZ40: 78.368998 | BA40: -7.4285188 | BB40: 1102.5811 | BC40: 1095.1526
A41: 1998Q1 | B41: 117.86997 | C41: 120.14502 | D41: 65.00531 | E41: 79.614797 | F41: -17.495168 | G41: -0.23656288 | H41: 4.9268845 | I41: 7.5025992 | J41: 62.887991 | K41: 37.011363 | L41: 35.048926 | M41: 59.483327 | N41: 66.116118 | O41: 97.777116 | P41: 5.7769488 | Q41: 62.912367 | R41: 71.259276 | S41: 61.229445 | T41: 76.239318 | U41: 64.1545 | V41: 73.0338 | W41: 64.189987 | X41: 73.062341 | Y41: 7395.5678 | Z41: 45.008628 | AA41: 53.971502 | AB41: 51.931365 | AC41: 45.26905 | AD41: 63.050769 | AE41: 72.690152 | AF41: 48.24563 | AG41: 54.786955 | AH41: 52.739682 | AI41: 50.312652 | AJ41: 86.91413 | AK41: 43.958354 | AL41: 61.257117 | AM41: 71.366555 | AN41: 60.196032 | AO41: 69.359294 | AP41: 77.44653 | AQ41: 71.151517 | AR41: 43.564611 | AS41: 53.619136 | AT41: 53.319337 | AU41: 57.183802 | AV41: 62.054169 | AW41: 40.37371 | AX41: 14.163333 | AY41: 34.089059 | AZ41: 73.781556 | BA41: 0.0060578 | BB41: 1069.1512 | BC41: 1069.1573
A42: 1998Q2 | B42: 118.58326 | C42: 121.11069 | D42: 65.070542 | E42: 79.47373 | F42: -16.556712 | G42: -0.22308394 | H42: 4.8081629 | I42: 7.74913 | J42: 61.386447 | K42: 37.779791 | L42: 35.642676 | M42: 57.039275 | N42: 64.101919 | O42: 96.692683 | P42: 5.8940142 | Q42: 63.710218 | R42: 71.96753 | S42: 61.329199 | T42: 76.607637 | U42: 64.39067 | V42: 73.323314 | W42: 64.43753 | X42: 73.358899 | Y42: 7421.7408 | Z42: 45.117562 | AA42: 54.090081 | AB42: 51.826076 | AC42: 45.943237 | AD42: 63.353917 | AE42: 73.027108 | AF42: 47.791331 | AG42: 54.560474 | AH42: 52.272622 | AI42: 49.848742 | AJ42: 79.300967 | AK42: 43.046364 | AL42: 62.094043 | AM42: 71.879836 | AN42: 61.104438 | AO42: 70.354407 | AP42: 78.037749 | AQ42: 73.086735 | AR42: 42.225152 | AS42: 52.746362 | AT42: 52.395166 | AU42: 57.802875 | AV42: 60.101426 | AW42: 38.343293 | AX42: 13.28 | AY42: 32.111445 | AZ42: 72.865114 | BA42: 1.2735368 | BB42: 1051.9626 | BC42: 1053.2362
A43: 1998Q3 | B43: 117.46068 | C43: 119.89665 | D43: 65.098642 | E43: 79.478529 | F43: -21.076306 | G43: -0.28514051 | H43: 4.5044982 | I43: 8.9280128 | J43: 50.862811 | K43: 38.433772 | L43: 36.154053 | M43: 48.658626 | N43: 53.530388 | O43: 96.490753 | P43: 5.910443 | Q43: 64.419775 | R43: 72.693107 | S43: 61.772898 | T43: 77.357677 | U43: 64.732013 | V43: 73.783837 | W43: 64.792801 | X43: 73.828247 | Y43: 7391.551 | Z43: 44.861609 | AA43: 54.247753 | AB43: 51.41945 | AC43: 46.428425 | AD43: 63.535709 | AE43: 73.459515 | AF43: 48.533815 | AG43: 54.790961 | AH43: 52.406234 | AI43: 46.704414 | AJ43: 72.218148 | AK43: 40.319462 | AL43: 63.309242 | AM43: 72.53254 | AN43: 62.458647 | AO43: 71.396233 | AP43: 78.635873 | AQ43: 66.993627 | AR43: 40.096272 | AS43: 50.473244 | AT43: 50.108467 | AU43: 53.678919 | AV43: 55.349863 | AW43: 36.615972 | AX43: 13.003333 | AY43: 31.447843 | AZ43: 70.101985 | BA43: 0.4381368 | BB43: 1032.5707 | BC43: 1033.0089
A44: 1998Q4 | B44: 113.83154 | C44: 117.03749 | D44: 65.40845 | E44: 79.654185 | F44: -24.844116 | G44: -0.3189453 | H44: 4.0458849 | I44: 7.4180618 | J44: 59.083448 | K44: 39.390522 | L44: 36.973789 | M44: 59.73604 | N44: 63.314726 | O44: 91.164035 | P44: 5.9009699 | Q44: 64.512305 | R44: 73.068351 | S44: 61.852459 | T44: 77.900835 | U44: 65.30301 | V44: 74.404544 | W44: 65.367478 | X44: 74.451143 | Y44: 7789.46 | Z44: 44.432107 | AA44: 54.378245 | AB44: 51.271346 | AC44: 47.336275 | AD44: 64.142846 | AE44: 74.190801 | AF44: 48.508017 | AG44: 55.045089 | AH44: 52.699654 | AI44: 45.28768 | AJ44: 70.78806 | AK44: 39.422316 | AL44: 64.777684 | AM44: 73.376711 | AN44: 64.006725 | AO44: 72.979953 | AP44: 79.362209 | AQ44: 67.109746 | AR44: 38.253864 | AS44: 47.489751 | AT44: 47.359723 | AU44: 53.062905 | AV44: 52.310551 | AW44: 34.041018 | AX44: 11.85 | AY44: 27.468552 | AZ44: 68.594988 | BA44: 0.8463912 | BB44: 1054.3734 | BC44: 1055.2198
A45: 1999Q1 | B45: 115.1168 | C45: 119.37603 | D45: 66.086884 | E45: 80.420753 | F45: -44.964606 | G45: -0.58431556 | H45: 4.30392 | I45: 5.8591847 | J45: 65.382372 | K45: 40.079624 | L45: 38.085259 | M45: 62.673719 | N45: 69.195037 | O45: 91.925607 | P45: 6.1930905 | Q45: 65.4856 | R45: 73.832662 | S45: 62.168444 | T45: 78.289912 | U45: 65.837487 | V45: 74.840694 | W45: 65.889406 | X45: 74.879659 | Y45: 7695.2608 | Z45: 44.858827 | AA45: 55.161241 | AB45: 51.846529 | AC45: 48.547818 | AD45: 64.744007 | AE45: 74.721129 | AF45: 48.704807 | AG45: 55.282993 | AH45: 53.0429 | AI45: 43.577208 | AJ45: 66.978686 | AK45: 38.783476 | AL45: 65.50583 | AM45: 73.798799 | AN45: 64.854515 | AO45: 73.696272 | AP45: 79.799965 | AQ45: 63.131155 | AR45: 36.87191 | AS45: 49.991232 | AT45: 50.076621 | AU45: 50.883877 | AV45: 49.435003 | AW45: 33.008298 | AX45: 11.643333 | AY45: 27.325469 | AZ45: 70.010596 | BA45: -23.807876 | BB45: 1053.6226 | BC45: 1029.8148
A46: 1999Q2 | B46: 116.57227 | C46: 120.835 | D46: 67.009715 | E46: 81.181855 | F46: -34.430546 | G46: -0.45135419 | H46: 4.5455102 | I46: 5.0709603 | J46: 73.648655 | K46: 40.947443 | L46: 39.000316 | M46: 69.054998 | N46: 77.306735 | O46: 91.101485 | P46: 6.1537895 | Q46: 66.127168 | R46: 74.548323 | S46: 63.110807 | T46: 79.332377 | U46: 66.487827 | V46: 75.435941 | W46: 66.528758 | X46: 75.468302 | Y46: 7628.2766 | Z46: 46.131572 | AA46: 56.56245 | AB46: 53.452127 | AC46: 49.442105 | AD46: 65.528507 | AE46: 75.392705 | AF46: 49.321184 | AG46: 56.139748 | AH46: 53.894594 | AI46: 46.738513 | AJ46: 60.791796 | AK46: 38.115968 | AL46: 66.204673 | AM46: 74.303437 | AN46: 65.623862 | AO46: 74.298722 | AP46: 80.221056 | AQ46: 61.417138 | AR46: 39.258281 | AS46: 52.663726 | AT46: 52.711832 | AU46: 50.130971 | AV46: 55.833913 | AW46: 41.831411 | AX46: 16.03 | AY46: 38.578353 | AZ46: 70.653989 | BA46: -32.357248 | BB46: 1077.7655 | BC46: 1045.4082
A47: 1999Q3 | B47: 116.58872 | C47: 120.65954 | D47: 68.104372 | E47: 82.398093 | F47: -47.164832 | G47: -0.60600866 | H47: 5.0252919 | I47: 4.8200446 | J47: 71.071066 | K47: 41.707872 | L47: 39.759653 | M47: 67.988862 | N47: 74.339988 | O47: 90.793812 | P47: 6.0846694 | Q47: 66.678917 | R47: 75.260885 | S47: 63.828781 | T47: 80.30056 | U47: 67.295614 | V47: 76.3051 | W47: 67.336521 | X47: 76.337386 | Y47: 7782.8644 | Z47: 47.434504 | AA47: 58.165438 | AB47: 55.018014 | AC47: 50.38588 | AD47: 66.116644 | AE47: 76.143452 | AF47: 51.293454 | AG47: 58.054977 | AH47: 55.935878 | AI47: 50.365907 | AJ47: 54.650712 | AK47: 36.581733 | AL47: 66.95205 | AM47: 74.861891 | AN47: 66.440782 | AO47: 74.839227 | AP47: 80.618662 | AQ47: 60.133058 | AR47: 43.441775 | AS47: 54.734197 | AT47: 54.737567 | AU47: 49.796608 | AV47: 63.302413 | AW47: 51.189383 | AX47: 20.443333 | AY47: 48.725894 | AZ47: 70.689782 | BA47: -31.198158 | BB47: 1131.4546 | BC47: 1100.2565
A48: 1999Q4 | B48: 117.29515 | C48: 121.23453 | D48: 69.482043 | E48: 83.982385 | F48: -55.894931 | G48: -0.69767911 | H48: 5.2040297 | I48: 4.9723817 | J48: 84.742722 | K48: 42.594125 | L48: 41.221036 | M48: 81.800515 | N48: 90.14852 | O48: 90.619955 | P48: 5.9845935 | Q48: 67.69708 | R48: 76.177337 | S48: 64.722822 | T48: 81.108559 | U48: 68.313427 | V48: 77.3522 | W48: 68.350479 | X48: 77.382079 | Y48: 8011.5528 | Z48: 49.007056 | AA48: 59.963632 | AB48: 56.907996 | AC48: 51.528706 | AD48: 67.071702 | AE48: 77.170714 | AF48: 53.191166 | AG48: 59.970634 | AH48: 57.806448 | AI48: 53.957226 | AJ48: 60.017196 | AK48: 35.769861 | AL48: 67.658733 | AM48: 75.425728 | AN48: 67.22651 | AO48: 75.539359 | AP48: 81.113709 | AQ48: 60.251134 | AR48: 45.986144 | AS48: 57.160647 | AT48: 57.060071 | AU48: 51.361151 | AV48: 67.638583 | AW48: 57.712382 | AX48: 23.806667 | AY48: 55.977589 | AZ48: 72.781576 | BA48: -33.485644 | BB48: 1193.4022 | BC48: 1159.9166
A49: 2000Q1 | B49: 118.4264 | C49: 123.64278 | D49: 70.535514 | E49: 84.991837 | F49: -67.774692 | G49: -0.8434948 | H49: 5.4509211 | I49: 5.1069292 | J49: 87.116989 | K49: 43.374835 | L49: 41.854333 | M49: 82.953727 | N49: 92.665396 | O49: 90.337286 | P49: 6.0615046 | Q49: 68.728171 | R49: 77.209763 | S49: 66.405659 | T49: 82.895849 | U49: 69.21508 | V49: 78.209604 | W49: 69.241742 | X49: 78.233979 | Y49: 8034.9863 | Z49: 51.16643 | AA49: 61.948651 | AB49: 58.987277 | AC49: 52.395222 | AD49: 68.065675 | AE49: 78.069103 | AF49: 54.935087 | AG49: 61.785268 | AH49: 59.65336 | AI49: 58.059386 | AJ49: 52.952902 | AK49: 36.22532 | AL49: 68.357769 | AM49: 76.029687 | AN49: 67.996224 | AO49: 76.19478 | AP49: 81.572184 | AQ49: 61.859577 | AR49: 49.768508 | AS49: 55.955602 | AT49: 55.946165 | AU49: 52.971489 | AV49: 79.369951 | AW49: 65.418899 | AX49: 26.616667 | AY49: 63.799923 | AZ49: 74.002809 | BA49: -56.388599 | BB49: 1252.9883 | BC49: 1196.5997
...

Sheet Sheet1

Sheet Commodity_Prices
A1: EcDatabase | B1: ID:PRIMARY_COMMODITY_PRICE_SYSTEM_LIVE | C1: ID:PRIMARY_COMMODITY_PRICE_SYSTEM_LIVE | D1: ID:PRIMARY_COMMODITY_PRICE_SYSTEM_LIVE | E1: ID:PRIMARY_COMMODITY_PRICE_SYSTEM_LIVE | F1: ID:PRIMARY_COMMODITY_PRICE_SYSTEM_LIVE | G1: ID:PRIMARY_COMMODITY_PRICE_SYSTEM_LIVE | H1: ID:PRIMARY_COMMODITY_PRICE_SYSTEM_LIVE | I1: ID:PRIMARY_COMMODITY_PRICE_SYSTEM_LIVE | J1: ID:PRIMARY_COMMODITY_PRICE_SYSTEM_LIVE | K1: ID:PRIMARY_COMMODITY_PRICE_SYSTEM_LIVE | L1: ID:PRIMARY_COMMODITY_PRICE_SYSTEM_LIVE | M1: ID:PRIMARY_COMMODITY_PRICE_SYSTEM_LIVE | N1: ID:PRIMARY_COMMODITY_PRICE_SYSTEM_LIVE | O1: ID:PRIMARY_COMMODITY_PRICE_SYSTEM_LIVE | P1: ID:PRIMARY_COMMODITY_PRICE_SYSTEM_LIVE | Q1: ID:PRIMARY_COMMODITY_PRICE_SYSTEM_LIVE | R1: ID:PRIMARY_COMMODITY_PRICE_SYSTEM_LIVE | S1: ID:PRIMARY_COMMODITY_PRICE_SYSTEM_LIVE | T1: ID:PRIMARY_COMMODITY_PRICE_SYSTEM_LIVE
A2: Series_code | B2: PALUM_USD.M | C2: PCOALAU_USD.M | D2: PCOALSA_USD.M | E2: PCOPP_USD.M | F2: PGOLD_USD.M | G2: PIORECR_USD.M | H2: PNGASEU_USD.M | I2: PNGASJP_USD.M | J2: PNGASUS_USD.M | K2: PNICK_USD.M | L2: POILBRE_USD.M | M2: POILDUB_USD.M | N2: POILWTI_USD.M | O2: PPALLA_USD.M | P2: PPLAT_USD.M | Q2: PSILVER_USD.M | R2: POILAPSP_USD.M | S2: PALLFNF_Index.M | T2: PFOOD_Index.M
A3: Commodity | B3: PALUM | C3: PCOALAU | D3: PCOALSA | E3: PCOPP | F3: PGOLD | G3: PIORECR | H3: PNGASEU | I3: PNGASJP | J3: PNGASUS | K3: PNICK | L3: POILBRE | M3: POILDUB | N3: POILWTI | O3: PPALLA | P3: PPLAT | Q3: PSILVER | R3: POILAPSP | S3: PALLFNF | T3: PFOOD
A4: Data Type | B4: USD | C4: USD | D4: USD | E4: USD | F4: USD | G4: USD | H4: USD | I4: USD | J4: USD | K4: USD | L4: USD | M4: USD | N4: USD | O4: USD | P4: USD | Q4: USD | R4: USD | S4: Index | T4: Index
A5: Frequency | B5: Monthly | C5: Monthly | D5: Monthly | E5: Monthly | F5: Monthly | G5: Monthly | H5: Monthly | I5: Monthly | J5: Monthly | K5: Monthly | L5: Monthly | M5: Monthly | N5: Monthly | O5: Monthly | P5: Monthly | Q5: Monthly | R5: Monthly | S5: Monthly | T5: Monthly
A6: Scale | B6: Units | C6: Units | D6: Units | E6: Units | F6: Units | G6: Units | H6: Units | I6: Units | J6: Units | K6: Units | L6: Units | M6: Units | N6: Units | O6: Units | P6: Units | Q6: Units | R6: Units | S6: Units | T6: Units
A7: Display_scale | B7: Units | C7: Units | D7: Units | E7: Units | F7: Units | G7: Units | H7: Units | I7: Units | J7: Units | K7: Units | L7: Units | M7: Units | N7: Units | O7: Units | P7: Units | Q7: Units | R7: Units | S7: Units | T7: Units
A8: 1990M1 | B8: 1528 | C8: 38 | D8: 31 | E8: 2365.557 | F8: 409.81906 | G8: 14.05 | H8: 1.73 | K8: 7056 | L8: 21.25 | M8: 17.57 | N8: 22.96 | O8: 135.41304 | P8: 497.65652 | Q8: 5.2475455 | R8: 20.59
A9: 1990M2 | B9: 1454 | C9: 38 | D9: 31 | E9: 2358.9434 | F9: 417.18106 | G9: 14.05 | H9: 1.73 | K9: 6977 | L9: 19.93 | M9: 17 | N9: 22.12 | O9: 135.4375 | P9: 516.1 | Q9: 5.28935 | R9: 19.68
A10: 1990M3 | B10: 1567 | C10: 38 | D10: 31 | E10: 2625.7027 | F10: 392.70334 | G10: 14.05 | H10: 1.73 | K10: 9267 | L10: 18.37 | M10: 15.59 | N10: 20.41 | O10: 130.28182 | P10: 497.06364 | Q10: 5.0768864 | R10: 18.12
A11: 1990M4 | B11: 1526 | C11: 38 | D11: 31 | E11: 2685.2269 | F11: 374.29211 | G11: 14.05 | H11: 2.1099998 | K11: 8939 | L11: 16.49 | M11: 14.05 | N11: 18.43 | O11: 126.95952 | P11: 478.14762 | Q11: 5.059 | R11: 16.32
