Workbook
Name _DLX1.USE: #REF!
Name _DLX2.USE: 'Monthly Haver'!$1:$4
Name _DLX3.USE: 'Quarterly Haver'!$A$1:$W$3

Sheet GDS_Monthly
A1: EcDatabase | B1: ID:GDS_LIVE | C1: ID:GDS_LIVE | D1: ID:GDS_LIVE | E1: ID:GDS_LIVE | F1: ID:GDS_LIVE | G1: ID:GDS_LIVE | H1: ID:GDS_LIVE | I1: ID:GDS_LIVE | J1: ID:GDS_LIVE | K1: ID:GDS_LIVE | L1: ID:GDS_LIVE | M1: ID:GDS_LIVE | N1: ID:GDS_LIVE | O1: ID:GDS_LIVE | P1: ID:GDS_LIVE | Q1: ID:GDS_LIVE | R1: ID:GDS_LIVE | S1: ID:GDS_LIVE | T1: ID:GDS_LIVE | U1: ID:GDS_LIVE | V1: ID:GDS_LIVE | W1: ID:GDS_LIVE | X1: ID:GDS_LIVE | Y1: ID:GDS_LIVE | Z1: ID:GDS_LIVE | AA1: ID:GDS_LIVE | AB1: ID:GDS_LIVE | AC1: ID:GDS_LIVE | AD1: ID:GDS_LIVE | AE1: ID:GDS_LIVE | AF1: ID:GDS_LIVE | AG1: ID:GDS_LIVE | AH1: ID:GDS_LIVE | AI1: ID:GDS_LIVE
A2: Series_code | B2: 001ACC_PPPWGT.M | C2: 001ACC.M | D2: 001AIP.M | E2: 001AIP_GDPWGT.M | F2: 001FIGB.M | G2: 001FIPR.M | H2: 001FISI.M | I2: 001FMB.M | J2: 001FMN.M | K2: 001FMSCID.M | L2: 001FMSCIL.M | M2: 001LE.M | N2: 001LUR.M | O2: 001NRS.M | P2: 001PALLFNFW.M | Q2: 001PBEVEW.M | R2: 001PCOALW.M | S2: 001PCPI.M | T2: 001PCPI_GDPWGT.M | U2: 001PCPIX.M | V2: 001.M | W2: 001PFOODW.M | X2: 001PMETAW.M | Y2: 001PMI.M | Z2: 001PMI_PPPWGT.M | AA2: 001PNFUELW.M | AB2: 001PNGASW.M | AC2: 001PNRGW.M | AD2: 001POILAPSP.M | AE2: 001POILAPSPW.M | AF2: 001PRAWMW.M | AG2: 001TG.M | AH2: 001TMG.M | AI2: 001TXG.M
A3: Country | B3: World | C3: World | D3: World | E3: World | F3: World | G3: World | H3: World | I3: World | J3: World | K3: World | L3: World | M3: World | N3: World | O3: World | P3: World | Q3: World | R3: World | S3: World | T3: World | U3: World | V3: World | W3: World | X3: World | Y3: World | Z3: World | AA3: World | AB3: World | AC3: World | AD3: World | AE3: World | AF3: World | AG3: World | AH3: World | AI3: World
A4: Country.Name | B4: World | C4: World | D4: World | E4: World | F4: World | G4: World | H4: World | I4: World | J4: World | K4: World | L4: World | M4: World | N4: World | O4: World | P4: World | Q4: World | R4: World | S4: World | T4: World | U4: World | V4: World | W4: World | X4: World | Y4: World | Z4: World | AA4: World | AB4: World | AC4: World | AD4: World | AE4: World | AF4: World | AG4: World | AH4: World | AI4: World
A5: Indicator | B5: ACC_PPPWGT | C5: ACC | D5: AIP | E5: AIP_GDPWGT | F5: FIGB | G5: FIPR | H5: FISI | I5: FMB | J5: FMN | K5: FMSCID | L5: FMSCIL | M5: LE | N5: LUR | O5: NRS | P5: PALLFNFW | Q5: PBEVEW | R5: PCOALW | S5: PCPI | T5: PCPI_GDPWGT | U5: PCPIX | V5: PCPIX_GDPWGT | W5: PFOODW | X5: PMETAW | Y5: PMI | Z5: PMI_PPPWGT | AA5: PNFUELW | AB5: PNGASW | AC5: PNRGW | AD5: POILAPSP | AE5: POILAPSPW | AF5: PRAWMW | AG5: TG | AH5: TMG | AI5: TXG
A6: Indicator.Code | B6: ACC_PPPWGT | C6: ACC | D6: AIP | E6: AIP_GDPWGT | F6: FIGB | G6: FIPR | H6: FISI | I6: FMB | J6: FMN | K6: FMSCID | L6: FMSCIL | M6: LE | N6: LUR | O6: NRS | P6: PALLFNFW | Q6: PBEVEW | R6: PCOALW | S6: PCPI | T6: PCPI_GDPWGT | U6: PCPIX | V6: PCPIX_GDPWGT | W6: PFOODW | X6: PMETAW | Y6: PMI | Z6: PMI_PPPWGT | AA6: PNFUELW | AB6: PNGASW | AC6: PNRGW | AD6: POILAPSP | AE6: POILAPSPW | AF6: PRAWMW | AG6: TG | AH6: TMG | AI6: TXG
A7: Indicator.Descriptor | B7: Consumer confidence, PPP weighted | C7: Consumer confidence | D7: Industrial production | E7: Industrial production, MER weighted | F7: Long-term interest rate | G7: Policy-related interest rate | H7: Benchmark stock market index | I7: Broad money | J7: Narrow money | K7: Morgan Stanley MSCI stock price index in US dollars | L7: Morgan Stanley MSCI stock price index in national currency | M7: Employment | N7: Unemployment rate | O7: Retail sales | P7: Commodity price: all primary commodities | Q7: Commodity price: beverage | R7: Commodity price: coal | S7: Consumer price index | T7: Consumer price index, MER weighted | U7: Core consumer price index | V7: Core consumer price index, GDP weighted | W7: Commodity price: food | X7: Commodity price: metals | Y7: Manufacturing PMI | Z7: Manufacturing PMI, PPP weighted | AA7: Commodity price: non-fuel primary commodities | AB7: Commodity price: natural gas | AC7: Commodity price: energy | AD7: Commodity price: petroleum, US dollar per barrel | AE7: Commodity price: petroleum | AF7: Commodity price: raw materials | AG7: Merchandise trade balance | AH7: Merchandise imports | AI7: Merchandise exports
A8: Frequency | B8: Monthly | C8: Monthly | D8: Monthly | E8: Monthly | F8: Monthly | G8: Monthly | H8: Monthly | I8: Monthly | J8: Monthly | K8: Monthly | L8: Monthly | M8: Monthly | N8: Monthly | O8: Monthly | P8: Monthly | Q8: Monthly | R8: Monthly | S8: Monthly | T8: Monthly | U8: Monthly | V8: Monthly | W8: Monthly | X8: Monthly | Y8: Monthly | Z8: Monthly | AA8: Monthly | AB8: Monthly | AC8: Monthly | AD8: Monthly | AE8: Monthly | AF8: Monthly | AG8: Monthly | AH8: Monthly | AI8: Monthly
A9: Scale | B9: Units | C9: Units | D9: Units | E9: Units | F9: Units | G9: Units | H9: Units | I9: Units | J9: Units | K9: Units | L9: Units | M9: Units | N9: Units | O9: Units | P9: Units | Q9: Units | R9: Units | S9: Units | T9: Units | U9: Units | V9: Units | W9: Units | X9: Units | Y9: Units | Z9: Units | AA9: Units | AB9: Units | AC9: Units | AD9: Units | AE9: Units | AF9: Units | AG9: Billions | AH9: Billions | AI9: Billions
A10: Display_scale | B10: Units | C10: Units | D10: Units | E10: Units | F10: Units | G10: Units | H10: Units | I10: Units | J10: Units | K10: Units | L10: Units | M10: Units | N10: Units | O10: Units | P10: Units | Q10: Units | R10: Units | S10: Units | T10: Units | U10: Units | V10: Units | W10: Units | X10: Units | Y10: Units | Z10: Units | AA10: Units | AB10: Units | AC10: Units | AD10: Units | AE10: Units | AF10: Units | AG10: Billions | AH10: Billions | AI10: Billions
A11: 1990M1 | B11: 114.26463 | C11: 123.43022 | D11: 49.373068 | E11: 63.263084 | F11: 8.323664 | G11: 12.046458 | H11: 23.792103 | I11: 9.7663488 | J11: 10.911992 | K11: 27.282369 | L11: 17.279113 | M11: 81.080056 | N11: 3.3688556 | Q11: 49.20388 | R11: 51.172528 | S11: 11.636356 | T11: 30.225858 | U11: 47.247042 | V11: 57.862272 | AD11: 20.59 | AF11: 72.855085 | AG11: -5.0335787 | AH11: 196.38481 | AI11: 191.35123
A12: 1990M2 | B12: 114.33734 | C12: 123.48367 | D12: 49.582408 | E12: 63.587981 | F12: 8.5701345 | G12: 12.811761 | H12: 23.474586 | I12: 9.9135879 | J12: 10.992793 | K12: 26.764041 | L12: 17.859719 | M12: 81.703794 | N12: 3.3654726 | Q12: 49.947777 | R12: 51.172528 | S12: 11.771227 | T12: 30.521308 | U12: 47.441222 | V12: 58.101556 | AD12: 19.68 | AF12: 73.449658 | AG12: -2.9189287 | AH12: 193.68674 | AI12: 190.76781
A13: 1990M3 | B13: 115.12952 | C13: 124.95586 | D13: 49.87727 | E13: 64.179296 | F13: 8.8640729 | G13: 13.737382 | H13: 23.048825 | I13: 10.002343 | J13: 11.147585 | K13: 25.138839 | L13: 17.108852 | M13: 81.95714 | N13: 3.3468002 | Q13: 54.434712 | R13: 51.172528 | S13: 12.444696 | T13: 31.733288 | U13: 47.662526 | V13: 58.377687 | AD13: 18.12 | AF13: 74.172077 | AG13: -4.3576504 | AH13: 195.41389 | AI13: 191.05624
A14: 1990M4 | B14: 114.22148 | C14: 123.21768 | D14: 49.262783 | E14: 63.606555 | F14: 9.0542255 | G14: 10.216768 | H14: 22.498329 | I14: 10.139628 | J14: 11.298593 | K14: 25.177875 | L14: 17.192593 | M14: 82.357685 | N14: 3.3997466 | Q14: 56.292064 | R14: 51.172528 | S14: 12.545076 | T14: 31.929521 | U14: 47.86742 | V14: 58.603466 | AD14: 16.32 | AF14: 76.022077 | AG14: -4.8716052 | AH14: 192.9747 | AI14: 188.10309
A15: 1990M5 | B15: 114.08956 | C15: 123.03385 | D15: 49.879239 | E15: 64.189096 | F15: 8.8861221 | G15: 9.8641319 | H15: 24.678425 | I15: 10.198687 | J15: 11.362863 | K15: 27.69119 | L15: 18.723617 | M15: 82.477082 | N15: 3.4192908 | Q15: 55.920823 | R15: 54.120417 | S15: 12.657056 | T15: 32.167761 | U15: 48.054379 | V15: 58.801065 | AD15: 16.21 | AF15: 75.418959 | AG15: -5.4577123 | AH15: 200.14548 | AI15: 194.68777
A16: 1990M6 | B16: 112.86521 | C16: 120.87103 | D16: 49.93695 | E16: 64.411191 | F16: 8.6788407 | G16: 10.142622 | H16: 24.468707 | I16: 10.290694 | J16: 11.463502 | K16: 27.335213 | L16: 18.434519 | M16: 82.556306 | N16: 3.4074475 | Q16: 53.061015 | R16: 55.284677 | S16: 12.772721 | T16: 32.423467 | U16: 48.291541 | V16: 59.067568 | AD16: 14.93 | AF16: 75.563455 | AG16: -1.0163899 | AH16: 193.96258 | AI16: 192.94619
A17: 1990M7 | B17: 112.78358 | C17: 120.74384 | D17: 50.030674 | E17: 64.415656 | F17: 8.7403436 | G17: 9.9579222 | H17: 24.696283 | I17: 10.373357 | J17: 11.502069 | K17: 27.746394 | L17: 18.523374 | M17: 82.713743 | N17: 3.4275145 | Q17: 52.830834 | R17: 55.284677 | S17: 13.155994 | T17: 33.119466 | U17: 48.503311 | V17: 59.337706 | AD17: 16.81 | AF17: 76.236284 | AG17: -4.568308 | AH17: 199.85918 | AI17: 195.29087
A18: 1990M8 | B18: 108.17004 | C18: 112.68192 | D18: 50.269507 | E18: 64.700889 | F18: 9.1118153 | G18: 9.7714184 | H18: 22.176611 | I18: 10.468343 | J18: 11.603811 | K18: 25.110873 | L18: 16.692975 | M18: 82.693623 | N18: 3.4594441 | Q18: 54.507742 | R18: 55.284677 | S18: 13.446916 | T18: 33.797205 | U18: 48.757985 | V18: 59.652243 | AD18: 26.54 | AF18: 73.868209 | AG18: -7.548359 | AH18: 209.49247 | AI18: 202.42481
A19: 1990M9 | B19: 107.89813 | C19: 113.02926 | D19: 50.2996 | E19: 64.567872 | F19: 9.3303678 | G19: 10.466012 | H19: 20.261359 | I19: 10.560172 | J19: 11.670862 | K19: 22.814 | L19: 15.094139 | M19: 82.643044 | N19: 3.5081315 | Q19: 56.439606 | R19: 55.284677 | S19: 13.772519 | T19: 34.394458 | U19: 48.977705 | V19: 59.874835 | AD19: 33.62 | AF19: 73.204601 | AG19: -4.7183941 | AH19: 208.23271 | AI19: 203.97791
A20: 1990M10 | B20: 101.69647 | C20: 102.17398 | D20: 50.39912 | E20: 64.700691 | F20: 9.1290741 | G20: 9.9007028 | H20: 21.317148 | I20: 10.626389 | J20: 11.728933 | K20: 24.122569 | L20: 15.740032 | M20: 82.501739 | N20: 3.5357895 | Q20: 56.63649 | R20: 55.284677 | S20: 13.921279 | T20: 34.729373 | U20: 49.206028 | V20: 60.094099 | AD20: 34.85 | AF20: 73.155127 | AG20: -11.439028 | AH20: 224.80416 | AI20: 213.84453
A21: 1990M11 | B21: 101.59472 | C21: 101.76927 | D21: 50.020814 | E21: 64.26483 | F21: 8.75802 | G21: 9.411279 | H21: 21.287443 | I21: 10.674368 | J21: 11.82289 | K21: 24.143126 | L21: 16.022611 | M21: 82.591849 | N21: 3.575767 | Q21: 55.621551 | R21: 55.284677 | S21: 14.182217 | T21: 35.198282 | U21: 49.409033 | V21: 60.296318 | AD21: 31.54 | AF21: 73.029421 | AG21: -12.740631 | AH21: 226.21262 | AI21: 213.90199
A22: 1990M12 | B22: 101.75224 | C22: 101.9674 | D22: 49.892126 | E22: 63.915307 | F22: 8.3662984 | G22: 9.1426827 | H22: 21.933351 | I22: 10.747179 | J22: 11.945251 | K22: 24.645852 | L22: 16.53637 | M22: 82.673156 | N22: 3.5904697 | Q22: 55.882156 | R22: 55.284677 | S22: 14.403888 | T22: 35.593541 | U22: 49.636155 | V22: 60.548269 | AD22: 26.61 | AF22: 72.658165 | AG22: -6.705504 | AH22: 214.48589 | AI22: 208.21439
A23: 1991M1 | B23: 99.904302 | C23: 98.963857 | D23: 50.747193 | E23: 63.835284 | F23: 8.3136686 | G23: 9.412147 | H23: 22.191026 | I23: 10.821023 | J23: 12.032754 | K23: 25.858524 | L23: 17.532666 | M23: 82.844274 | N23: 3.8673046 | Q23: 54.152241 | R23: 55.284677 | S23: 14.621475 | T23: 36.050952 | U23: 49.960967 | V23: 60.957015 | AD23: 22.81 | AE23: 51.895164 | AF23: 71.245906 | AG23: -10.246718 | AH23: 225.44573 | AI23: 215.60341
A24: 1991M2 | B24: 100.96674 | C24: 100.87018 | D24: 50.52348 | E24: 63.68767 | F24: 8.0397546 | G24: 9.6127573 | H24: 24.146844 | I24: 10.89197 | J24: 12.184811 | K24: 28.234565 | L24: 19.275695 | M24: 82.844331 | N24: 3.9295921 | Q24: 52.871024 | R24: 55.284677 | S24: 14.869108 | T24: 36.516064 | U24: 50.214283 | V24: 61.243507 | AD24: 18.53 | AE24: 41.623317 | AF24: 72.488907 | AG24: -8.3386206 | AH24: 218.87019 | AI24: 210.87937
A25: 1991M3 | B25: 107.05537 | C25: 111.27839 | D25: 50.333723 | E25: 63.383655 | F25: 8.239066 | G25: 9.2125234 | H25: 24.4134 | I25: 10.957662 | J25: 12.265427 | K25: 28.011022 | L25: 19.683323 | M25: 82.828955 | N25: 4.0170687 | Q25: 53.016481 | R25: 52.242706 | S25: 15.044756 | T25: 36.828993 | U25: 50.390576 | V25: 61.430117 | AD25: 18.21 | AE25: 42.713082 | AF25: 71.063991 | AG25: -4.6778698 | AH25: 209.88529 | AI25: 205.57472
A26: 1991M4 | B26: 106.54678 | C26: 110.55536 | D26: 50.281803 | E26: 63.482142 | F26: 8.1915197 | G26: 7.9690305 | H26: 24.395545 | I26: 11.031071 | J26: 12.351706 | K26: 28.233458 | L26: 19.833218 | M26: 82.881747 | N26: 4.0339042 | Q26: 52.103358 | R26: 52.242706 | S26: 15.231675 | T26: 37.176733 | U26: 50.531865 | V26: 61.556683 | AD26: 18.49 | AE26: 44.273197 | AF26: 71.897367 | AG26: -5.1484774 | AH26: 206.17964 | AI26: 201.36416
A27: 1991M5 | B27: 105.7765 | C27: 109.00304 | D27: 50.495472 | E27: 63.986469 | F27: 8.1932169 | G27: 7.7954514 | H27: 25.101678 | I27: 11.112941 | J27: 12.505604 | K27: 29.219699 | L27: 20.668098 | M27: 82.821498 | N27: 4.0774253 | Q27: 48.774236 | R27: 52.242706 | S27: 15.342237 | T27: 37.4003 | U27: 50.793609 | V27: 61.807601 | AD27: 18.72 | AE27: 45.108066 | AF27: 72.823651 | AG27: -5.3268246 | AH27: 210.05599 | AI27: 205.10467
A28: 1991M6 | B28: 106.11954 | C28: 109.8483 | D28: 50.685422 | E28: 63.773231 | F28: 8.3817849 | G28: 7.8349017 | H28: 23.848407 | I28: 11.177839 | J28: 12.632306 | K28: 27.64234 | L28: 19.754628 | M28: 82.857766 | N28: 4.0231949 | Q28: 47.46047 | R28: 52.242706 | S28: 15.519202 | T28: 37.710648 | U28: 51.020038 | V28: 62.041292 | AD28: 17.78 | AE28: 43.608103 | AF28: 74.039224 | AG28: -2.9471217 | AH28: 204.5661 | AI28: 201.92088
A29: 1991M7 | B29: 105.86967 | C29: 109.75141 | D29: 50.876631 | E29: 64.328114 | F29: 8.3331844 | G29: 7.6497919 | H29: 24.956447 | I29: 11.23252 | J29: 12.725871 | K29: 28.951373 | L29: 20.669017 | M29: 82.770792 | N29: 3.9273901 | Q29: 45.930383 | R29: 52.242706 | S29: 15.759571 | T29: 38.088271 | U29: 51.26753 | V29: 62.273606 | AD29: 19.02 | AE29: 46.598285 | AF29: 72.267005 | AG29: -6.6242043 | AH29: 211.17367 | AI29: 204.87297
A30: 1991M8 | B30: 105.42458 | C30: 109.1287 | D30: 50.693852 | E30: 64.061363 | F30: 8.0410372 | G30: 7.5331555 | H30: 24.948298 | I30: 11.268009 | J30: 12.861592 | K30: 29.007244 | L30: 20.777752 | M30: 82.854299 | N30: 3.975763 | Q30: 47.387427 | R30: 52.242706 | S30: 15.963186 | T30: 38.454865 | U30: 51.441949 | V30: 62.470308 | AD30: 19.3 | AE30: 46.77816 | AF30: 71.029708 | AG30: -4.4024016 | AH30: 210.95699 | AI30: 206.86609
A31: 1991M9 | B31: 104.86761 | C31: 107.8504 | D31: 50.810871 | E31: 64.320508 | F31: 7.7846416 | G31: 7.1938334 | H31: 25.252212 | I31: 11.32418 | J31: 12.968305 | K31: 29.224076 | L31: 20.829253 | M31: 82.981104 | N31: 4.0146664 | Q31: 50.699127 | R31: 52.242706 | S31: 16.12185 | T31: 38.725055 | U31: 51.644707 | V31: 62.718693 | AD31: 19.95 | AE31: 47.725344 | AF31: 71.490928 | AG31: -4.6671969 | AH31: 213.88295 | AI31: 209.49836
A32: 1991M10 | B32: 101.48308 | C32: 102.00356 | D32: 51.015106 | E32: 64.395463 | F32: 7.6430148 | G32: 7.0513179 | H32: 26.020507 | I32: 11.393074 | J32: 13.229762 | K32: 29.75936 | L32: 21.348462 | M32: 83.08598 | N32: 4.0199583 | Q32: 49.690825 | R32: 52.242706 | S32: 16.437139 | T32: 39.272224 | U32: 51.854683 | V32: 62.897651 | AD32: 21.56 | AE32: 51.2623 | AF32: 70.083241 | AG32: -4.0199373 | AH32: 217.42571 | AI32: 213.70088
A33: 1991M11 | B33: 99.500857 | C33: 98.517895 | D33: 51.002728 | E33: 64.332826 | F33: 7.5594833 | G33: 6.7887872 | H33: 24.637211 | I33: 11.460838 | J33: 13.409447 | K33: 28.425931 | L33: 20.462706 | M33: 83.070715 | N33: 4.0453083 | Q33: 51.331064 | R33: 52.242706 | S33: 16.717709 | T33: 39.799074 | U33: 52.063073 | V33: 63.12383 | AD33: 20.41 | AE33: 47.715173 | AF33: 68.819061 | AG33: -1.1984588 | AH33: 220.2292 | AI33: 219.36324
A34: 1991M12 | B34: 99.224558 | C34: 98.246289 | D34: 50.610352 | E34: 63.833969 | F34: 7.3023264 | G34: 6.4824864 | H34: 26.006905 | I34: 11.536941 | J34: 13.569935 | K34: 30.888157 | L34: 22.174654 | M34: 82.991285 | N34: 4.0665032 | Q34: 51.101844 | R34: 52.242706 | S34: 16.95425 | T34: 40.173664 | U34: 52.246397 | V34: 63.302154 | AD34: 17.63 | AE34: 40.52036 | AF34: 68.755252 | AG34: -2.0864155 | AH34: 220.16971 | AI34: 218.5327
A35: 1992M1 | B35: 98.528361 | C35: 96.95769 | D35: 50.870273 | E35: 63.742584 | F35: 7.1715464 | G35: 6.1545573 | H35: 26.491494 | I35: 11.590866 | J35: 13.7764 | K35: 30.933791 | L35: 22.629282 | M35: 83.051439 | N35: 4.1345617 | P35: 50.254019 | Q35: 48.467677 | R35: 52.242706 | S35: 19.437947 | T35: 40.520456 | U35: 52.415968 | V35: 63.464959 | W35: 65.8159 | X35: 46.948673 | AA35: 53.878233 | AB35: 54.51602 | AC35: 45.011688 | AD35: 17.52 | AE35: 40.225371 | AF35: 67.201791 | AG35: -3.5624729 | AH35: 223.08563 | AI35: 219.76875
A36: 1992M2 | B36: 98.029969 | C36: 95.888164 | D36: 51.126879 | E36: 63.991257 | F36: 7.3549699 | G36: 6.1724543 | H36: 26.497097 | I36: 11.662883 | J36: 13.962783 | K36: 30.207302 | L36: 22.48542 | M36: 83.081817 | N36: 4.2768695 | P36: 50.247364 | Q36: 44.121634 | R36: 52.242706 | S36: 20.050797 | T36: 40.945017 | U36: 52.575926 | V36: 63.63192 | W36: 66.411709 | X36: 48.319412 | AA36: 54.31691 | AB36: 49.91186 | AC36: 44.36087 | AD36: 17.65 | AE36: 41.089686 | AF36: 68.202929 | AG36: -0.31315782 | AH36: 226.46113 | AI36: 226.49927
A37: 1992M3 | B37: 100.38045 | C37: 100.25818 | D37: 51.147522 | E37: 64.04875 | F37: 7.4888812 | G37: 6.1570527 | H37: 25.958013 | I37: 11.715211 | J37: 14.13337 | K37: 29.051796 | L37: 21.991082 | M37: 83.144534 | N37: 4.2960534 | P37: 50.273464 | Q37: 44.006519 | R37: 52.242706 | S37: 20.689405 | T37: 41.338497 | U37: 52.818345 | V37: 63.884856 | W37: 67.330671 | X37: 48.220121 | AA37: 54.596682 | AB37: 50.533712 | AC37: 44.020041 | AD37: 17.35 | AE37: 41.165326 | AF37: 68.573076 | AG37: -2.954955 | AH37: 222.47059 | AI37: 219.85003
A38: 1992M4 | B38: 102.70405 | C38: 104.46636 | D38: 51.208948 | E38: 64.279492 | F38: 7.4651584 | G38: 5.8096008 | H38: 25.885881 | I38: 11.757077 | J38: 14.268491 | K38: 29.218581 | L38: 22.264797 | M38: 83.216594 | N38: 4.2817709 | P38: 50.689243 | Q38: 42.97254 | R38: 52.242706 | S38: 21.259907 | T38: 41.745005 | U38: 52.983283 | V38: 64.0517 | W38: 64.459292 | X38: 48.628629 | AA38: 53.543374 | AB38: 51.972758 | AC38: 46.560816 | AD38: 18.65 | AE38: 44.087573 | AF38: 72.508877 | AG38: -4.1153961 | AH38: 227.16108 | AI38: 223.41298
A39: 1992M5 | B39: 104.46594 | C39: 107.65004 | D39: 50.954306 | E39: 63.853834 | F39: 7.3539937 | G39: 5.7414934 | H39: 26.284304 | I39: 11.794808 | J39: 14.416428 | K39: 30.004958 | L39: 22.671053 | M39: 83.254239 | N39: 4.3513274 | P39: 52.134939 | Q39: 40.89879 | R39: 52.242706 | S39: 21.868983 | T39: 42.214681 | U39: 53.180868 | V39: 64.247868 | W39: 66.748541 | X39: 48.605568 | AA39: 54.577398 | AB39: 54.754973 | AC39: 48.601984 | AD39: 19.52 | AE39: 45.566176 | AF39: 72.273732 | AG39: -2.7737231 | AH39: 226.48434 | AI39: 224.02552
A40: 1992M6 | B40: 104.58569 | C40: 107.73399 | D40: 51.08569 | E40: 64.30902 | F40: 7.2696369 | G40: 5.7284058 | H40: 24.939879 | I40: 11.832685 | J40: 14.501339 | K40: 28.653464 | L40: 21.56172 | M40: 83.279109 | N40: 4.2651362 | P40: 52.346674 | Q40: 39.672732 | R40: 50.690361 | S40: 22.518425 | T40: 42.620573 | U40: 53.338532 | V40: 64.417631 | W40: 63.74508 | X40: 48.725491 | AA40: 53.222498 | AB40: 55.870772 | AC40: 51.079817 | AD40: 20.88 | AE40: 47.918269 | AF40: 72.802168 | AG40: -6.9170601 | AH40: 236.15737 | AI40: 229.24031
...

Sheet Bloomberg
C1: Baltic
B3: month info
B4: year info
A5: 0 | B5: Security | C5: BDIY Index
A6: 2 | B6: Fields | C6: px_last
A7: 3 | B7: Start Date | C7: 43800
A8: 4 | B8: End Date
A9: D,W,M,Q,S,Y | B9: Per= | C9: D
A10: N,C,T,W,A | B10: Days= | C10: N
A11: C,P,E,B | B11: Fill= | C11: C
A12: TRUE,FALSE | B12: Dts= | C12: TRUE
A13: P,Y | B13: QtTyp=
A14: C,A,R,D | B14: Sort=
A15: USD | B15: Curr=
A16: G=Avg C=Last | B16: Quote= | C16: G
A17: Bloomberg Description | C17: =_xll.BDP(C5,"long_comp_name") -> #NAME?
B18: =_xll.BDH(C5,C6,C7,C8,$B$9&C9,$B$10&C10,$B$11&C11,$B$12&C12,$B$13&C13,$B$14&C14,$B$15&C15,$B$16&C16,"cols=2;rows=60") -> #NAME? | C18: 1568
B19: 43802 | C19: 1606
B20: 43803 | C20: 1599
B21: 43804 | C21: 1575
B22: 43805 | C22: 1558
B23: 43808 | C23: 1551
B24: 43809 | C24: 1528
B25: 43810 | C25: 1460
B26: 43811 | C26: 1388
B27: 43812 | C27: 1355
B28: 43815 | C28: 1315
B29: 43816 | C29: 1281
B30: 43817 | C30: 1221
... B61: 43860 | C61: 498
B62: 43861 | C62: 487 | E62: January Average | F62: =AVERAGE(C40:C62) -> 718
B63: 43864 | C63: 466 | E63: Feb Average | F63: =AVERAGE(C63:C77) -> 440
B64: 43865 | C64: 453
B65: 43866 | C65: 430
B66: 43867 | C66: 431
B67: 43868 | C67: 415
B68: 43871 | C68: 411
B69: 43872 | C69: 418
B70: 43873 | C70: 421
B71: 43874 | C71: 421
...

Sheet OECD
B1: OECDCLI | C1: CHEM
A2: ='Monthly Haver'!A5 -> Jan-1999 | B2: 99.50104 | C2: 95.61 | E2: CHEM: Comes from https://www.americanchemistry.com/CAB-vs-Industrial-Production/
A3: ='Monthly Haver'!A6 -> Feb-1999 | B3: 99.68887 | C3: 96.34 | E3: Download worksheet, look for CAB variable (first variable column).
A4: ='Monthly Haver'!A7 -> Mar-1999 | B4: 99.87469 | C4: 96.64
A5: ='Monthly Haver'!A8 -> Apr-1999 | B5: 100.0538 | C5: 97.25
A6: ='Monthly Haver'!A9 -> May-1999 | B6: 100.2218 | C6: 98.12
A7: ='Monthly Haver'!A10 -> Jun-1999 | B7: 100.3789 | C7: 98.7 | E7: OECDCLI: https://data.oecd.org/leadind/composite-leading-indicator-cli.htm
A8: ='Monthly Haver'!A11 -> Jul-1999 | B8: 100.5246 | C8: 98.78
A9: ='Monthly Haver'!A12 -> Aug-1999 | B9: 100.6616 | C9: 98.8
A10: ='Monthly Haver'!A13 -> Sep-1999 | B10: 100.7954 | C10: 98.59
A11: ='Monthly Haver'!A14 -> Oct-1999 | B11: 100.9314 | C11: 99.03
A12: ='Monthly Haver'!A15 -> Nov-1999 | B12: 101.0658 | C12: 100.26
A13: ='Monthly Haver'!A16 -> Dec-1999 | B13: 101.1871 | C13: 100.67
A14: ='Monthly Haver'!A17 -> Jan-2000 | B14: 101.2855 | C14: 100.84
A15: ='Monthly Haver'!A18 -> Feb-2000 | B15: 101.343 | C15: 100.41
A16: ='Monthly Haver'!A19 -> Mar-2000 | B16: 101.3606 | C16: 101.06
A17: ='Monthly Haver'!A20 -> Apr-2000 | B17: 101.3398 | C17: 101.16
A18: ='Monthly Haver'!A21 -> May-2000 | B18: 101.2792 | C18: 100.53
A19: ='Monthly Haver'!A22 -> Jun-2000 | B19: 101.1854 | C19: 100.36
... A242: ='Monthly Haver'!A245 -> Jan-2019 | B242: 99.54697 | C242: 121.4
A243: ='Monthly Haver'!A246 -> Feb-2019 | B243: 99.45459 | C243: 121.42 | G243: Sources:
A244: ='Monthly Haver'!A247 -> Mar-2019 | B244: 99.38396 | C244: 122.17 | G244: https://www.americanchemistry.com/CAB-vs-Industrial-Production/
A245: ='Monthly Haver'!A248 -> Apr-2019 | B245: 99.32558 | C245: 122.79
A246: ='Monthly Haver'!A249 -> May-2019 | B246: 99.26957 | C246: 122.29
A247: ='Monthly Haver'!A250 -> Jun-2019 | B247: 99.21947 | C247: 122.42
A248: ='Monthly Haver'!A251 -> Jul-2019 | B248: 99.18283 | C248: 122.93
A249: ='Monthly Haver'!A252 -> Aug-2019 | B249: 99.16628 | C249: 122.33
A250: ='Monthly Haver'!A253 -> Sep-2019 | B250: 99.17904 | C250: 122.57
A251: ='Monthly Haver'!A254 -> Oct-2019 | B251: 99.23029 | C251: 121.97
A252: ='Monthly Haver'!A255 -> Nov-2019 | B252: 99.31636 | C252: 122.42
A253: ='Monthly Haver'!A256 -> Dec-2019 | B253: 99.43238 | C253: 122.74
A254: ='Monthly Haver'!A257 -> Jan-2020 | C254: 124.64
A255: ='Monthly Haver'!A258 -> Feb-2020 | C255: 124.08

Sheet GDS_Quarterly
A1: EcDatabase | B1: ID:GDS_LIVE | C1: ID:GDS_LIVE | D1: ID:GDS_LIVE | E1: ID:GDS_LIVE | F1: ID:GDS_LIVE | G1: ID:GDS_LIVE | H1: ID:GDS_LIVE | I1: ID:GDS_LIVE | J1: ID:GDS_LIVE | K1: ID:GDS_LIVE | L1: ID:GDS_LIVE | M1: ID:GDS_LIVE | N1: ID:GDS_LIVE | O1: ID:GDS_LIVE | P1: ID:GDS_LIVE | Q1: ID:GDS_LIVE | R1: ID:GDS_LIVE | S1: ID:GDS_LIVE | T1: ID:GDS_LIVE | U1: ID:GDS_LIVE | V1: ID:GDS_LIVE | W1: ID:GDS_LIVE | X1: ID:GDS_LIVE | Y1: ID:GDS_LIVE | Z1: ID:GDS_LIVE | AA1: ID:GDS_LIVE | AB1: ID:GDS_LIVE | AC1: ID:GDS_LIVE | AD1: ID:GDS_LIVE | AE1: ID:GDS_LIVE | AF1: ID:GDS_LIVE | AG1: ID:GDS_LIVE | AH1: ID:GDS_LIVE | AI1: ID:GDS_LIVE | AJ1: ID:GDS_LIVE | AK1: ID:GDS_LIVE | AL1: ID:GDS_LIVE | AM1: ID:GDS_LIVE | AN1: ID:GDS_LIVE | AO1: ID:GDS_LIVE | AP1: ID:GDS_LIVE | AQ1: ID:GDS_LIVE | AR1: ID:GDS_LIVE | AS1: ID:GDS_LIVE | AT1: ID:GDS_LIVE | AU1: ID:GDS_LIVE | AV1: ID:GDS_LIVE | AW1: ID:GDS_LIVE | AX1: ID:GDS_LIVE | AY1: ID:GDS_LIVE | AZ1: ID:GDS_LIVE | BA1: ID:GDS_LIVE | BB1: ID:GDS_LIVE | BC1: ID:GDS_LIVE
A2: Series_code | B2: 001ACC_PPPWGT.Q | C2: 001ACC.Q | D2: 001AIP.Q | E2: 001AIP_GDPWGT.Q | F2: 001BCA.Q | G2: 001BCA_GDP.Q | H2: 001FIGB.Q | I2: 001FIPR.Q | J2: 001FISI.Q | K2: 001FMB.Q | L2: 001FMN.Q | M2: 001FMSCID.Q | N2: 001FMSCIL.Q | O2: 001LE.Q | P2: 001LUR.Q | Q2: 001NCP_R.Q | R2: 001NCP_R_GDPWGT.Q | S2: 001NFI_R.Q | T2: 001NFI_R_GDPWGT.Q | U2: 001NGDP_R.Q | V2: 001NGDP_R_GDPWGT.Q | W2: 001NGDP_RF.Q | X2: 001NGDP_RF_GDPWGT.Q | Y2: 001NGDPD.Q | Z2: 001NM_R.Q | AA2: 001NM_R_GDPWGT.Q | AB2: 001NM_R_TMWGT.Q | AC2: 001NRS.Q | AD2: 001NTDD_R.Q | AE2: 001NTDD_R_GDPWGT.Q | AF2: 001NX_R.Q | AG2: 001NX_R_GDPWGT.Q | AH2: 001NX_R_TXWGT.Q | AI2: 001PALLFNFW.Q | AJ2: 001PBEVEW.Q | AK2: 001PCOALW.Q | AL2: 001PCPI.Q | AM2: 001PCPI_GDPWGT.Q | AN2: 001PCPIF.Q | AO2: 001PCPIX.Q | AP2: 001.Q | AQ2: 001PFOODW.Q | AR2: 001PMETAW.Q | AS2: 001PMI.Q | AT2: 001PMI_PPPWGT.Q | AU2: 001PNFUELW.Q | AV2: 001PNGASW.Q | AW2: 001PNRGW.Q | AX2: 001POILAPSP.Q | AY2: 001POILAPSPW.Q | AZ2: 001PRAWMW.Q | BA2: 001TG.Q | BB2: 001TMG.Q | BC2: 001TXG.Q
A3: Country | B3: World | C3: World | D3: World | E3: World | F3: World | G3: World | H3: World | I3: World | J3: World | K3: World | L3: World | M3: World | N3: World | O3: World | P3: World | Q3: World | R3: World | S3: World | T3: World | U3: World | V3: World | W3: World | X3: World | Y3: World | Z3: World | AA3: World | AB3: World | AC3: World | AD3: World | AE3: World | AF3: World | AG3: World | AH3: World | AI3: World | AJ3: World | AK3: World | AL3: World | AM3: World | AN3: World | AO3: World | AP3: World | AQ3: World | AR3: World | AS3: World | AT3: World | AU3: World | AV3: World | AW3: World | AX3: World | AY3: World | AZ3: World | BA3: World | BB3: World | BC3: World
A4: Indicator | B4: ACC_PPPWGT | C4: ACC | D4: AIP | E4: AIP_GDPWGT | F4: BCA | G4: BCA_GDP | H4: FIGB | I4: FIPR | J4: FISI | K4: FMB | L4: FMN | M4: FMSCID | N4: FMSCIL | O4: LE | P4: LUR | Q4: NCP_R | R4: NCP_R_GDPWGT | S4: NFI_R | T4: NFI_R_GDPWGT | U4: NGDP_R | V4: NGDP_R_GDPWGT | W4: NGDP_RF | X4: NGDP_RF_GDPWGT | Y4: NGDPD | Z4: NM_R | AA4: NM_R_GDPWGT | AB4: NM_R_TMWGT | AC4: NRS | AD4: NTDD_R | AE4: NTDD_R_GDPWGT | AF4: NX_R | AG4: NX_R_GDPWGT | AH4: NX_R_TXWGT | AI4: PALLFNFW | AJ4: PBEVEW | AK4: PCOALW | AL4: PCPI | AM4: PCPI_GDPWGT | AN4: PCPIF | AO4: PCPIX | AP4: PCPIX_GDPWGT | AQ4: PFOODW | AR4: PMETAW | AS4: PMI | AT4: PMI_PPPWGT | AU4: PNFUELW | AV4: PNGASW | AW4: PNRGW | AX4: POILAPSP | AY4: POILAPSPW | AZ4: PRAWMW | BA4: TG | BB4: TMG | BC4: TXG
A5: Indicator.Descriptor | B5: Consumer confidence, PPP weighted | C5: Consumer confidence | D5: Industrial production | E5: Industrial production, MER weighted | F5: Current account balance | G5: Current account balance, percent of GDP | H5: Long-term interest rate | I5: Policy-related interest rate | J5: Benchmark stock market index | K5: Broad money | L5: Narrow money | M5: Morgan Stanley MSCI stock price index in US dollars | N5: Morgan Stanley MSCI stock price index in national currency | O5: Employment | P5: Unemployment rate | Q5: Real private consumption | R5: Real private consumption, MER weighted | S5: Real gross fixed capital formation | T5: Real gross fixed capital formation, MER weighted | U5: Real gross domestic product | V5: Real gross domestic product, MER weighted | W5: Real gross domestic product, with projections from WEO | X5: Real gross domestic product, with projections from WEO, MER weighted | Y5: Nominal gross domestic product, US dollars | Z5: Real imports | AA5: Real imports, MER weighted | AB5: Real imports, imports weighted | AC5: Retail sales | AD5: Real total domestic demand | AE5: Real total domestic demand, MER weighted | AF5: Real exports | AG5: Real exports, MER weighted | AH5: Real exports, exports weighted | AI5: Commodity price: all primary commodities | AJ5: Commodity price: beverage | AK5: Commodity price: coal | AL5: Consumer price index | AM5: Consumer price index, MER weighted | AN5: Consumer price index, with projections from WEO | AO5: Core consumer price index | AP5: Core consumer price index, GDP weighted | AQ5: Commodity price: food | AR5: Commodity price: metals | AS5: Manufacturing PMI | AT5: Manufacturing PMI, PPP weighted | AU5: Commodity price: non-fuel primary commodities | AV5: Commodity price: natural gas | AW5: Commodity price: energy | AX5: Commodity price: petroleum, US dollar per barrel | AY5: Commodity price: petroleum | AZ5: Commodity price: raw materials | BA5: Merchandise trade balance | BB5: Merchandise imports | BC5: Merchandise exports
A6: Frequency | B6: Quarterly | C6: Quarterly | D6: Quarterly | E6: Quarterly | F6: Quarterly | G6: Quarterly | H6: Quarterly | I6: Quarterly | J6: Quarterly | K6: Quarterly | L6: Quarterly | M6: Quarterly | N6: Quarterly | O6: Quarterly | P6: Quarterly | Q6: Quarterly | R6: Quarterly | S6: Quarterly | T6: Quarterly | U6: Quarterly | V6: Quarterly | W6: Quarterly | X6: Quarterly | Y6: Quarterly | Z6: Quarterly | AA6: Quarterly | AB6: Quarterly | AC6: Quarterly | AD6: Quarterly | AE6: Quarterly | AF6: Quarterly | AG6: Quarterly | AH6: Quarterly | AI6: Quarterly | AJ6: Quarterly | AK6: Quarterly | AL6: Quarterly | AM6: Quarterly | AN6: Quarterly | AO6: Quarterly | AP6: Quarterly | AQ6: Quarterly | AR6: Quarterly | AS6: Quarterly | AT6: Quarterly | AU6: Quarterly | AV6: Quarterly | AW6: Quarterly | AX6: Quarterly | AY6: Quarterly | AZ6: Quarterly | BA6: Quarterly | BB6: Quarterly | BC6: Quarterly
A7: Scale | B7: Units | C7: Units | D7: Units | E7: Units | F7: Billions | G7: Units | H7: Units | I7: Units | J7: Units | K7: Units | L7: Units | M7: Units | N7: Units | O7: Units | P7: Units | Q7: Units | R7: Units | S7: Units | T7: Units | U7: Units | V7: Units | W7: Units | X7: Units | Y7: Billions | Z7: Units | AA7: Units | AB7: Units | AC7: Units | AD7: Units | AE7: Units | AF7: Units | AG7: Units | AH7: Units | AI7: Units | AJ7: Units | AK7: Units | AL7: Units | AM7: Units | AN7: Units | AO7: Units | AP7: Units | AQ7: Units | AR7: Units | AS7: Units | AT7: Units | AU7: Units | AV7: Units | AW7: Units | AX7: Units | AY7: Units | AZ7: Units | BA7: Billions | BB7: Billions | BC7: Billions
A8: Display_scale | B8: Units | C8: Units | D8: Units | E8: Units | F8: Billions | G8: Units | H8: Units | I8: Units | J8: Units | K8: Units | L8: Units | M8: Units | N8: Units | O8: Units | P8: Units | Q8: Units | R8: Units | S8: Units | T8: Units | U8: Units | V8: Units | W8: Units | X8: Units | Y8: Billions | Z8: Units | AA8: Units | AB8: Units | AC8: Units | AD8: Units | AE8: Units | AF8: Units | AG8: Units | AH8: Units | AI8: Units | AJ8: Units | AK8: Units | AL8: Units | AM8: Units | AN8: Units | AO8: Units | AP8: Units | AQ8: Units | AR8: Units | AS8: Units | AT8: Units | AU8: Units | AV8: Units | AW8: Units | AX8: Units | AY8: Units | AZ8: Units | BA8: Billions | BB8: Billions | BC8: Billions
A9: 1990Q1 | B9: 114.57716 | C9: 123.95658 | D9: 49.610915 | E9: 63.676787 | F9: -39.321559 | G9: -1.1090686 | H9: 8.5859571 | I9: 12.8652 | J9: 23.048825 | K9: 10.002343 | L9: 11.147585 | M9: 25.138839 | N9: 17.108852 | O9: 81.58033 | P9: 3.3603761 | Q9: 47.454501 | R9: 56.619681 | S9: 42.902703 | T9: 59.965452 | U9: 48.90739 | V9: 58.402007 | W9: 49.885179 | X9: 58.92731 | Y9: 3545.4578 | Z9: 22.271797 | AA9: 30.804851 | AB9: 29.797069 | AD9: 48.879127 | AE9: 58.941664 | AF9: 23.76231 | AG9: 30.227676 | AH9: 29.113541 | AJ9: 51.195456 | AK9: 51.172528 | AL9: 11.95076 | AM9: 30.826818 | AN9: 4.5174393 | AO9: 47.450264 | AP9: 58.113838 | AX9: 19.463333 | AZ9: 73.492273 | BA9: -12.310158 | BB9: 585.48544 | BC9: 573.17528
A10: 1990Q2 | B10: 113.72542 | C10: 122.37419 | D10: 49.692991 | E10: 64.068947 | F10: -31.530476 | G10: -0.8903193 | H10: 8.8730628 | I10: 10.074507 | J10: 24.468707 | K10: 10.290694 | L10: 11.463502 | M10: 27.335213 | N10: 18.434519 | O10: 82.463691 | P10: 3.4088283 | Q10: 47.996259 | R10: 57.280292 | S10: 42.482857 | T10: 59.560934 | U10: 49.132618 | V10: 58.84342 | W10: 50.078028 | X10: 59.362381 | Y10: 3541.4796 | Z10: 22.353061 | AA10: 30.956948 | AB10: 30.010831 | AD10: 49.303633 | AE10: 59.489536 | AF10: 23.892262 | AG10: 30.603044 | AH10: 29.39376 | AJ10: 55.091301 | AK10: 53.525874 | AL10: 12.658284 | AM10: 32.173583 | AN10: 4.8907648 | AO10: 48.071113 | AP10: 58.824033 | AX10: 15.82 | AZ10: 75.668164 | BA10: -11.345707 | BB10: 587.08275 | BC10: 575.73705
A11: 1990Q3 | B11: 109.61725 | C11: 115.48501 | D11: 50.199927 | E11: 64.561472 | F11: -31.341681 | G11: -0.84952419 | H11: 9.0608422 | I11: 10.065118 | J11: 20.261359 | K11: 10.560172 | L11: 11.670862 | M11: 22.814 | N11: 15.094139 | O11: 82.68347 | P11: 3.46503 | Q11: 48.308419 | R11: 57.602174 | S11: 44.098994 | T11: 60.310768 | U11: 49.514114 | V11: 59.197831 | W11: 50.447389 | X11: 59.701264 | Y11: 3689.3218 | Z11: 22.529919 | AA11: 30.83848 | AB11: 29.859349 | AD11: 49.461895 | AE11: 59.627623 | AF11: 24.380517 | AG11: 30.886802 | AH11: 29.669397 | AJ11: 54.592727 | AK11: 55.284677 | AL11: 13.458476 | AM11: 33.770376 | AN11: 5.4327878 | AO11: 48.746334 | AP11: 59.621595 | AX11: 25.656667 | AZ11: 74.436365 | BA11: -16.835061 | BB11: 617.58435 | BC11: 601.69359
A12: 1990Q4 | B12: 101.68114 | C12: 101.97022 | D12: 50.10402 | E12: 64.293609 | F12: -33.280688 | G12: -0.86949116 | H12: 8.7511308 | I12: 9.4848882 | J12: 21.933351 | K12: 10.747179 | L12: 11.945251 | M12: 24.645852 | N12: 16.53637 | O12: 82.588915 | P12: 3.5673421 | Q12: 48.169026 | R12: 57.35894 | S12: 43.739078 | T12: 59.88237 | U12: 49.584453 | V12: 59.100944 | W12: 50.443883 | X12: 59.551707 | Y12: 3827.6051 | Z12: 22.594528 | AA12: 30.906512 | AB12: 29.961992 | AD12: 49.425737 | AE12: 59.352199 | AF12: 24.801093 | AG12: 31.437589 | AH12: 30.21401 | AJ12: 56.046732 | AK12: 55.284677 | AL12: 14.169128 | AM12: 35.173732 | AN12: 5.8224907 | AO12: 49.417072 | AP12: 60.312896 | AX12: 31 | AZ12: 72.947571 | BA12: -30.885163 | BB12: 665.50267 | BC12: 635.9609
A13: 1991Q1 | B13: 102.64214 | C13: 103.70414 | D13: 50.534799 | E13: 63.635536 | F13: -4.2691369 | G13: -0.1112018 | H13: 8.1974964 | I13: 9.4124759 | J13: 24.4134 | K13: 10.957662 | L13: 12.265427 | M13: 28.011022 | N13: 19.683323 | O13: 82.839187 | P13: 3.9379885 | Q13: 48.222368 | R13: 57.288128 | S13: 43.158562 | T13: 59.154513 | U13: 49.439196 | V13: 59.001864 | W13: 50.271907 | X13: 59.442887 | Y13: 3839.0898 | Z13: 22.184072 | AA13: 30.217621 | AB13: 29.576016 | AD13: 49.248609 | AE13: 59.21465 | AF13: 25.073097 | AG13: 31.539852 | AH13: 30.241904 | AJ13: 53.346582 | AK13: 54.270686 | AL13: 14.845113 | AM13: 36.465336 | AN13: 6.2696693 | AO13: 50.188609 | AP13: 61.210213 | AX13: 19.85 | AY13: 45.410521 | AZ13: 71.599601 | BA13: -23.263209 | BB13: 654.20121 | BC13: 632.0575
A14: 1991Q2 | B14: 106.14761 | C14: 109.80223 | D14: 50.487566 | E14: 63.747281 | F14: 3.3422451 | G14: 0.087525572 | H14: 8.2555072 | I14: 7.8664612 | J14: 23.848407 | K14: 11.177839 | L14: 12.632306 | M14: 27.64234 | N14: 19.754628 | O14: 82.85367 | P14: 4.0448415 | Q14: 48.919939 | R14: 57.967412 | S14: 43.368928 | T14: 59.087744 | U14: 50.027521 | V14: 59.53345 | W14: 50.809346 | X14: 59.937718 | Y14: 3818.5927 | Z14: 22.830031 | AA14: 30.819553 | AB14: 30.104496 | AD14: 49.625971 | AE14: 59.61803 | AF14: 25.888054 | AG14: 32.424379 | AH14: 31.194186 | AJ14: 49.446021 | AK14: 52.242706 | AL14: 15.364372 | AM14: 37.429227 | AN14: 6.5921321 | AO14: 50.781838 | AP14: 61.801858 | AX14: 18.33 | AY14: 44.329788 | AZ14: 72.920081 | BA14: -13.422424 | BB14: 620.80173 | BC14: 608.38971
A15: 1991Q3 | B15: 105.38728 | C15: 108.91017 | D15: 50.793785 | E15: 64.236662 | F15: -6.0306232 | G15: -0.15571677 | H15: 8.0529544 | I15: 7.4589269 | J15: 25.252212 | K15: 11.32418 | L15: 12.968305 | M15: 29.224076 | N15: 20.829253 | O15: 82.868732 | P15: 3.9726065 | Q15: 49.386586 | R15: 58.331711 | S15: 43.729284 | T15: 59.320526 | U15: 50.481992 | V15: 59.869153 | W15: 51.138992 | X15: 60.200869 | Y15: 3872.8156 | Z15: 23.491438 | AA15: 31.630021 | AB15: 30.843919 | AD15: 50.192894 | AE15: 60.012121 | AF15: 26.052484 | AG15: 32.886647 | AH15: 31.574332 | AJ15: 48.005646 | AK15: 52.242706 | AL15: 15.948203 | AM15: 38.42273 | AN15: 6.9683222 | AO15: 51.451395 | AP15: 62.487536 | AX15: 19.423333 | AY15: 47.03393 | AZ15: 71.59588 | BA15: -15.693803 | BB15: 636.01362 | BC15: 621.23742
A16: 1991Q4 | B16: 100.0695 | C16: 99.589247 | D16: 50.876062 | E16: 64.187419 | F16: 6.2783686 | G16: 0.15690032 | H16: 7.5016082 | I16: 6.7741972 | J16: 26.006905 | K16: 11.536941 | L16: 13.569935 | M16: 30.888157 | N16: 22.174654 | O16: 83.049327 | P16: 4.0439232 | Q16: 49.618253 | R16: 58.57445 | S16: 43.999846 | T16: 59.486362 | U16: 50.793182 | V16: 60.180055 | W16: 51.300929 | X16: 60.437241 | Y16: 4001.5015 | Z16: 24.121961 | AA16: 32.238018 | AB16: 31.276994 | AD16: 50.411298 | AE16: 60.206084 | AF16: 26.749704 | AG16: 33.643549 | AH16: 32.171823 | AJ16: 50.707911 | AK16: 52.242706 | AL16: 16.703033 | AM16: 39.748321 | AN16: 7.5211591 | AO16: 52.054717 | AP16: 63.107878 | AX16: 19.866667 | AY16: 46.499278 | AZ16: 69.219185 | BA16: -7.3048117 | BB16: 657.82463 | BC16: 651.59682
A17: 1992Q1 | B17: 98.979594 | C17: 97.701345 | D17: 51.048225 | E17: 63.92753 | F17: -0.54879872 | G17: -0.013563717 | H17: 7.3384658 | I17: 6.1613548 | J17: 25.958013 | K17: 11.715211 | L17: 14.13337 | M17: 29.051796 | N17: 21.991082 | O17: 83.092596 | P17: 4.2358282 | Q17: 49.975695 | R17: 59.198762 | S17: 44.335697 | T17: 59.591735 | U17: 51.33632 | V17: 60.693203 | W17: 51.732251 | X17: 60.896221 | Y17: 4046.0791 | Z17: 24.506206 | AA17: 32.529187 | AB17: 31.729678 | AD17: 50.869186 | AE17: 60.671003 | AF17: 27.431198 | AG17: 34.290457 | AH17: 32.832818 | AI17: 50.258283 | AJ17: 45.531943 | AK17: 52.242706 | AL17: 20.059383 | AM17: 40.934657 | AN17: 10.419023 | AO17: 52.603413 | AP17: 63.660579 | AQ17: 66.519427 | AR17: 47.829402 | AU17: 54.263942 | AV17: 51.653864 | AW17: 44.4642 | AX17: 17.506667 | AY17: 40.826794 | AZ17: 67.992599 | BA17: -6.8305857 | BB17: 672.01734 | BC17: 666.11806
A18: 1992Q2 | B18: 103.91856 | C18: 106.6168 | D18: 51.082981 | E18: 64.147448 | F18: -8.2186637 | G18: -0.20072862 | H18: 7.3629297 | I18: 5.7598333 | J18: 24.939879 | K18: 11.832685 | L18: 14.501339 | M18: 28.653464 | N18: 21.56172 | O18: 83.249981 | P18: 4.2994115 | Q18: 50.49074 | R18: 59.556844 | S18: 45.143591 | T18: 60.506912 | U18: 51.749078 | V18: 61.074851 | W18: 52.137748 | X18: 61.272429 | Y18: 4094.4154 | Z18: 25.018509 | AA18: 33.060568 | AB18: 32.342648 | AD18: 51.430872 | AE18: 61.15527 | AF18: 27.501555 | AG18: 34.445037 | AH18: 33.047754 | AI18: 51.723619 | AJ18: 41.181354 | AK18: 51.725258 | AL18: 21.882438 | AM18: 42.19342 | AN18: 11.982565 | AO18: 53.167561 | AP18: 64.239066 | AQ18: 64.984304 | AR18: 48.653229 | AU18: 53.78109 | AV18: 54.199501 | AW18: 48.747539 | AX18: 19.683333 | AY18: 45.857339 | AZ18: 72.528259 | BA18: -13.806179 | BB18: 689.80279 | BC18: 676.67881
A19: 1992Q3 | B19: 100.99172 | C19: 101.20892 | D19: 51.108131 | E19: 64.497915 | F19: -12.672036 | G19: -0.29963426 | H19: 6.8129193 | I19: 5.4484827 | J19: 25.058766 | K19: 11.991291 | L19: 14.983063 | M19: 29.108061 | N19: 22.248486 | O19: 83.341424 | P19: 4.2717723 | Q19: 50.959187 | R19: 60.013287 | S19: 45.491978 | T19: 60.621606 | U19: 52.277747 | V19: 61.59549 | W19: 52.66082 | X19: 61.788012 | Y19: 4229.1681 | Z19: 25.255727 | AA19: 33.239037 | AB19: 32.526455 | AD19: 51.782821 | AE19: 61.580107 | AF19: 28.111755 | AG19: 35.007429 | AH19: 33.514844 | AI19: 52.13722 | AJ19: 41.845637 | AK19: 49.138015 | AL19: 23.629282 | AM19: 43.446128 | AN19: 13.540622 | AO19: 53.682183 | AP19: 64.718098 | AQ19: 63.082407 | AR19: 50.141161 | AU19: 53.176748 | AV19: 61.388955 | AW19: 50.633568 | AX19: 19.996667 | AY19: 44.615931 | AZ19: 72.227941 | BA19: -11.577064 | BB19: 721.76381 | BC19: 710.18675
A20: 1992Q4 | B20: 102.40385 | C20: 104.19516 | D20: 51.245665 | E20: 64.638415 | F20: -7.9428396 | G20: -0.18932182 | H20: 6.7318076 | I20: 4.8908571 | J20: 25.639143 | K20: 12.164012 | L20: 15.497241 | M20: 29.418506 | N20: 23.8457 | O20: 83.436844 | P20: 4.2706197 | Q20: 51.502053 | R20: 60.443607 | S20: 45.966834 | T20: 60.887704 | U20: 52.595833 | V20: 61.9166 | W20: 52.953234 | X20: 62.096682 | Y20: 4195.4169 | Z20: 25.922482 | AA20: 33.766728 | AB20: 32.987577 | AD20: 51.980817 | AE20: 61.782192 | AF20: 28.837971 | AG20: 35.621344 | AH20: 34.213053 | AI20: 50.557026 | AJ20: 46.601668 | AK20: 46.462571 | AL20: 25.735198 | AM20: 44.947416 | AN20: 15.560854 | AO20: 54.219145 | AP20: 65.247916 | AQ20: 61.231113 | AR20: 44.892083 | AU20: 51.344047 | AV20: 65.947681 | AW20: 49.418622 | AX20: 18.956667 | AY20: 43.745614 | AZ20: 72.125898 | BA20: -9.4854212 | BB20: 705.48371 | BC20: 695.99829
A21: 1993Q1 | B21: 103.24847 | C21: 105.51122 | D21: 51.487975 | E21: 65.158724 | F21: -5.7876936 | G21: -0.13269153 | H21: 6.2895059 | I21: 4.5145208 | J21: 27.21316 | K21: 12.50483 | L21: 16.407767 | M21: 31.639239 | N21: 25.826285 | O21: 83.554679 | P21: 4.9602999 | Q21: 52.640917 | R21: 61.292826 | S21: 47.14364 | T21: 61.592522 | U21: 53.111071 | V21: 62.308641 | W21: 53.477523 | X21: 62.486482 | Y21: 4361.7656 | Z21: 26.897003 | AA21: 34.593486 | AB21: 33.780769 | AD21: 52.604998 | AE21: 62.197379 | AF21: 30.382313 | AG21: 36.817071 | AH21: 35.403096 | AI21: 50.034526 | AJ21: 45.135889 | AK21: 44.024943 | AL21: 27.808968 | AM21: 46.829245 | AN21: 17.57456 | AO21: 54.798433 | AP21: 65.778121 | AQ21: 62.812453 | AR21: 43.882471 | AU21: 52.039682 | AV21: 63.018192 | AW21: 47.13412 | AX21: 17.99 | AY21: 42.3372 | AZ21: 76.160493 | BA21: -0.19124414 | BB21: 687.8729 | BC21: 687.68165
A22: 1993Q2 | B22: 101.749 | C22: 102.87849 | D22: 51.796828 | E22: 65.576903 | F22: -19.011224 | G22: -0.41978226 | H22: 6.1341952 | I22: 4.2917927 | J22: 28.6376 | K22: 17.852794 | L22: 17.561017 | M22: 33.813197 | N22: 27.909577 | O22: 83.694154 | P22: 4.9812768 | Q22: 53.222521 | R22: 61.72581 | S22: 47.784674 | T22: 62.025543 | U22: 53.615739 | V22: 62.671143 | W22: 53.958127 | X22: 62.833186 | Y22: 4528.8297 | Z22: 27.444794 | AA22: 35.099275 | AB22: 34.268182 | AD22: 53.206911 | AE22: 62.63286 | AF22: 30.354299 | AG22: 36.843324 | AH22: 35.571613 | AI22: 50.992396 | AJ22: 42.162183 | AK22: 43.073674 | AL22: 30.417039 | AM22: 49.476246 | AN22: 20.42259 | AO22: 55.469412 | AP22: 66.390493 | AQ22: 64.308096 | AR22: 40.780315 | AU22: 53.365152 | AV22: 65.690285 | AW22: 47.560264 | AX22: 17.993333 | AY22: 41.253286 | AZ22: 86.622907 | BA22: -3.4746474 | BB22: 717.91602 | BC22: 714.44137
A23: 1993Q3 | B23: 101.43717 | C23: 102.29282 | D23: 52.147282 | E23: 65.946824 | F23: -18.41809 | G23: -0.39928018 | H23: 5.677141 | I23: 4.2543031 | J23: 29.880758 | K23: 21.832706 | L23: 18.795 | M23: 35.582569 | N23: 30.299742 | O23: 83.902125 | P23: 4.986375 | Q23: 53.896423 | R23: 62.332828 | S23: 48.346594 | T23: 62.320425 | U23: 54.067867 | V23: 63.024689 | W23: 54.385599 | X23: 63.172901 | Y23: 4612.8236 | Z23: 28.4596 | AA23: 35.88201 | AB23: 34.9352 | AD23: 53.733707 | AE23: 63.024283 | AF23: 30.795054 | AG23: 37.152911 | AH23: 35.958918 | AI23: 49.595479 | AJ23: 50.310757 | AK23: 43.073674 | AL23: 33.886944 | AM23: 52.843346 | AN23: 24.600056 | AO23: 56.076753 | AP23: 66.889485 | AQ23: 63.670136 | AR23: 39.651704 | AU23: 53.210871 | AV23: 65.329983 | AW23: 44.365908 | AX23: 16.2 | AY23: 37.405873 | AZ23: 85.740496 | BA23: -0.9447507 | BB23: 718.93549 | BC23: 717.99074
A24: 1993Q4 | B24: 104.15099 | C24: 106.98842 | D24: 52.828155 | E24: 66.455809 | F24: -22.279986 | G24: -0.47682848 | H24: 5.3968968 | I24: 4.0395384 | J24: 32.042274 | K24: 22.854827 | L24: 25.921096 | M24: 37.684721 | N24: 33.524496 | O24: 84.048738 | P24: 4.9896452 | Q24: 54.630786 | R24: 63.121061 | S24: 49.494438 | T24: 63.530318 | U24: 54.674231 | V24: 63.679982 | W24: 54.978026 | X24: 63.822091 | Y24: 4672.5366 | Z24: 29.271835 | AA24: 36.886785 | AB24: 35.827522 | AD24: 54.387403 | AE24: 63.732312 | AF24: 31.668269 | AG24: 37.927463 | AH24: 36.672803 | AI24: 48.580649 | AJ24: 54.312888 | AK24: 42.944312 | AL24: 37.592803 | AM24: 56.120641 | AN24: 29.460842 | AO24: 56.636658 | AP24: 67.395588 | AQ24: 64.978977 | AR24: 37.491932 | AU24: 53.365886 | AV24: 63.126565 | AW24: 41.658927 | AX24: 14.963333 | AY24: 34.768052 | AZ24: 83.352583 | BA24: 2.4185888 | BB24: 732.1666 | BC24: 734.58518
A25: 1994Q1 | B25: 107.36886 | C25: 107.41858 | D25: 53.634238 | E25: 67.323183 | F25: -8.7345659 | G25: -0.18598883 | H25: 6.0863743 | I25: 3.9730805 | J25: 31.728389 | K25: 26.897378 | L25: 26.568753 | M25: 37.402626 | N25: 33.968623 | O25: 84.423521 | P25: 5.3174852 | Q25: 55.004444 | R25: 63.679636 | S25: 50.30673 | T25: 64.170732 | U25: 55.357627 | V25: 64.443543 | W25: 55.661376 | X25: 64.584698 | Y25: 4696.2852 | Z25: 29.879196 | AA25: 37.880387 | AB25: 36.796127 | AD25: 55.135578 | AE25: 64.544005 | AF25: 32.192312 | AG25: 38.784959 | AH25: 37.373901 | AI25: 49.703681 | AJ25: 54.613994 | AK25: 42.716948 | AL25: 40.607174 | AM25: 58.301998 | AN25: 33.496127 | AO25: 57.215119 | AP25: 67.835323 | AQ25: 68.568639 | AR25: 41.210151 | AU25: 56.429343 | AV25: 63.361327 | AW25: 39.975184 | AX25: 13.87 | AY25: 32.400629 | AZ25: 87.670608 | BA25: -2.1554525 | BB25: 748.78378 | BC25: 746.62832
A26: 1994Q2 | B26: 108.77435 | C26: 109.64331 | D26: 54.751041 | E26: 68.739901 | F26: -13.97817 | G26: -0.28879549 | H26: 6.9597779 | I26: 4.3642008 | J26: 31.809771 | K26: 27.508793 | L26: 27.066818 | M26: 37.901309 | N26: 34.999701 | O26: 84.641415 | P26: 5.2586926 | Q26: 55.486939 | R26: 64.164266 | S26: 51.330566 | T26: 65.314858 | U26: 55.976299 | V26: 65.00473 | W26: 56.252092 | X26: 65.131973 | Y26: 4840.1622 | Z26: 30.899304 | AA26: 39.054808 | AB26: 38.119965 | AD26: 55.740955 | AE26: 65.20271 | AF26: 33.8106 | AG26: 40.031659 | AH26: 38.58444 | AI26: 51.592128 | AJ26: 73.330981 | AK26: 43.818486 | AL26: 43.96514 | AM26: 60.367451 | AN26: 38.545627 | AO26: 57.775896 | AP26: 68.316383 | AQ26: 66.832474 | AR26: 44.029156 | AU26: 57.526776 | AV26: 57.867371 | AW26: 43.007813 | AX26: 16.27 | AY26: 37.247286 | AZ26: 96.131796 | BA26: 1.2714055 | BB26: 796.94559 | BC26: 798.217
A27: 1994Q3 | B27: 107.85682 | C27: 109.41925 | D27: 55.792834 | E27: 69.810736 | F27: -11.579537 | G27: -0.22999331 | H27: 7.5210742 | I27: 4.6320622 | J27: 34.013745 | K27: 28.074749 | L27: 28.066447 | M27: 40.157584 | N27: 36.802396 | O27: 84.779237 | P27: 5.2480783 | Q27: 56.435045 | R27: 64.892774 | S27: 52.01315 | T27: 66.070513 | U27: 56.702932 | V27: 65.701311 | W27: 56.951785 | X27: 65.814704 | Y27: 5034.7279 | Z27: 31.71023 | AA27: 40.020234 | AB27: 38.971956 | AD27: 56.330936 | AE27: 65.772738 | AF27: 34.770004 | AG27: 41.16815 | AH27: 39.60127 | AI27: 53.248013 | AJ27: 118.69993 | AK27: 45.865544 | AL27: 46.317076 | AM27: 61.862273 | AN27: 41.413241 | AO27: 58.381509 | AP27: 68.814325 | AQ27: 65.424484 | AR27: 48.093674 | AU27: 59.543089 | AV27: 56.124686 | AW27: 44.142348 | AX27: 17.05 | AY27: 37.902343 | AZ27: 96.457375 | BA27: -3.3664787 | BB27: 844.76697 | BC27: 841.4005
A28: 1994Q4 | B28: 109.98042 | C28: 111.49418 | D28: 56.993701 | E28: 71.272003 | F28: -29.106937 | G28: -0.56613454 | H28: 7.8544488 | I28: 5.0711117 | J28: 33.337011 | K28: 28.492526 | L28: 28.186371 | M28: 38.557301 | N28: 35.748417 | O28: 85.059932 | P28: 5.0782535 | Q28: 57.148192 | R28: 65.50151 | S28: 53.285493 | T28: 67.194471 | U28: 57.396018 | V28: 66.311079 | W28: 57.619736 | X28: 66.411255 | Y28: 5141.3462 | Z28: 33.581246 | AA28: 41.657732 | AB28: 40.614016 | AD28: 57.040181 | AE28: 66.411186 | AF28: 36.09869 | AG28: 42.324993 | AH28: 40.796419 | AI28: 53.890599 | AJ28: 105.66132 | AK28: 48.454747 | AL28: 48.203235 | AM28: 62.92802 | AN28: 43.904545 | AO28: 59.005054 | AP28: 69.330158 | AQ28: 66.072537 | AR28: 55.404847 | AU28: 60.986447 | AV28: 54.790314 | AW28: 43.626638 | AX28: 16.603333 | AY28: 36.697972 | AZ28: 95.652185 | BA28: -10.118334 | BB28: 894.66472 | BC28: 884.54638
A29: 1995Q1 | B29: 110.59681 | C29: 112.2343 | D29: 57.445947 | E29: 71.613688 | F29: -10.343759 | G29: -0.14646236 | H29: 7.6740672 | I29: 6.9718789 | J29: 32.569764 | K29: 28.802973 | L29: 28.271585 | M29: 38.667632 | N29: 34.74634 | O29: 85.144935 | P29: 5.4197161 | Q29: 57.540985 | R29: 65.806257 | S29: 53.26313 | T29: 67.118094 | U29: 57.980309 | V29: 66.776957 | W29: 58.187639 | X29: 66.867122 | Y29: 7062.4011 | Z29: 34.203493 | AA29: 42.361249 | AB29: 41.174644 | AC29: 39.613488 | AD29: 57.364061 | AE29: 66.679281 | AF29: 37.095588 | AG29: 43.310238 | AH29: 41.863445 | AI29: 55.701556 | AJ29: 99.400901 | AK29: 53.598526 | AL29: 49.916911 | AM29: 63.902252 | AN29: 46.117104 | AO29: 59.668045 | AP29: 69.963963 | AQ29: 67.625323 | AR29: 58.908725 | AU29: 62.971284 | AV29: 56.01934 | AW29: 45.18608 | AX29: 17.223333 | AY29: 37.416993 | AZ29: 104.54496 | BA29: 8.6691288 | BB29: 929.07269 | BC29: 937.74182
A30: 1995Q2 | B30: 110.5291 | C30: 112.17225 | D30: 57.89591 | E30: 72.033505 | F30: -19.366068 | G30: -0.25910504 | H30: 6.9652833 | I30: 7.5975461 | J30: 33.879404 | K30: 29.466038 | L30: 28.671096 | M30: 40.699816 | N30: 36.401407 | O30: 85.303041 | P30: 5.4469028 | Q30: 57.961986 | R30: 66.324699 | S30: 53.982813 | T30: 67.498994 | U30: 58.369817 | V30: 67.138526 | W30: 58.529023 | X30: 67.209779 | Y30: 7474.2151 | Z30: 35.125243 | AA30: 43.239657 | AB30: 42.227034 | AC30: 40.243147 | AD30: 57.941713 | AE30: 67.244003 | AF30: 37.777109 | AG30: 43.946874 | AH30: 42.360295 | AI30: 56.020016 | AJ30: 97.361764 | AK30: 54.876597 | AL30: 51.580392 | AM30: 64.846073 | AN30: 48.326914 | AO30: 60.744248 | AP30: 70.771652 | AQ30: 65.877854 | AR30: 56.225819 | AU30: 61.921823 | AV30: 59.503206 | AW30: 47.483203 | AX30: 18.176667 | AY30: 37.633271 | AZ30: 107.96797 | BA30: -6.9513935 | BB30: 986.80182 | BC30: 979.85042
A31: 1995Q3 | B31: 110.21137 | C31: 112.01949 | D31: 58.153007 | E31: 72.119758 | F31: -14.015629 | G31: -0.18898649 | H31: 6.6409069 | I31: 6.4321911 | J31: 36.778788 | K31: 30.124828 | L31: 29.226492 | M31: 42.487474 | N31: 39.575076 | O31: 85.502316 | P31: 5.5107129 | Q31: 58.522959 | R31: 66.738848 | S31: 53.973716 | T31: 68.07629 | U31: 58.875356 | V31: 67.670022 | W31: 59.007505 | X31: 67.732366 | Y31: 7416.2067 | Z31: 35.620379 | AA31: 43.87497 | AB31: 42.919116 | AC31: 40.856012 | AD31: 58.350402 | AE31: 67.669074 | AF31: 38.159647 | AG31: 44.603565 | AH31: 43.553829 | AI31: 54.978679 | AJ31: 86.846148 | AK31: 57.103534 | AL31: 53.00529 | AM31: 65.637784 | AN31: 50.189574 | AO31: 61.65237 | AP31: 71.49117 | AQ31: 69.105941 | AR31: 58.779071 | AU31: 62.395453 | AV31: 57.041536 | AW31: 44.250506 | AX31: 16.44 | AY31: 35.150398 | AZ31: 96.401307 | BA31: -9.6403854 | BB31: 990.82604 | BC31: 981.18565
A32: 1995Q4 | B32: 109.78129 | C32: 111.55389 | D32: 58.59508 | E32: 72.64615 | F32: -10.551183 | G32: -0.14261878 | H32: 6.2823168 | I32: 6.6678421 | J32: 38.55462 | K32: 30.836202 | L32: 29.741424 | M32: 43.425746 | N32: 41.386892 | O32: 85.631225 | P32: 5.5967743 | Q32: 58.911912 | R32: 67.185584 | S32: 55.274761 | T32: 69.17658 | U32: 59.236154 | V32: 68.038537 | W32: 59.327392 | X32: 68.085707 | Y32: 7398.172 | Z32: 36.276773 | AA32: 44.72738 | AB32: 43.641685 | AC32: 41.052738 | AD32: 58.699765 | AE32: 68.061492 | AF32: 38.639988 | AG32: 45.112154 | AH32: 44.017194 | AI32: 56.490424 | AJ32: 77.718999 | AK32: 56.156185 | AL32: 54.054033 | AM32: 66.276855 | AN32: 51.550011 | AO32: 62.421664 | AP32: 72.109816 | AQ32: 72.025159 | AR32: 56.156229 | AU32: 63.280644 | AV32: 64.942259 | AW32: 46.668545 | AX32: 16.976667 | AY32: 36.87293 | AZ32: 96.309526 | BA32: -7.6068583 | BB32: 1002.1575 | BC32: 994.55067
A33: 1996Q1 | B33: 108.90941 | C33: 110.15735 | D33: 59.118182 | E33: 73.022688 | F33: -19.15674 | G33: -0.25957522 | H33: 6.1318475 | I33: 6.6490072 | J33: 41.849177 | K33: 31.501342 | L33: 30.179236 | M33: 45.361077 | N33: 43.812214 | O33: 86.207752 | P33: 5.5523826 | Q33: 59.671018 | R33: 67.778858 | S33: 55.653223 | T33: 69.850308 | U33: 59.79031 | V33: 68.556434 | W33: 59.818727 | X33: 68.580266 | Y33: 7380.0342 | Z33: 37.125532 | AA33: 45.696284 | AB33: 44.688911 | AC33: 41.567792 | AD33: 59.185401 | AE33: 68.551723 | AF33: 39.485932 | AG33: 45.923624 | AH33: 44.965898 | AI33: 59.29158 | AJ33: 72.893951 | AK33: 54.35076 | AL33: 54.986237 | AM33: 67.014294 | AN33: 52.693056 | AO33: 63.322446 | AP33: 72.768145 | AQ33: 75.317844 | AR33: 54.195055 | AU33: 64.324933 | AV33: 80.384877 | AW33: 52.010965 | AX33: 18.313333 | AY33: 40.492783 | AZ33: 95.380567 | BA33: -12.83216 | BB33: 1017.8364 | BC33: 1005.0043
A34: 1996Q2 | B34: 110.63121 | C34: 112.07654 | D34: 59.928965 | E34: 73.783275 | F34: -29.744221 | G34: -0.39532677 | H34: 6.4650677 | I34: 6.3817603 | J34: 44.339739 | K34: 32.117467 | L34: 30.692988 | M34: 47.644344 | N34: 46.508521 | O34: 86.435519 | P34: 5.5940314 | Q34: 60.141087 | R34: 68.35107 | S34: 56.845127 | T34: 71.667128 | U34: 60.512687 | V34: 69.364214 | W34: 60.541228 | X34: 69.387847 | Y34: 7523.9583 | Z34: 37.697265 | AA34: 46.496292 | AB34: 45.485563 | AC34: 42.197603 | AD34: 59.901172 | AE34: 69.383127 | AF34: 39.979543 | AG34: 46.359238 | AH34: 45.418139 | AI34: 59.763206 | AJ34: 74.435982 | AK34: 53.226851 | AL34: 56.07309 | AM34: 67.760762 | AN34: 53.845636 | AO34: 64.18897 | AP34: 73.363542 | AQ34: 79.149183 | AR34: 53.301133 | AU34: 65.499738 | AV34: 68.800912 | AW34: 51.465461 | AX34: 19.486667 | AY34: 43.647121 | AZ34: 95.292647 | BA34: -21.011862 | BB34: 1025.6018 | BC34: 1004.59
A35: 1996Q3 | B35: 112.26036 | C35: 113.96815 | D35: 60.448728 | E35: 74.527981 | F35: -31.9932 | G35: -0.41888087 | H35: 6.3288935 | I35: 6.2080817 | J35: 44.950803 | K35: 32.704481 | L35: 31.144987 | M35: 47.243705 | N35: 46.381521 | O35: 86.714502 | P35: 5.5358027 | Q35: 60.52784 | R35: 68.750551 | S35: 57.614529 | T35: 72.533278 | U35: 61.038058 | V35: 69.884226 | W35: 61.061763 | X35: 69.905196 | Y35: 7637.7801 | Z35: 38.747864 | AA35: 47.452638 | AB35: 46.391913 | AC35: 42.551209 | AD35: 60.387435 | AE35: 69.8801 | AF35: 41.556594 | AG35: 47.466502 | AH35: 46.273864 | AI35: 58.79486 | AJ35: 68.735574 | AK35: 52.54152 | AL35: 57.014246 | AM35: 68.354431 | AN35: 54.859112 | AO35: 65.037686 | AP35: 73.942394 | AQ35: 75.82815 | AR35: 48.014356 | AU35: 62.640612 | AV35: 66.404608 | AW35: 53.232078 | AX35: 20.63 | AY35: 46.055409 | AZ35: 94.600387 | BA35: -14.070196 | BB35: 1033.5062 | BC35: 1019.436
A36: 1996Q4 | B36: 112.53552 | C36: 114.24661 | D36: 61.200926 | E36: 75.414955 | F36: -31.26305 | G36: -0.40663765 | H36: 5.860278 | I36: 5.9511492 | J36: 46.664233 | K36: 33.409491 | L36: 31.769451 | M36: 48.347118 | N36: 47.963509 | O36: 86.912764 | P36: 5.4588106 | Q36: 61.164649 | R36: 69.372905 | S36: 58.639109 | T36: 73.22442 | U36: 61.708152 | V36: 70.540688 | W36: 61.726113 | X36: 70.558463 | Y36: 7688.1837 | Z36: 39.782086 | AA36: 48.630669 | AB36: 47.576763 | AC36: 43.115528 | AD36: 60.973696 | AE36: 70.43858 | AF36: 42.566411 | AG36: 49.175892 | AH36: 47.459011 | AI36: 60.509418 | AJ36: 66.050179 | AK36: 52.5987 | AL36: 57.827717 | AM36: 68.977769 | AN36: 55.730208 | AO36: 65.717896 | AP36: 74.469082 | AQ36: 70.266876 | AR36: 48.245684 | AU36: 59.807898 | AV36: 82.453389 | AW36: 61.524147 | AX36: 23.063333 | AY36: 51.800672 | AZ36: 93.519181 | BA36: -16.305219 | BB36: 1064.5153 | BC36: 1048.2101
A37: 1997Q1 | B37: 114.35325 | C37: 116.11163 | D37: 62.16156 | E37: 76.633358 | F37: -16.348082 | G37: -0.21789417 | H37: 5.8351904 | I37: 5.860732 | J37: 50.437048 | K37: 34.057075 | L37: 32.709297 | M37: 49.419648 | N37: 50.994752 | O37: 87.201869 | P37: 5.5508306 | Q37: 61.71576 | R37: 70.000269 | S37: 58.604369 | T37: 73.131841 | U37: 62.137682 | V37: 70.969791 | W37: 62.153062 | X37: 70.986043 | Y37: 7502.7623 | Z37: 40.709637 | AA37: 49.811161 | AB37: 48.693111 | AC37: 43.045465 | AD37: 61.425343 | AE37: 70.833189 | AF37: 43.525453 | AG37: 50.424304 | AH37: 48.704487 | AI37: 59.386114 | AJ37: 77.01896 | AK37: 51.141847 | AL37: 58.792362 | AM37: 69.631526 | AN37: 56.864809 | AO37: 66.807361 | AP37: 75.128804 | AQ37: 73.523529 | AR37: 52.491388 | AU37: 62.148736 | AV37: 73.904389 | AW37: 55.390052 | AX37: 21.083333 | AY37: 49.031321 | AZ37: 93.501119 | BA37: -21.902095 | BB37: 1071.7711 | BC37: 1049.869
A38: 1997Q2 | B38: 116.078 | C38: 117.9135 | D38: 63.392727 | E38: 77.78397 | F38: 0.76504108 | G38: 0.010116391 | H38: 5.8710191 | I38: 5.586599 | J38: 57.485343 | K38: 34.768736 | L38: 33.39039 | M38: 56.575687 | N38: 58.348607 | O38: 87.452471 | P38: 5.6134673 | Q38: 61.955824 | R38: 70.124885 | S38: 59.551908 | T38: 74.238305 | U38: 62.921627 | V38: 71.767504 | W38: 62.933842 | X38: 71.781846 | Y38: 7562.3916 | Z38: 41.605926 | AA38: 50.891584 | AB38: 49.917758 | AC38: 43.124301 | AD38: 61.961196 | AE38: 71.432315 | AF38: 45.446064 | AG38: 52.4975 | AH38: 50.523431 | AI38: 56.137209 | AJ38: 96.610058 | AK38: 50.423874 | AL38: 59.668473 | AM38: 70.26476 | AN38: 57.675423 | AO38: 67.832996 | AP38: 75.838525 | AQ38: 70.2598 | AR38: 52.592666 | AU38: 60.967208 | AV38: 66.16305 | AW38: 49.150741 | AX38: 18.49 | AY38: 43.384475 | AZ38: 90.148852 | BA38: -6.9623738 | BB38: 1081.4362 | BC38: 1074.4738
A39: 1997Q3 | B39: 116.6013 | C39: 118.69529 | D39: 64.354334 | E39: 78.921472 | F39: -2.3606312 | G39: -0.031235372 | H39: 5.468803 | I39: 5.5438967 | J39: 58.362527 | K39: 35.404611 | L39: 33.983995 | M39: 57.396383 | N39: 60.591781 | O39: 87.675553 | P39: 5.5951809 | Q39: 62.740256 | R39: 70.810033 | S39: 60.570131 | T39: 75.346529 | U39: 63.557049 | V39: 72.405358 | W39: 63.566787 | X39: 72.418172 | Y39: 7557.5574 | Z39: 42.858458 | AA39: 52.202238 | AB39: 51.193573 | AC39: 43.571554 | AD39: 62.60277 | AE39: 72.082809 | AF39: 46.462245 | AG39: 53.482026 | AH39: 51.355924 | AI39: 54.662719 | AJ39: 86.421071 | AK39: 49.790313 | AL39: 60.462618 | AM39: 70.841413 | AN39: 58.516026 | AO39: 68.537381 | AP39: 76.33143 | AQ39: 66.78846 | AR39: 51.426611 | AS39: 53.202402 | AT39: 53.180929 | AU39: 57.874991 | AV39: 68.77176 | AW39: 50.016249 | AX39: 18.656667 | AY39: 44.372457 | AZ39: 85.728892 | BA39: -3.6809471 | BB39: 1091.4444 | BC39: 1087.7634
A40: 1997Q4 | B40: 116.70054 | C40: 119.02852 | D40: 64.971298 | E40: 79.52144 | F40: -5.2126556 | G40: -0.069100796 | H40: 5.1667463 | I40: 5.8762279 | J40: 54.747937 | K40: 36.092541 | L40: 34.568498 | M40: 52.544136 | N40: 57.798165 | O40: 87.919965 | P40: 5.5104929 | Q40: 63.360402 | R40: 71.411754 | S40: 61.033145 | T40: 75.94999 | U40: 64.155839 | V40: 72.983395 | W40: 64.164052 | X40: 72.995117 | Y40: 7543.5536 | Z40: 43.900738 | AA40: 52.936126 | AB40: 51.792086 | AC40: 43.929968 | AD40: 63.199322 | AE40: 72.647717 | AF40: 47.217194 | AG40: 54.211339 | AH40: 52.203155 | AI40: 54.304377 | AJ40: 83.096329 | AK40: 46.139714 | AL40: 61.128551 | AM40: 71.338094 | AN40: 59.231227 | AO40: 69.402768 | AP40: 76.943904 | AQ40: 68.439806 | AR40: 47.113442 | AS40: 53.570672 | AT40: 53.393933 | AU40: 56.837809 | AV40: 71.967076 | AW40: 50.639834 | AX40: 18.84 | AY40: 44.710486 | AZ40: 78.368998 | BA40: -7.1594988 | BB40: 1099.6734 | BC40: 1092.5139
...

Sheet Sheet1

Sheet Commodity_Prices
