Workbook
Name _DLX1.USE: Haver_M!$A$2:$HO$5
Name _DLX2.USE: Haver_Q!$A$2:$CJ$5
Name EdssBatchRange: #REF!

Sheet Haver_M
C1: RS | D1: LTY | E1: REER | F1: CPI | G1: CORE | H1: IPALL | I1: IPBASIC | J1: IPCAPITAL | K1: IPINTERM | L1: IPCONS | M1: IPDURABLE | N1: IPNONDUR | O1: COREINDUSTRY | P1: CORECOAL | Q1: COREOIL | R1: COREGAS | S1: COREREFINE | T1: COREFERT | U1: CORESTEEL | V1: CORECEMENT | W1: COREELEC | X1: OILCONS | Y1: EXPMERCH | Z1: IMPMERCH | AA1: BOPXSERV | AB1: BOPMSERV | AC1: CONSCONF | AD1: CONSCONFX | AE1: UNCERTAINTY | AF1: PMIALL | AG1: PMIMANU | AH1: PMISERV | AI1: PMIOUTPUT | AJ1: PMINO | AK1: PMIEMPL | AL1: PMIDEL | AM1: PMISTOCKS | AN1: PMIINPUT | AO1: PMIQUANT | AP1: PMISTOCKS | AQ1: PMINEO | AR1: PMIOUTPRICES | AS1: PMIBACK | AT1: PMIORDERSINV | AU1: PMISERVEMPL | AV1: PMISERVPRI | AW1: PMISERNEW | AX1: PMISERVIN | AY1: PMISNEO | AZ1: PMISOUTB | BA1: STOCKS | BB1: CEICLEAD | BC1: BUSINESS | BD1: BUSINESSEXP | BE1: IOS_SURVEY | BF1: Auto_Two | BG1: Auto_Commercial | BH1: Auto_Total | BI1: Auto_Passenger | BN1: Exports_usd | BO1: Imports_USD | BP1: rup_usd | BQ1: Credit_Personal | BR1: Credit_Industry | BS1: Credit_Services | BT1: Credit_Nonfood | BU1: Agri_Production
A2: 10001 !M | B2: .excel_last | C2: N534RP@EMERGEPR | D2: N534RG10@EMERGEPR | E2: N534XJRB@EMERGEPR | F2: N534PC@EMERGEPR | G2: N534PCXG@EMERGEPR | H2: H534D@EMERGEPR | I2: H534DB@EMERGEPR | J2: H534DK@EMERGEPR | K2: H534DI@EMERGEPR | L2: H534DR@EMERGEPR | M2: H534DCD@EMERGEPR | N2: H534DCN@EMERGEPR | O2: H534VI@EMERGEPR | P2: H534OCLI@EMERGEPR | Q2: H534OCOI@EMERGEPR | R2: H534ONGI@EMERGEPR | S2: H534OPRI@EMERGEPR | T2: H534OFTI@EMERGEPR | U2: H534OSTI@EMERGEPR | V2: H534OCNI@EMERGEPR | W2: H534OELI@EMERGEPR | X2: sa(N534CRP@EMERGEPR) | Y2: H534IXD@EMERGEPR | Z2: H534IMD@EMERGEPR | AA2: M534BCSX@EMERGEPR | AB2: M534BCSM@EMERGEPR | AC2: N534VCC@EMERGEPR | AD2: N534VCE@EMERGEPR | AE2: sa(N534VIUC@EMERGEPR) | AF2: S534TG@MKTPMI | AG2: S534M@MKTPMI | AH2: S534S@MKTPMI | AI2: S534MG@MKTPMI | AJ2: S534MO@MKTPMI | AK2: S534ME@MKTPMI | AL2: S534MD@MKTPMI | AM2: S534MSP@MKTPMI | AN2: S534MPI@MKTPMI | AO2: S534MQP@MKTPMI | AP2: S534MSF@MKTPMI | AQ2: S534MX@MKTPMI | AR2: S534MPO@MKTPMI | AS2: S534MB@MKTPMI | AT2: S534OI@MKTPMI | AU2: S534SE@MKTPMI | AV2: S534SPC@MKTPMI | AW2: S534SNB@MKTPMI | AX2: S534SPI@MKTPMI | AY2: S534SX@MKTPMI | AZ2: S534SWO@MKTPMI | BA2: N534FKSV@EMERGEPR | BB2: 6 | BC2: 2 | BD2: 3 | BE2: 4 | BJ2: N534CNHH@EMERGEPR | BK2: N534CNIN@EMERGEPR | BL2: N534CNOP@EMERGEPR | BM2: N534CNF@EMERGEPR | BN2: N534IXD@EMERGEPR | BO2: N534IMD@EMERGEPR | BP2: N534XUSV@EMERGEPR | BU2: N534OASF@EMERGEPR
A3: .DESC | C3: India: Repo Rate (EOP, % per annum) | D3: India: 10-Year Government Bond Yield (EOP, % per annum) | E3: India: JPMorgan Real Broad Effective Exchange Rate Index, PPI Based (2010=100) | F3: India: Consumer Price Index (NSA, 2012=100) | G3: India: CPI Ex Food and Energy (NSA, 2012=100) | H3: India: IP: General Index (SA, Apr.11-Mar.12=100) | I3: India: IP: Basic Goods (SA, Apr.11-Mar.12=100) | J3: India: IP: Capital Goods (SA, Apr.11-Mar.12=100) | K3: India: IP: Intermediate Goods (SA, Apr.11-Mar.12=100) | L3: India: IP: Infrastructure and Construction Goods (SA, Apr.11-Mar.12=100) | M3: India: IP: Consumer Durable Goods (SA, Apr.11-Mar.12=100) | N3: India: IP: Consumer Nondurable Goods (SA, Apr.11-Mar.12=100) | O3: India: Eight Core Industry Infrastructure Index (SA, Apr.11-Mar.12=100) | P3: India: Eight Core Industries Index: Coal (SA, Apr.11-Mar.12=100) | Q3: India: Eight Core Industries Index: Crude Oil (SA, Apr.11-Mar.12=100) | R3: India: Eight Core Industries Index: Natural Gas (SA, Apr.11-Mar.12=100) | S3: India: Eight Core Ind Index: Petroleum Refinery Products(SA, Apr.11-Mar.12=100) | T3: India: Eight Core Industries Index: Fertilizers (SA, Apr.11-Mar.12=100) | U3: India: Eight Core Industries Index: Steel (SA, Apr.11-Mar.12=100) | V3: India: Eight Core Industries Index: Cement (SA, Apr.11-Mar.12=100) | W3: India: Eight Core Industries Index: Electricity (SA, Apr.11-Mar.12=100) | X3: India: Consumption of Petroleum Products (NSA, Thous.Metric Tons) - Seasonal Adjustment, All | Y3: India: Merchandise Exports, f.o.b. (SA, Mil.US$) | Z3: India: Merchandise Imports, c.i.f. (SA, Mil.US$) | AA3: India: BOP: Services: Exports (NSA, Mil.US$) | AB3: India: BOP: Services: Imports (NSA, Mil.US$) | AC3: India: Consumer Confidence Survey: Current Situation Index (NSA, 100=neutral) | AD3: India: Consumer Confidence Survey: Future Expectation Index (NSA, 100=neutral) | AE3: India: News Based Economic Policy Uncertainty Index (Mean=100) - Seasonal Adjustment, All | AF3: India PMI: Composite Output (SA, 50+=Expansion) | AG3: India PMI: Manufacturing (SA, 50+=Expansion) | AH3: India PMI: Services Business Activity (SA, 50+=Expansion) | AI3: India PMI: Manufacturing Output (SA, 50+=Expansion) | AJ3: India PMI: Manufacturing New Orders (SA, 50+=Expansion) | AK3: India PMI: Manufacturing Employment (SA, 50+=Expansion) | AL3: India PMI: Manufacturing Suppliers' Delivery Times (SA, 50+=Contraction) | AM3: India PMI: Manufacturing Stocks of Purchases (SA, 50+=Expansion) | AN3: India PMI: Manufacturing Input Prices (SA, 50+=Expansion) | AO3: India PMI: Manufacturing Quantity of Purchases (SA, 50+=Expansion) | AP3: India PMI: Manufacturing Stocks of Finished Goods (SA, 50+=Expansion) | AQ3: India PMI: Manufacturing New Export Orders (SA, 50+=Expansion) | AR3: India PMI: Manufacturing Output Prices (SA, 50+=Expansion) | AS3: India PMI: Manufacturing Backlogs of Work (SA, 50+=Expansion) | AT3: India: Manufacturing Orders to Inventories (SA, Ratio) | AU3: India PMI: Services Employment (SA, 50+=Expansion) | AV3: India PMI: Services Prices Charged (SA, 50+=Expansion) | AW3: India PMI: Services New Business (SA, 50+=Expansion) | AX3: India PMI: Services Input Prices (SA, 50+=Expansion) | AY3: India PMI: Services New Export Orders (SA, 50+=Expansion) | AZ3: India PMI: Services Outstanding Business (SA, 50+=Expansion) | BA3: India: Stock Prices: BSE Sensex/BSE 30 Index (AVG, 1978-79=100) | BB3: CEIC Leading Indicator: Smoothed: India | BC3: RBI: Industrial Outlook Survey: Business Expectation Index: Assessment for Current Quarter | BD3: RBI Forecast: Industrial Outlook Survey: Business Expectation Index: Expectation for Next Quarter | BE3: RBI Forecast: Industrial Outlook Survey: Overall Business Situation | BF3: Automobile Sales: SIAM: Two Wheelers | BG3: Automobile Sales: SIAM: Commercial Vehicle | BH3: Automobile Sales: SIAM: Total | BI3: Automobile Sales: SIAM: Passenger Vehicle | BJ3: India: Bank Credit Outstanding: Personal Loans (EOP, NSA, Bil.Rupees) | BK3: India: Bank Credit Outstanding: Industry (EOP, NSA, Bil.Rupees) | BL3: India: Bank Credit Outstanding: Services (EOP, NSA, Bil.Rupees) | BM3: India: Bank Credit Outstanding: Nonfood Credit (EOP, NSA, Bil.Rupees) | BN3: India: Merchandise Exports, f.o.b. (NSA, Mil.US$) | BO3: India: Merchandise Imports, c.i.f. (NSA, Mil.US$) | BP3: India: Rupee/US$ Exchange Rate (AVG) | BU3: India: Agricultural Production: Stock of Foodgrains (NSA, Thous.Metric Tons)
A4: .T1 | C4: Apr-2001 | D4: May-1996 | E4: Jan-1990 | F4: Jan-2001 | G4: Jan-2011 | H4: Jan-1971 | I4: Apr-1994 | J4: Apr-1994 | K4: Apr-1994 | L4: Apr-2012 | M4: Apr-1994 | N4: Apr-1994 | O4: Apr-2004 | P4: Apr-2004 | Q4: Apr-2004 | R4: Apr-2004 | S4: Apr-2004 | T4: Apr-2004 | U4: Apr-2004 | V4: Apr-2004 | W4: Apr-2004 | X4: Apr-1998 | Y4: Jan-1968 | Z4: Jan-1968 | AA4: Apr-2011 | AB4: Apr-2011 | AC4: Dec-2010 | AD4: Dec-2010 | AE4: Jan-1997 | AF4: Dec-2005 | AG4: Mar-2005 | AH4: Dec-2005 | AI4: Mar-2005 | AJ4: Mar-2005 | AK4: Mar-2005 | AL4: Mar-2005 | AM4: Mar-2005 | AN4: Mar-2005 | AO4: Mar-2005 | AP4: Mar-2005 | AQ4: Mar-2005 | AR4: Mar-2005 | AS4: Mar-2005 | AT4: Mar-2005 | AU4: Dec-2005 | AV4: Dec-2005 | AW4: Dec-2005 | AX4: Dec-2005 | AY4: Sep-2014 | AZ4: Dec-2005 | BA4: Apr-1979 | BJ4: Apr-2007 | BK4: Apr-2007 | BL4: Apr-2007 | BM4: Apr-2007 | BN4: Jan-1968 | BO4: Jan-1968 | BP4: Mar-1992 | BU4: Apr-1990
A5: .TN | C5: Feb-2020 | D5: Dec-2019 | E5: Jan-2020 | F5: Jan-2020 | G5: Jan-2020 | H5: Dec-2019 | I5: Dec-2019 | J5: Dec-2019 | K5: Dec-2019 | L5: Dec-2019 | M5: Dec-2019 | N5: Dec-2019 | O5: Dec-2019 | P5: Dec-2019 | Q5: Dec-2019 | R5: Dec-2019 | S5: Dec-2019 | T5: Dec-2019 | U5: Dec-2019 | V5: Dec-2019 | W5: Dec-2019 | X5: Jan-2020 | Y5: Jan-2020 | Z5: Jan-2020 | AA5: Dec-2019 | AB5: Dec-2019 | AC5: Jan-2020 | AD5: Jan-2020 | AE5: Jan-2020 | AF5: Jan-2020 | AG5: Jan-2020 | AH5: Jan-2020 | AI5: Jan-2020 | AJ5: Jan-2020 | AK5: Jan-2020 | AL5: Jan-2020 | AM5: Jan-2020 | AN5: Jan-2020 | AO5: Jan-2020 | AP5: Jan-2020 | AQ5: Jan-2020 | AR5: Jan-2020 | AS5: Jan-2020 | AT5: Jan-2020 | AU5: Jan-2020 | AV5: Jan-2020 | AW5: Jan-2020 | AX5: Jan-2020 | AY5: Jan-2020 | AZ5: Jan-2020 | BA5: Jan-2020 | BJ5: Dec-2019 | BK5: Dec-2019 | BL5: Dec-2019 | BM5: Dec-2019 | BN5: Jan-2020 | BO5: Jan-2020 | BP5: Jan-2020 | BU5: Jan-2020
A6: 0001 | B6: 36556 | C6: #N/A | D6: 10.9434 | E6: 91.11364 | F6: #N/A | G6: #N/A | H6: 44.61 | I6: 53.7 | J6: 26.22 | K6: 56.45 | L6: #N/A | M6: 22.46 | N6: 45.74 | O6: #N/A | P6: #N/A | Q6: #N/A | R6: #N/A | S6: #N/A | T6: #N/A | U6: #N/A | V6: #N/A | W6: #N/A | X6: 7897.1824 | Y6: 2739.66 | Z6: 3874.06 | AA6: #N/A | AB6: #N/A | AC6: #N/A | AD6: #N/A | AE6: 58.825769 | AF6: #N/A | AG6: #N/A | AH6: #N/A | AI6: #N/A | AJ6: #N/A | AK6: #N/A | AL6: #N/A | AM6: #N/A | AN6: #N/A | AO6: #N/A | AP6: #N/A | AQ6: #N/A | AR6: #N/A | AS6: #N/A | AT6: #N/A | AU6: #N/A | AV6: #N/A | AW6: #N/A | AX6: #N/A | AY6: #N/A | AZ6: #N/A | BA6: 5407.14 | BB6: =IF(ISNUMBER(VLOOKUP($B6,CEIC_DATA!$I$26:$N$353,Haver_M!BB$2,FALSE)),VLOOKUP($B6,CEIC_DATA!$I$26:$N$353,Haver_M!BB$2,FALSE),NA()) -> 118.54817 | BC6: =IF(ISNUMBER(VLOOKUP($B6,CEIC_DATA!$I$26:$N$353,Haver_M!BC$2,FALSE)),VLOOKUP($B6,CEIC_DATA!$I$26:$N$353,Haver_M!BC$2,FALSE),NA()) -> #N/A | BD6: =IF(ISNUMBER(VLOOKUP($B6,CEIC_DATA!$I$26:$N$353,Haver_M!BD$2,FALSE)),VLOOKUP($B6,CEIC_DATA!$I$26:$N$353,Haver_M!BD$2,FALSE),NA()) -> #N/A | BE6: =IF(ISNUMBER(VLOOKUP($B6,CEIC_DATA!$I$26:$N$353,Haver_M!BE$2,FALSE)),VLOOKUP($B6,CEIC_DATA!$I$26:$N$353,Haver_M!BE$2,FALSE),NA()) -> #N/A | BJ6: #N/A | BK6: #N/A | BL6: #N/A | BM6: #N/A | BN6: 2748 | BO6: 3879 | BP6: 43.55 | BQ6: =IF(ISNUMBER(BJ6),BJ6/$BP6,"") | BR6: =IF(ISNUMBER(BK6),BK6/$BP6,"") | BS6: =IF(ISNUMBER(BL6),BL6/$BP6,"") | BT6: =IF(ISNUMBER(BM6),BM6/$BP6,"") | BU6: 31165
A7: 0002 | B7: 36585 | C7: #N/A | D7: 10.4416 | E7: 92.20659 | F7: #N/A | G7: #N/A | H7: 44.07 | I7: 53.84 | J7: 26.76 | K7: 55.37 | L7: #N/A | M7: 23.3 | N7: 45.97 | O7: #N/A | P7: #N/A | Q7: #N/A | R7: #N/A | S7: #N/A | T7: #N/A | U7: #N/A | V7: #N/A | W7: #N/A | X7: 8487.2218 | Y7: 3406.19 | Z7: 4558.46 | AA7: #N/A | AB7: #N/A | AC7: #N/A | AD7: #N/A | AE7: 56.396633 | AF7: #N/A | AG7: #N/A | AH7: #N/A | AI7: #N/A | AJ7: #N/A | AK7: #N/A | AL7: #N/A | AM7: #N/A | AN7: #N/A | AO7: #N/A | AP7: #N/A | AQ7: #N/A | AR7: #N/A | AS7: #N/A | AT7: #N/A | AU7: #N/A | AV7: #N/A | AW7: #N/A | AX7: #N/A | AY7: #N/A | AZ7: #N/A | BA7: 5650.66 | BB7: =IF(ISNUMBER(VLOOKUP($B7,CEIC_DATA!$I$26:$N$353,Haver_M!BB$2,FALSE)),VLOOKUP($B7,CEIC_DATA!$I$26:$N$353,Haver_M!BB$2,FALSE),NA()) -> 118.91702 | BC7: =IF(ISNUMBER(VLOOKUP($B7,CEIC_DATA!$I$26:$N$353,Haver_M!BC$2,FALSE)),VLOOKUP($B7,CEIC_DATA!$I$26:$N$353,Haver_M!BC$2,FALSE),NA()) -> #N/A | BD7: =IF(ISNUMBER(VLOOKUP($B7,CEIC_DATA!$I$26:$N$353,Haver_M!BD$2,FALSE)),VLOOKUP($B7,CEIC_DATA!$I$26:$N$353,Haver_M!BD$2,FALSE),NA()) -> #N/A | BE7: =IF(ISNUMBER(VLOOKUP($B7,CEIC_DATA!$I$26:$N$353,Haver_M!BE$2,FALSE)),VLOOKUP($B7,CEIC_DATA!$I$26:$N$353,Haver_M!BE$2,FALSE),NA()) -> #N/A | BJ7: #N/A | BK7: #N/A | BL7: #N/A | BM7: #N/A | BN7: 3404 | BO7: 4344 | BP7: 43.6136 | BQ7: =IF(ISNUMBER(BJ7),BJ7/$BP7,"") | BR7: =IF(ISNUMBER(BK7),BK7/$BP7,"") | BS7: =IF(ISNUMBER(BL7),BL7/$BP7,"") | BT7: =IF(ISNUMBER(BM7),BM7/$BP7,"") | BU7: 30452
A8: 0003 | B8: 36616 | C8: #N/A | D8: 10.8663 | E8: 94.05975 | F8: #N/A | G8: #N/A | H8: 45.67 | I8: 55.16 | J8: 26.04 | K8: 56.77 | L8: #N/A | M8: 25.83 | N8: 46.55 | O8: #N/A | P8: #N/A | Q8: #N/A | R8: #N/A | S8: #N/A | T8: #N/A | U8: #N/A | V8: #N/A | W8: #N/A | X8: 8182.9763 | Y8: 3354.8 | Z8: 4577.21 | AA8: #N/A | AB8: #N/A | AC8: #N/A | AD8: #N/A | AE8: 62.373813 | AF8: #N/A | AG8: #N/A | AH8: #N/A | AI8: #N/A | AJ8: #N/A | AK8: #N/A | AL8: #N/A | AM8: #N/A | AN8: #N/A | AO8: #N/A | AP8: #N/A | AQ8: #N/A | AR8: #N/A | AS8: #N/A | AT8: #N/A | AU8: #N/A | AV8: #N/A | AW8: #N/A | AX8: #N/A | AY8: #N/A | AZ8: #N/A | BA8: 5261.77 | BB8: =IF(ISNUMBER(VLOOKUP($B8,CEIC_DATA!$I$26:$N$353,Haver_M!BB$2,FALSE)),VLOOKUP($B8,CEIC_DATA!$I$26:$N$353,Haver_M!BB$2,FALSE),NA()) -> 118.53685 | BC8: =IF(ISNUMBER(VLOOKUP($B8,CEIC_DATA!$I$26:$N$353,Haver_M!BC$2,FALSE)),VLOOKUP($B8,CEIC_DATA!$I$26:$N$353,Haver_M!BC$2,FALSE),NA()) -> 122.8 | BD8: =IF(ISNUMBER(VLOOKUP($B8,CEIC_DATA!$I$26:$N$353,Haver_M!BD$2,FALSE)),VLOOKUP($B8,CEIC_DATA!$I$26:$N$353,Haver_M!BD$2,FALSE),NA()) -> #N/A | BE8: =IF(ISNUMBER(VLOOKUP($B8,CEIC_DATA!$I$26:$N$353,Haver_M!BE$2,FALSE)),VLOOKUP($B8,CEIC_DATA!$I$26:$N$353,Haver_M!BE$2,FALSE),NA()) -> #N/A | BJ8: #N/A | BK8: #N/A | BL8: #N/A | BM8: #N/A | BN8: 3860 | BO8: 4871 | BP8: 43.5857 | BQ8: =IF(ISNUMBER(BJ8),BJ8/$BP8,"") | BR8: =IF(ISNUMBER(BK8),BK8/$BP8,"") | BS8: =IF(ISNUMBER(BL8),BL8/$BP8,"") | BT8: =IF(ISNUMBER(BM8),BM8/$BP8,"") | BU8: 28906
A9: 0004 | B9: 36646 | C9: #N/A | D9: 10.3663 | E9: 95.74013 | F9: #N/A | G9: #N/A | H9: 45.86 | I9: 54.3 | J9: 29.41 | K9: 57.06 | L9: #N/A | M9: 24.91 | N9: 46.49 | O9: #N/A | P9: #N/A | Q9: #N/A | R9: #N/A | S9: #N/A | T9: #N/A | U9: #N/A | V9: #N/A | W9: #N/A | X9: 8274.9538 | Y9: 3422.47 | Z9: 4551.49 | AA9: #N/A | AB9: #N/A | AC9: #N/A | AD9: #N/A | AE9: 75.890914 | AF9: #N/A | AG9: #N/A | AH9: #N/A | AI9: #N/A | AJ9: #N/A | AK9: #N/A | AL9: #N/A | AM9: #N/A | AN9: #N/A | AO9: #N/A | AP9: #N/A | AQ9: #N/A | AR9: #N/A | AS9: #N/A | AT9: #N/A | AU9: #N/A | AV9: #N/A | AW9: #N/A | AX9: #N/A | AY9: #N/A | AZ9: #N/A | BA9: 4905.3 | BB9: =IF(ISNUMBER(VLOOKUP($B9,CEIC_DATA!$I$26:$N$353,Haver_M!BB$2,FALSE)),VLOOKUP($B9,CEIC_DATA!$I$26:$N$353,Haver_M!BB$2,FALSE),NA()) -> 117.60795 | BC9: =IF(ISNUMBER(VLOOKUP($B9,CEIC_DATA!$I$26:$N$353,Haver_M!BC$2,FALSE)),VLOOKUP($B9,CEIC_DATA!$I$26:$N$353,Haver_M!BC$2,FALSE),NA()) -> #N/A | BD9: =IF(ISNUMBER(VLOOKUP($B9,CEIC_DATA!$I$26:$N$353,Haver_M!BD$2,FALSE)),VLOOKUP($B9,CEIC_DATA!$I$26:$N$353,Haver_M!BD$2,FALSE),NA()) -> #N/A | BE9: =IF(ISNUMBER(VLOOKUP($B9,CEIC_DATA!$I$26:$N$353,Haver_M!BE$2,FALSE)),VLOOKUP($B9,CEIC_DATA!$I$26:$N$353,Haver_M!BE$2,FALSE),NA()) -> #N/A | BJ9: #N/A | BK9: #N/A | BL9: #N/A | BM9: #N/A | BN9: 3310 | BO9: 4401 | BP9: 43.6388 | BQ9: =IF(ISNUMBER(BJ9),BJ9/$BP9,"") | BR9: =IF(ISNUMBER(BK9),BK9/$BP9,"") | BS9: =IF(ISNUMBER(BL9),BL9/$BP9,"") | BT9: =IF(ISNUMBER(BM9),BM9/$BP9,"") | BU9: 36577
A10: 0005 | B10: 36677 | C10: #N/A | D10: 10.8186 | E10: 96.77981 | F10: #N/A | G10: #N/A | H10: 46.05 | I10: 55.04 | J10: 27.13 | K10: 58.18 | L10: #N/A | M10: 25.83 | N10: 46.12 | O10: #N/A | P10: #N/A | Q10: #N/A | R10: #N/A | S10: #N/A | T10: #N/A | U10: #N/A | V10: #N/A | W10: #N/A | X10: 8384.727 | Y10: 3687.09 | Z10: 4212.82 | AA10: #N/A | AB10: #N/A | AC10: #N/A | AD10: #N/A | AE10: 66.784844 | AF10: #N/A | AG10: #N/A | AH10: #N/A | AI10: #N/A | AJ10: #N/A | AK10: #N/A | AL10: #N/A | AM10: #N/A | AN10: #N/A | AO10: #N/A | AP10: #N/A | AQ10: #N/A | AR10: #N/A | AS10: #N/A | AT10: #N/A | AU10: #N/A | AV10: #N/A | AW10: #N/A | AX10: #N/A | AY10: #N/A | AZ10: #N/A | BA10: 4253.11 | BB10: =IF(ISNUMBER(VLOOKUP($B10,CEIC_DATA!$I$26:$N$353,Haver_M!BB$2,FALSE)),VLOOKUP($B10,CEIC_DATA!$I$26:$N$353,Haver_M!BB$2,FALSE),NA()) -> 116.38076 | BC10: =IF(ISNUMBER(VLOOKUP($B10,CEIC_DATA!$I$26:$N$353,Haver_M!BC$2,FALSE)),VLOOKUP($B10,CEIC_DATA!$I$26:$N$353,Haver_M!BC$2,FALSE),NA()) -> #N/A | BD10: =IF(ISNUMBER(VLOOKUP($B10,CEIC_DATA!$I$26:$N$353,Haver_M!BD$2,FALSE)),VLOOKUP($B10,CEIC_DATA!$I$26:$N$353,Haver_M!BD$2,FALSE),NA()) -> #N/A | BE10: =IF(ISNUMBER(VLOOKUP($B10,CEIC_DATA!$I$26:$N$353,Haver_M!BE$2,FALSE)),VLOOKUP($B10,CEIC_DATA!$I$26:$N$353,Haver_M!BE$2,FALSE),NA()) -> #N/A | BJ10: #N/A | BK10: #N/A | BL10: #N/A | BM10: #N/A | BN10: 3577 | BO10: 4371 | BP10: 43.9829 | BQ10: =IF(ISNUMBER(BJ10),BJ10/$BP10,"") | BR10: =IF(ISNUMBER(BK10),BK10/$BP10,"") | BS10: =IF(ISNUMBER(BL10),BL10/$BP10,"") | BT10: =IF(ISNUMBER(BM10),BM10/$BP10,"") | BU10: 42885
A11: 0006 | B11: 36707 | C11: #N/A | D11: 11.1004 | E11: 93.66655 | F11: #N/A | G11: #N/A | H11: 45.8 | I11: 55.37 | J11: 27.31 | K11: 57.25 | L11: #N/A | M11: 25.58 | N11: 45.87 | O11: #N/A | P11: #N/A | Q11: #N/A | R11: #N/A | S11: #N/A | T11: #N/A | U11: #N/A | V11: #N/A | W11: #N/A | X11: 8235.3562 | Y11: 3631.69 | Z11: 4263.3 | AA11: #N/A | AB11: #N/A | AC11: #N/A | AD11: #N/A | AE11: 117.52526 | AF11: #N/A | AG11: #N/A | AH11: #N/A | AI11: #N/A | AJ11: #N/A | AK11: #N/A | AL11: #N/A | AM11: #N/A | AN11: #N/A | AO11: #N/A | AP11: #N/A | AQ11: #N/A | AR11: #N/A | AS11: #N/A | AT11: #N/A | AU11: #N/A | AV11: #N/A | AW11: #N/A | AX11: #N/A | AY11: #N/A | AZ11: #N/A | BA11: 4675.4 | BB11: =IF(ISNUMBER(VLOOKUP($B11,CEIC_DATA!$I$26:$N$353,Haver_M!BB$2,FALSE)),VLOOKUP($B11,CEIC_DATA!$I$26:$N$353,Haver_M!BB$2,FALSE),NA()) -> 115.04659 | BC11: =IF(ISNUMBER(VLOOKUP($B11,CEIC_DATA!$I$26:$N$353,Haver_M!BC$2,FALSE)),VLOOKUP($B11,CEIC_DATA!$I$26:$N$353,Haver_M!BC$2,FALSE),NA()) -> 115.2 | BD11: =IF(ISNUMBER(VLOOKUP($B11,CEIC_DATA!$I$26:$N$353,Haver_M!BD$2,FALSE)),VLOOKUP($B11,CEIC_DATA!$I$26:$N$353,Haver_M!BD$2,FALSE),NA()) -> 125.5 | BE11: =IF(ISNUMBER(VLOOKUP($B11,CEIC_DATA!$I$26:$N$353,Haver_M!BE$2,FALSE)),VLOOKUP($B11,CEIC_DATA!$I$26:$N$353,Haver_M!BE$2,FALSE),NA()) -> 53.8 | BJ11: #N/A | BK11: #N/A | BL11: #N/A | BM11: #N/A | BN11: 3455 | BO11: 4028 | BP11: 44.6863 | BQ11: =IF(ISNUMBER(BJ11),BJ11/$BP11,"") | BR11: =IF(ISNUMBER(BK11),BK11/$BP11,"") | BS11: =IF(ISNUMBER(BL11),BL11/$BP11,"") | BT11: =IF(ISNUMBER(BM11),BM11/$BP11,"") | BU11: 42247
A12: 0007 | B12: 36738 | C12: #N/A | D12: 11.3 | E12: 93.99963 | F12: #N/A | G12: #N/A | H12: 45.93 | I12: 55.24 | J12: 27.83 | K12: 57.28 | L12: #N/A | M12: 25.32 | N12: 44.75 | O12: #N/A | P12: #N/A | Q12: #N/A | R12: #N/A | S12: #N/A | T12: #N/A | U12: #N/A | V12: #N/A | W12: #N/A | X12: 8201.1603 | Y12: 3516.88 | Z12: 4282.13 | AA12: #N/A | AB12: #N/A | AC12: #N/A | AD12: #N/A | AE12: 67.622725 | AF12: #N/A | AG12: #N/A | AH12: #N/A | AI12: #N/A | AJ12: #N/A | AK12: #N/A | AL12: #N/A | AM12: #N/A | AN12: #N/A | AO12: #N/A | AP12: #N/A | AQ12: #N/A | AR12: #N/A | AS12: #N/A | AT12: #N/A | AU12: #N/A | AV12: #N/A | AW12: #N/A | AX12: #N/A | AY12: #N/A | AZ12: #N/A | BA12: 4647.34 | BB12: =IF(ISNUMBER(VLOOKUP($B12,CEIC_DATA!$I$26:$N$353,Haver_M!BB$2,FALSE)),VLOOKUP($B12,CEIC_DATA!$I$26:$N$353,Haver_M!BB$2,FALSE),NA()) -> 113.73682 | BC12: =IF(ISNUMBER(VLOOKUP($B12,CEIC_DATA!$I$26:$N$353,Haver_M!BC$2,FALSE)),VLOOKUP($B12,CEIC_DATA!$I$26:$N$353,Haver_M!BC$2,FALSE),NA()) -> #N/A | BD12: =IF(ISNUMBER(VLOOKUP($B12,CEIC_DATA!$I$26:$N$353,Haver_M!BD$2,FALSE)),VLOOKUP($B12,CEIC_DATA!$I$26:$N$353,Haver_M!BD$2,FALSE),NA()) -> #N/A | BE12: =IF(ISNUMBER(VLOOKUP($B12,CEIC_DATA!$I$26:$N$353,Haver_M!BE$2,FALSE)),VLOOKUP($B12,CEIC_DATA!$I$26:$N$353,Haver_M!BE$2,FALSE),NA()) -> #N/A | BJ12: #N/A | BK12: #N/A | BL12: #N/A | BM12: #N/A | BN12: 3526 | BO12: 4487 | BP12: 44.7788 | BQ12: =IF(ISNUMBER(BJ12),BJ12/$BP12,"") | BR12: =IF(ISNUMBER(BK12),BK12/$BP12,"") | BS12: =IF(ISNUMBER(BL12),BL12/$BP12,"") | BT12: =IF(ISNUMBER(BM12),BM12/$BP12,"") | BU12: 41250
A13: 0008 | B13: 36769 | C13: #N/A | D13: 11.3715 | E13: 93.4465 | F13: #N/A | G13: #N/A | H13: 45.99 | I13: 55.02 | J13: 27.45 | K13: 58.06 | L13: #N/A | M13: 25.01 | N13: 46.03 | O13: #N/A | P13: #N/A | Q13: #N/A | R13: #N/A | S13: #N/A | T13: #N/A | U13: #N/A | V13: #N/A | W13: #N/A | X13: 8701.667 | Y13: 3651.1 | Z13: 4054.36 | AA13: #N/A | AB13: #N/A | AC13: #N/A | AD13: #N/A | AE13: 63.806214 | AF13: #N/A | AG13: #N/A | AH13: #N/A | AI13: #N/A | AJ13: #N/A | AK13: #N/A | AL13: #N/A | AM13: #N/A | AN13: #N/A | AO13: #N/A | AP13: #N/A | AQ13: #N/A | AR13: #N/A | AS13: #N/A | AT13: #N/A | AU13: #N/A | AV13: #N/A | AW13: #N/A | AX13: #N/A | AY13: #N/A | AZ13: #N/A | BA13: 4330.31 | BB13: =IF(ISNUMBER(VLOOKUP($B13,CEIC_DATA!$I$26:$N$353,Haver_M!BB$2,FALSE)),VLOOKUP($B13,CEIC_DATA!$I$26:$N$353,Haver_M!BB$2,FALSE),NA()) -> 112.67092 | BC13: =IF(ISNUMBER(VLOOKUP($B13,CEIC_DATA!$I$26:$N$353,Haver_M!BC$2,FALSE)),VLOOKUP($B13,CEIC_DATA!$I$26:$N$353,Haver_M!BC$2,FALSE),NA()) -> #N/A | BD13: =IF(ISNUMBER(VLOOKUP($B13,CEIC_DATA!$I$26:$N$353,Haver_M!BD$2,FALSE)),VLOOKUP($B13,CEIC_DATA!$I$26:$N$353,Haver_M!BD$2,FALSE),NA()) -> #N/A | BE13: =IF(ISNUMBER(VLOOKUP($B13,CEIC_DATA!$I$26:$N$353,Haver_M!BE$2,FALSE)),VLOOKUP($B13,CEIC_DATA!$I$26:$N$353,Haver_M!BE$2,FALSE),NA()) -> #N/A | BJ13: #N/A | BK13: #N/A | BL13: #N/A | BM13: #N/A | BN13: 3670 | BO13: 3993 | BP13: 45.68 | BQ13: =IF(ISNUMBER(BJ13),BJ13/$BP13,"") | BR13: =IF(ISNUMBER(BK13),BK13/$BP13,"") | BS13: =IF(ISNUMBER(BL13),BL13/$BP13,"") | BT13: =IF(ISNUMBER(BM13),BM13/$BP13,"") | BU13: 40768
A14: 0009 | B14: 36799 | C14: #N/A | D14: 11.8051 | E14: 94.54199 | F14: #N/A | G14: #N/A | H14: 46.55 | I14: 55.53 | J14: 26.98 | K14: 58.23 | L14: #N/A | M14: 24.47 | N14: 48.02 | O14: #N/A | P14: #N/A | Q14: #N/A | R14: #N/A | S14: #N/A | T14: #N/A | U14: #N/A | V14: #N/A | W14: #N/A | X14: 9044.4752 | Y14: 3758.25 | Z14: 4211.38 | AA14: #N/A | AB14: #N/A | AC14: #N/A | AD14: #N/A | AE14: 49.221947 | AF14: #N/A | AG14: #N/A | AH14: #N/A | AI14: #N/A | AJ14: #N/A | AK14: #N/A | AL14: #N/A | AM14: #N/A | AN14: #N/A | AO14: #N/A | AP14: #N/A | AQ14: #N/A | AR14: #N/A | AS14: #N/A | AT14: #N/A | AU14: #N/A | AV14: #N/A | AW14: #N/A | AX14: #N/A | AY14: #N/A | AZ14: #N/A | BA14: 4416.61 | BB14: =IF(ISNUMBER(VLOOKUP($B14,CEIC_DATA!$I$26:$N$353,Haver_M!BB$2,FALSE)),VLOOKUP($B14,CEIC_DATA!$I$26:$N$353,Haver_M!BB$2,FALSE),NA()) -> 111.82207 | BC14: =IF(ISNUMBER(VLOOKUP($B14,CEIC_DATA!$I$26:$N$353,Haver_M!BC$2,FALSE)),VLOOKUP($B14,CEIC_DATA!$I$26:$N$353,Haver_M!BC$2,FALSE),NA()) -> 116.1 | BD14: =IF(ISNUMBER(VLOOKUP($B14,CEIC_DATA!$I$26:$N$353,Haver_M!BD$2,FALSE)),VLOOKUP($B14,CEIC_DATA!$I$26:$N$353,Haver_M!BD$2,FALSE),NA()) -> 126.1 | BE14: =IF(ISNUMBER(VLOOKUP($B14,CEIC_DATA!$I$26:$N$353,Haver_M!BE$2,FALSE)),VLOOKUP($B14,CEIC_DATA!$I$26:$N$353,Haver_M!BE$2,FALSE),NA()) -> 49 | BJ14: #N/A | BK14: #N/A | BL14: #N/A | BM14: #N/A | BN14: 3848 | BO14: 4249 | BP14: 45.8883 | BQ14: =IF(ISNUMBER(BJ14),BJ14/$BP14,"") | BR14: =IF(ISNUMBER(BK14),BK14/$BP14,"") | BS14: =IF(ISNUMBER(BL14),BL14/$BP14,"") | BT14: =IF(ISNUMBER(BM14),BM14/$BP14,"") | BU14: 40064
A15: 0010 | B15: 36830 | C15: #N/A | D15: 11.6078 | E15: 96.10024 | F15: #N/A | G15: #N/A | H15: 46.87 | I15: 56.6 | J15: 26.79 | K15: 58.53 | L15: #N/A | M15: 24.52 | N15: 48.96 | O15: #N/A | P15: #N/A | Q15: #N/A | R15: #N/A | S15: #N/A | T15: #N/A | U15: #N/A | V15: #N/A | W15: #N/A | X15: 7804.4426 | Y15: 3661.32 | Z15: 4197.55 | AA15: #N/A | AB15: #N/A | AC15: #N/A | AD15: #N/A | AE15: 55.000218 | AF15: #N/A | AG15: #N/A | AH15: #N/A | AI15: #N/A | AJ15: #N/A | AK15: #N/A | AL15: #N/A | AM15: #N/A | AN15: #N/A | AO15: #N/A | AP15: #N/A | AQ15: #N/A | AR15: #N/A | AS15: #N/A | AT15: #N/A | AU15: #N/A | AV15: #N/A | AW15: #N/A | AX15: #N/A | AY15: #N/A | AZ15: #N/A | BA15: 3819.69 | BB15: =IF(ISNUMBER(VLOOKUP($B15,CEIC_DATA!$I$26:$N$353,Haver_M!BB$2,FALSE)),VLOOKUP($B15,CEIC_DATA!$I$26:$N$353,Haver_M!BB$2,FALSE),NA()) -> 111.14065 | BC15: =IF(ISNUMBER(VLOOKUP($B15,CEIC_DATA!$I$26:$N$353,Haver_M!BC$2,FALSE)),VLOOKUP($B15,CEIC_DATA!$I$26:$N$353,Haver_M!BC$2,FALSE),NA()) -> #N/A | BD15: =IF(ISNUMBER(VLOOKUP($B15,CEIC_DATA!$I$26:$N$353,Haver_M!BD$2,FALSE)),VLOOKUP($B15,CEIC_DATA!$I$26:$N$353,Haver_M!BD$2,FALSE),NA()) -> #N/A | BE15: =IF(ISNUMBER(VLOOKUP($B15,CEIC_DATA!$I$26:$N$353,Haver_M!BE$2,FALSE)),VLOOKUP($B15,CEIC_DATA!$I$26:$N$353,Haver_M!BE$2,FALSE),NA()) -> #N/A | BJ15: #N/A | BK15: #N/A | BL15: #N/A | BM15: #N/A | BN15: 3719 | BO15: 4264 | BP15: 46.3445 | BQ15: =IF(ISNUMBER(BJ15),BJ15/$BP15,"") | BR15: =IF(ISNUMBER(BK15),BK15/$BP15,"") | BS15: =IF(ISNUMBER(BL15),BL15/$BP15,"") | BT15: =IF(ISNUMBER(BM15),BM15/$BP15,"") | BU15: 44486
A16: 0011 | B16: 36860 | C16: #N/A | D16: 11.4009 | E16: 95.6523 | F16: #N/A | G16: #N/A | H16: 46.41 | I16: 55.87 | J16: 25.77 | K16: 58.21 | L16: #N/A | M16: 25.4 | N16: 49.36 | O16: #N/A | P16: #N/A | Q16: #N/A | R16: #N/A | S16: #N/A | T16: #N/A | U16: #N/A | V16: #N/A | W16: #N/A | X16: 8274.7941 | Y16: 3789.06 | Z16: 4803.98 | AA16: #N/A | AB16: #N/A | AC16: #N/A | AD16: #N/A | AE16: 82.292219 | AF16: #N/A | AG16: #N/A | AH16: #N/A | AI16: #N/A | AJ16: #N/A | AK16: #N/A | AL16: #N/A | AM16: #N/A | AN16: #N/A | AO16: #N/A | AP16: #N/A | AQ16: #N/A | AR16: #N/A | AS16: #N/A | AT16: #N/A | AU16: #N/A | AV16: #N/A | AW16: #N/A | AX16: #N/A | AY16: #N/A | AZ16: #N/A | BA16: 3928.1 | BB16: =IF(ISNUMBER(VLOOKUP($B16,CEIC_DATA!$I$26:$N$353,Haver_M!BB$2,FALSE)),VLOOKUP($B16,CEIC_DATA!$I$26:$N$353,Haver_M!BB$2,FALSE),NA()) -> 110.53002 | BC16: =IF(ISNUMBER(VLOOKUP($B16,CEIC_DATA!$I$26:$N$353,Haver_M!BC$2,FALSE)),VLOOKUP($B16,CEIC_DATA!$I$26:$N$353,Haver_M!BC$2,FALSE),NA()) -> #N/A | BD16: =IF(ISNUMBER(VLOOKUP($B16,CEIC_DATA!$I$26:$N$353,Haver_M!BD$2,FALSE)),VLOOKUP($B16,CEIC_DATA!$I$26:$N$353,Haver_M!BD$2,FALSE),NA()) -> #N/A | BE16: =IF(ISNUMBER(VLOOKUP($B16,CEIC_DATA!$I$26:$N$353,Haver_M!BE$2,FALSE)),VLOOKUP($B16,CEIC_DATA!$I$26:$N$353,Haver_M!BE$2,FALSE),NA()) -> #N/A | BJ16: #N/A | BK16: #N/A | BL16: #N/A | BM16: #N/A | BN16: 3604 | BO16: 4698 | BP16: 46.7789 | BQ16: =IF(ISNUMBER(BJ16),BJ16/$BP16,"") | BR16: =IF(ISNUMBER(BK16),BK16/$BP16,"") | BS16: =IF(ISNUMBER(BL16),BL16/$BP16,"") | BT16: =IF(ISNUMBER(BM16),BM16/$BP16,"") | BU16: 45510
A17: 0012 | B17: 36891 | C17: #N/A | D17: 10.9359 | E17: 94.82709 | F17: #N/A | G17: #N/A | H17: 46.79 | I17: 55.42 | J17: 27.4 | K17: 58.53 | L17: #N/A | M17: 25.59 | N17: 47.9 | O17: #N/A | P17: #N/A | Q17: #N/A | R17: #N/A | S17: #N/A | T17: #N/A | U17: #N/A | V17: #N/A | W17: #N/A | X17: 8162.7802 | Y17: 3819.91 | Z17: 3973.33 | AA17: #N/A | AB17: #N/A | AC17: #N/A | AD17: #N/A | AE17: 107.32323 | AF17: #N/A | AG17: #N/A | AH17: #N/A | AI17: #N/A | AJ17: #N/A | AK17: #N/A | AL17: #N/A | AM17: #N/A | AN17: #N/A | AO17: #N/A | AP17: #N/A | AQ17: #N/A | AR17: #N/A | AS17: #N/A | AT17: #N/A | AU17: #N/A | AV17: #N/A | AW17: #N/A | AX17: #N/A | AY17: #N/A | AZ17: #N/A | BA17: 4081.42 | BB17: =IF(ISNUMBER(VLOOKUP($B17,CEIC_DATA!$I$26:$N$353,Haver_M!BB$2,FALSE)),VLOOKUP($B17,CEIC_DATA!$I$26:$N$353,Haver_M!BB$2,FALSE),NA()) -> 109.86881 | BC17: =IF(ISNUMBER(VLOOKUP($B17,CEIC_DATA!$I$26:$N$353,Haver_M!BC$2,FALSE)),VLOOKUP($B17,CEIC_DATA!$I$26:$N$353,Haver_M!BC$2,FALSE),NA()) -> 113.9 | BD17: =IF(ISNUMBER(VLOOKUP($B17,CEIC_DATA!$I$26:$N$353,Haver_M!BD$2,FALSE)),VLOOKUP($B17,CEIC_DATA!$I$26:$N$353,Haver_M!BD$2,FALSE),NA()) -> 124.4 | BE17: =IF(ISNUMBER(VLOOKUP($B17,CEIC_DATA!$I$26:$N$353,Haver_M!BE$2,FALSE)),VLOOKUP($B17,CEIC_DATA!$I$26:$N$353,Haver_M!BE$2,FALSE),NA()) -> 51.7 | BJ17: #N/A | BK17: #N/A | BL17: #N/A | BM17: #N/A | BN17: 3657 | BO17: 3976 | BP17: 46.7496 | BQ17: =IF(ISNUMBER(BJ17),BJ17/$BP17,"") | BR17: =IF(ISNUMBER(BK17),BK17/$BP17,"") | BS17: =IF(ISNUMBER(BL17),BL17/$BP17,"") | BT17: =IF(ISNUMBER(BM17),BM17/$BP17,"") | BU17: 45768
A18: 0101 | B18: 36922 | C18: #N/A | D18: 10.4842 | E18: 93.97701 | F18: 46.9 | G18: #N/A | H18: 46.37 | I18: 54.93 | J18: 26.45 | K18: 57.89 | L18: #N/A | M18: 24.5 | N18: 49.62 | O18: #N/A | P18: #N/A | Q18: #N/A | R18: #N/A | S18: #N/A | T18: #N/A | U18: #N/A | V18: #N/A | W18: #N/A | X18: 8410.2443 | Y18: 3649.92 | Z18: 3994.9 | AA18: #N/A | AB18: #N/A | AC18: #N/A | AD18: #N/A | AE18: 103.76458 | AF18: #N/A | AG18: #N/A | AH18: #N/A | AI18: #N/A | AJ18: #N/A | AK18: #N/A | AL18: #N/A | AM18: #N/A | AN18: #N/A | AO18: #N/A | AP18: #N/A | AQ18: #N/A | AR18: #N/A | AS18: #N/A | AT18: #N/A | AU18: #N/A | AV18: #N/A | AW18: #N/A | AX18: #N/A | AY18: #N/A | AZ18: #N/A | BA18: 4152.39 | BB18: =IF(ISNUMBER(VLOOKUP($B18,CEIC_DATA!$I$26:$N$353,Haver_M!BB$2,FALSE)),VLOOKUP($B18,CEIC_DATA!$I$26:$N$353,Haver_M!BB$2,FALSE),NA()) -> 109.07673 | BC18: =IF(ISNUMBER(VLOOKUP($B18,CEIC_DATA!$I$26:$N$353,Haver_M!BC$2,FALSE)),VLOOKUP($B18,CEIC_DATA!$I$26:$N$353,Haver_M!BC$2,FALSE),NA()) -> #N/A | BD18: =IF(ISNUMBER(VLOOKUP($B18,CEIC_DATA!$I$26:$N$353,Haver_M!BD$2,FALSE)),VLOOKUP($B18,CEIC_DATA!$I$26:$N$353,Haver_M!BD$2,FALSE),NA()) -> #N/A | BE18: =IF(ISNUMBER(VLOOKUP($B18,CEIC_DATA!$I$26:$N$353,Haver_M!BE$2,FALSE)),VLOOKUP($B18,CEIC_DATA!$I$26:$N$353,Haver_M!BE$2,FALSE),NA()) -> #N/A | BJ18: #N/A | BK18: #N/A | BL18: #N/A | BM18: #N/A | BN18: 3666 | BO18: 4007 | BP18: 46.5439 | BQ18: =IF(ISNUMBER(BJ18),BJ18/$BP18,"") | BR18: =IF(ISNUMBER(BK18),BK18/$BP18,"") | BS18: =IF(ISNUMBER(BL18),BL18/$BP18,"") | BT18: =IF(ISNUMBER(BM18),BM18/$BP18,"") | BU18: 46558
A19: 0102 | B19: 36950 | C19: #N/A | D19: 10.0447 | E19: 95.06243 | F19: 46.8 | G19: #N/A | H19: 47.15 | I19: 55.3 | J19: 26.5 | K19: 58.86 | L19: #N/A | M19: 26.59 | N19: 50.01 | O19: #N/A | P19: #N/A | Q19: #N/A | R19: #N/A | S19: #N/A | T19: #N/A | U19: #N/A | V19: #N/A | W19: #N/A | X19: 8119.6426 | Y19: 3715.54 | Z19: 3713.63 | AA19: #N/A | AB19: #N/A | AC19: #N/A | AD19: #N/A | AE19: 121.81913 | AF19: #N/A | AG19: #N/A | AH19: #N/A | AI19: #N/A | AJ19: #N/A | AK19: #N/A | AL19: #N/A | AM19: #N/A | AN19: #N/A | AO19: #N/A | AP19: #N/A | AQ19: #N/A | AR19: #N/A | AS19: #N/A | AT19: #N/A | AU19: #N/A | AV19: #N/A | AW19: #N/A | AX19: #N/A | AY19: #N/A | AZ19: #N/A | BA19: 4310.13 | BB19: =IF(ISNUMBER(VLOOKUP($B19,CEIC_DATA!$I$26:$N$353,Haver_M!BB$2,FALSE)),VLOOKUP($B19,CEIC_DATA!$I$26:$N$353,Haver_M!BB$2,FALSE),NA()) -> 108.10665 | BC19: =IF(ISNUMBER(VLOOKUP($B19,CEIC_DATA!$I$26:$N$353,Haver_M!BC$2,FALSE)),VLOOKUP($B19,CEIC_DATA!$I$26:$N$353,Haver_M!BC$2,FALSE),NA()) -> #N/A | BD19: =IF(ISNUMBER(VLOOKUP($B19,CEIC_DATA!$I$26:$N$353,Haver_M!BD$2,FALSE)),VLOOKUP($B19,CEIC_DATA!$I$26:$N$353,Haver_M!BD$2,FALSE),NA()) -> #N/A | BE19: =IF(ISNUMBER(VLOOKUP($B19,CEIC_DATA!$I$26:$N$353,Haver_M!BE$2,FALSE)),VLOOKUP($B19,CEIC_DATA!$I$26:$N$353,Haver_M!BE$2,FALSE),NA()) -> #N/A | BJ19: #N/A | BK19: #N/A | BL19: #N/A | BM19: #N/A | BN19: 3695 | BO19: 3457 | BP19: 46.5167 | BQ19: =IF(ISNUMBER(BJ19),BJ19/$BP19,"") | BR19: =IF(ISNUMBER(BK19),BK19/$BP19,"") | BS19: =IF(ISNUMBER(BL19),BL19/$BP19,"") | BT19: =IF(ISNUMBER(BM19),BM19/$BP19,"") | BU19: 46752
A20: 0103 | B20: 36981 | C20: #N/A | D20: 10.2737 | E20: 96.51569 | F20: 47.1 | G20: #N/A | H20: 46.95 | I20: 55.14 | J20: 25.92 | K20: 60.54 | L20: #N/A | M20: 25.99 | N20: 48.52 | O20: #N/A | P20: #N/A | Q20: #N/A | R20: #N/A | S20: #N/A | T20: #N/A | U20: #N/A | V20: #N/A | W20: #N/A | X20: 8485.7498 | Y20: 3741.73 | Z20: 4323.55 | AA20: #N/A | AB20: #N/A | AC20: #N/A | AD20: #N/A | AE20: 143.45661 | AF20: #N/A | AG20: #N/A | AH20: #N/A | AI20: #N/A | AJ20: #N/A | AK20: #N/A | AL20: #N/A | AM20: #N/A | AN20: #N/A | AO20: #N/A | AP20: #N/A | AQ20: #N/A | AR20: #N/A | AS20: #N/A | AT20: #N/A | AU20: #N/A | AV20: #N/A | AW20: #N/A | AX20: #N/A | AY20: #N/A | AZ20: #N/A | BA20: 3807.64 | BB20: =IF(ISNUMBER(VLOOKUP($B20,CEIC_DATA!$I$26:$N$353,Haver_M!BB$2,FALSE)),VLOOKUP($B20,CEIC_DATA!$I$26:$N$353,Haver_M!BB$2,FALSE),NA()) -> 106.87329 | BC20: =IF(ISNUMBER(VLOOKUP($B20,CEIC_DATA!$I$26:$N$353,Haver_M!BC$2,FALSE)),VLOOKUP($B20,CEIC_DATA!$I$26:$N$353,Haver_M!BC$2,FALSE),NA()) -> 115.2 | BD20: =IF(ISNUMBER(VLOOKUP($B20,CEIC_DATA!$I$26:$N$353,Haver_M!BD$2,FALSE)),VLOOKUP($B20,CEIC_DATA!$I$26:$N$353,Haver_M!BD$2,FALSE),NA()) -> 122.5 | BE20: =IF(ISNUMBER(VLOOKUP($B20,CEIC_DATA!$I$26:$N$353,Haver_M!BE$2,FALSE)),VLOOKUP($B20,CEIC_DATA!$I$26:$N$353,Haver_M!BE$2,FALSE),NA()) -> 49 | BJ20: #N/A | BK20: #N/A | BL20: #N/A | BM20: #N/A | BN20: 4309 | BO20: 4625 | BP20: 46.6205 | BQ20: =IF(ISNUMBER(BJ20),BJ20/$BP20,"") | BR20: =IF(ISNUMBER(BK20),BK20/$BP20,"") | BS20: =IF(ISNUMBER(BL20),BL20/$BP20,"") | BT20: =IF(ISNUMBER(BM20),BM20/$BP20,"") | BU20: 44978
A21: 0104 | B21: 37011 | C21: 8.75 | D21: 10.0779 | E21: 97.44224 | F21: 47.4 | G21: #N/A | H21: 47.04 | I21: 55.86 | J21: 27.95 | K21: 59.6 | L21: #N/A | M21: 26.52 | N21: 47.52 | O21: #N/A | P21: #N/A | Q21: #N/A | R21: #N/A | S21: #N/A | T21: #N/A | U21: #N/A | V21: #N/A | W21: #N/A | X21: 8308.7308 | Y21: 3226.88 | Z21: 4209.42 | AA21: #N/A | AB21: #N/A | AC21: #N/A | AD21: #N/A | AE21: 121.81104 | AF21: #N/A | AG21: #N/A | AH21: #N/A | AI21: #N/A | AJ21: #N/A | AK21: #N/A | AL21: #N/A | AM21: #N/A | AN21: #N/A | AO21: #N/A | AP21: #N/A | AQ21: #N/A | AR21: #N/A | AS21: #N/A | AT21: #N/A | AU21: #N/A | AV21: #N/A | AW21: #N/A | AX21: #N/A | AY21: #N/A | AZ21: #N/A | BA21: 3487.44 | BB21: =IF(ISNUMBER(VLOOKUP($B21,CEIC_DATA!$I$26:$N$353,Haver_M!BB$2,FALSE)),VLOOKUP($B21,CEIC_DATA!$I$26:$N$353,Haver_M!BB$2,FALSE),NA()) -> 105.39878 | BC21: =IF(ISNUMBER(VLOOKUP($B21,CEIC_DATA!$I$26:$N$353,Haver_M!BC$2,FALSE)),VLOOKUP($B21,CEIC_DATA!$I$26:$N$353,Haver_M!BC$2,FALSE),NA()) -> #N/A | BD21: =IF(ISNUMBER(VLOOKUP($B21,CEIC_DATA!$I$26:$N$353,Haver_M!BD$2,FALSE)),VLOOKUP($B21,CEIC_DATA!$I$26:$N$353,Haver_M!BD$2,FALSE),NA()) -> #N/A | BE21: =IF(ISNUMBER(VLOOKUP($B21,CEIC_DATA!$I$26:$N$353,Haver_M!BE$2,FALSE)),VLOOKUP($B21,CEIC_DATA!$I$26:$N$353,Haver_M!BE$2,FALSE),NA()) -> #N/A | BJ21: #N/A | BK21: #N/A | BL21: #N/A | BM21: #N/A | BN21: 3115 | BO21: 4094 | BP21: 46.7835 | BQ21: =IF(ISNUMBER(BJ21),BJ21/$BP21,"") | BR21: =IF(ISNUMBER(BK21),BK21/$BP21,"") | BS21: =IF(ISNUMBER(BL21),BL21/$BP21,"") | BT21: =IF(ISNUMBER(BM21),BM21/$BP21,"") | BU21: 52444
A22: 0105 | B22: 37042 | C22: 8.75 | D22: 9.7149 | E22: 97.51621 | F22: 47.8 | G22: #N/A | H22: 46.86 | I22: 55.5 | J22: 26.1 | K22: 59.65 | L22: #N/A | M22: 27.44 | N22: 46.95 | O22: #N/A | P22: #N/A | Q22: #N/A | R22: #N/A | S22: #N/A | T22: #N/A | U22: #N/A | V22: #N/A | W22: #N/A | X22: 8356.4908 | Y22: 3687.82 | Z22: 4455.23 | AA22: #N/A | AB22: #N/A | AC22: #N/A | AD22: #N/A | AE22: 88.793829 | AF22: #N/A | AG22: #N/A | AH22: #N/A | AI22: #N/A | AJ22: #N/A | AK22: #N/A | AL22: #N/A | AM22: #N/A | AN22: #N/A | AO22: #N/A | AP22: #N/A | AQ22: #N/A | AR22: #N/A | AS22: #N/A | AT22: #N/A | AU22: #N/A | AV22: #N/A | AW22: #N/A | AX22: #N/A | AY22: #N/A | AZ22: #N/A | BA22: 3613.84 | BB22: =IF(ISNUMBER(VLOOKUP($B22,CEIC_DATA!$I$26:$N$353,Haver_M!BB$2,FALSE)),VLOOKUP($B22,CEIC_DATA!$I$26:$N$353,Haver_M!BB$2,FALSE),NA()) -> 103.67671 | BC22: =IF(ISNUMBER(VLOOKUP($B22,CEIC_DATA!$I$26:$N$353,Haver_M!BC$2,FALSE)),VLOOKUP($B22,CEIC_DATA!$I$26:$N$353,Haver_M!BC$2,FALSE),NA()) -> #N/A | BD22: =IF(ISNUMBER(VLOOKUP($B22,CEIC_DATA!$I$26:$N$353,Haver_M!BD$2,FALSE)),VLOOKUP($B22,CEIC_DATA!$I$26:$N$353,Haver_M!BD$2,FALSE),NA()) -> #N/A | BE22: =IF(ISNUMBER(VLOOKUP($B22,CEIC_DATA!$I$26:$N$353,Haver_M!BE$2,FALSE)),VLOOKUP($B22,CEIC_DATA!$I$26:$N$353,Haver_M!BE$2,FALSE),NA()) -> #N/A | BF22: 337038 | BG22: 9137 | BH22: 423736 | BI22: 61818 | BJ22: #N/A | BK22: #N/A | BL22: #N/A | BM22: #N/A | BN22: 3629 | BO22: 4674 | BP22: 46.9202 | BQ22: =IF(ISNUMBER(BJ22),BJ22/$BP22,"") | BR22: =IF(ISNUMBER(BK22),BK22/$BP22,"") | BS22: =IF(ISNUMBER(BL22),BL22/$BP22,"") | BT22: =IF(ISNUMBER(BM22),BM22/$BP22,"") | BU22: 60701
A23: 0106 | B23: 37072 | C23: 8.5 | D23: 9.4551 | E23: 98.84518 | F23: 48.3 | G23: #N/A | H23: 47.17 | I23: 55.4 | J23: 24.9 | K23: 59.36 | L23: #N/A | M23: 27.78 | N23: 50.49 | O23: #N/A | P23: #N/A | Q23: #N/A | R23: #N/A | S23: #N/A | T23: #N/A | U23: #N/A | V23: #N/A | W23: #N/A | X23: 8609.3938 | Y23: 3782.77 | Z23: 4247.93 | AA23: #N/A | AB23: #N/A | AC23: #N/A | AD23: #N/A | AE23: 88.922303 | AF23: #N/A | AG23: #N/A | AH23: #N/A | AI23: #N/A | AJ23: #N/A | AK23: #N/A | AL23: #N/A | AM23: #N/A | AN23: #N/A | AO23: #N/A | AP23: #N/A | AQ23: #N/A | AR23: #N/A | AS23: #N/A | AT23: #N/A | AU23: #N/A | AV23: #N/A | AW23: #N/A | AX23: #N/A | AY23: #N/A | AZ23: #N/A | BA23: 3439.01 | BB23: =IF(ISNUMBER(VLOOKUP($B23,CEIC_DATA!$I$26:$N$353,Haver_M!BB$2,FALSE)),VLOOKUP($B23,CEIC_DATA!$I$26:$N$353,Haver_M!BB$2,FALSE),NA()) -> 101.57751 | BC23: =IF(ISNUMBER(VLOOKUP($B23,CEIC_DATA!$I$26:$N$353,Haver_M!BC$2,FALSE)),VLOOKUP($B23,CEIC_DATA!$I$26:$N$353,Haver_M!BC$2,FALSE),NA()) -> 109.9 | BD23: =IF(ISNUMBER(VLOOKUP($B23,CEIC_DATA!$I$26:$N$353,Haver_M!BD$2,FALSE)),VLOOKUP($B23,CEIC_DATA!$I$26:$N$353,Haver_M!BD$2,FALSE),NA()) -> 120.7 | BE23: =IF(ISNUMBER(VLOOKUP($B23,CEIC_DATA!$I$26:$N$353,Haver_M!BE$2,FALSE)),VLOOKUP($B23,CEIC_DATA!$I$26:$N$353,Haver_M!BE$2,FALSE),NA()) -> 43.7 | BF23: 326699 | BG23: 12262 | BH23: 412217 | BI23: 55946 | BJ23: #N/A | BK23: #N/A | BL23: #N/A | BM23: #N/A | BN23: 3612 | BO23: 4017 | BP23: 47.0038 | BQ23: =IF(ISNUMBER(BJ23),BJ23/$BP23,"") | BR23: =IF(ISNUMBER(BK23),BK23/$BP23,"") | BS23: =IF(ISNUMBER(BL23),BL23/$BP23,"") | BT23: =IF(ISNUMBER(BM23),BM23/$BP23,"") | BU23: 61958
A24: 0107 | B24: 37103 | C24: 8.5 | D24: 9.2609 | E24: 99.14074 | F24: 48.8 | G24: #N/A | H24: 46.86 | I24: 55.32 | J24: 25.39 | K24: 58.94 | L24: #N/A | M24: 29.17 | N24: 47.11 | O24: #N/A | P24: #N/A | Q24: #N/A | R24: #N/A | S24: #N/A | T24: #N/A | U24: #N/A | V24: #N/A | W24: #N/A | X24: 7897.0122 | Y24: 3456.32 | Z24: 4765.93 | AA24: #N/A | AB24: #N/A | AC24: #N/A | AD24: #N/A | AE24: 115.32456 | AF24: #N/A | AG24: #N/A | AH24: #N/A | AI24: #N/A | AJ24: #N/A | AK24: #N/A | AL24: #N/A | AM24: #N/A | AN24: #N/A | AO24: #N/A | AP24: #N/A | AQ24: #N/A | AR24: #N/A | AS24: #N/A | AT24: #N/A | AU24: #N/A | AV24: #N/A | AW24: #N/A | AX24: #N/A | AY24: #N/A | AZ24: #N/A | BA24: 3346.88 | BB24: =IF(ISNUMBER(VLOOKUP($B24,CEIC_DATA!$I$26:$N$353,Haver_M!BB$2,FALSE)),VLOOKUP($B24,CEIC_DATA!$I$26:$N$353,Haver_M!BB$2,FALSE),NA()) -> 99.306173 | BC24: =IF(ISNUMBER(VLOOKUP($B24,CEIC_DATA!$I$26:$N$353,Haver_M!BC$2,FALSE)),VLOOKUP($B24,CEIC_DATA!$I$26:$N$353,Haver_M!BC$2,FALSE),NA()) -> #N/A | BD24: =IF(ISNUMBER(VLOOKUP($B24,CEIC_DATA!$I$26:$N$353,Haver_M!BD$2,FALSE)),VLOOKUP($B24,CEIC_DATA!$I$26:$N$353,Haver_M!BD$2,FALSE),NA()) -> #N/A | BE24: =IF(ISNUMBER(VLOOKUP($B24,CEIC_DATA!$I$26:$N$353,Haver_M!BE$2,FALSE)),VLOOKUP($B24,CEIC_DATA!$I$26:$N$353,Haver_M!BE$2,FALSE),NA()) -> #N/A | BF24: 326878 | BG24: 10660 | BH24: 414085 | BI24: 57654 | BJ24: #N/A | BK24: #N/A | BL24: #N/A | BM24: #N/A | BN24: 3433 | BO24: 4923 | BP24: 47.1393 | BQ24: =IF(ISNUMBER(BJ24),BJ24/$BP24,"") | BR24: =IF(ISNUMBER(BK24),BK24/$BP24,"") | BS24: =IF(ISNUMBER(BL24),BL24/$BP24,"") | BT24: =IF(ISNUMBER(BM24),BM24/$BP24,"") | BU24: 61008
A25: 0108 | B25: 37134 | C25: 8.5 | D25: 9.1394 | E25: 97.71676 | F25: 49.2 | G25: #N/A | H25: 47.28 | I25: 56.84 | J25: 25.28 | K25: 58.79 | L25: #N/A | M25: 28.98 | N25: 48.38 | O25: #N/A | P25: #N/A | Q25: #N/A | R25: #N/A | S25: #N/A | T25: #N/A | U25: #N/A | V25: #N/A | W25: #N/A | X25: 8479.202 | Y25: 3656.43 | Z25: 4430.63 | AA25: #N/A | AB25: #N/A | AC25: #N/A | AD25: #N/A | AE25: 89.27407 | AF25: #N/A | AG25: #N/A | AH25: #N/A | AI25: #N/A | AJ25: #N/A | AK25: #N/A | AL25: #N/A | AM25: #N/A | AN25: #N/A | AO25: #N/A | AP25: #N/A | AQ25: #N/A | AR25: #N/A | AS25: #N/A | AT25: #N/A | AU25: #N/A | AV25: #N/A | AW25: #N/A | AX25: #N/A | AY25: #N/A | AZ25: #N/A | BA25: 3304.99 | BB25: =IF(ISNUMBER(VLOOKUP($B25,CEIC_DATA!$I$26:$N$353,Haver_M!BB$2,FALSE)),VLOOKUP($B25,CEIC_DATA!$I$26:$N$353,Haver_M!BB$2,FALSE),NA()) -> 97.069076 | BC25: =IF(ISNUMBER(VLOOKUP($B25,CEIC_DATA!$I$26:$N$353,Haver_M!BC$2,FALSE)),VLOOKUP($B25,CEIC_DATA!$I$26:$N$353,Haver_M!BC$2,FALSE),NA()) -> #N/A | BD25: =IF(ISNUMBER(VLOOKUP($B25,CEIC_DATA!$I$26:$N$353,Haver_M!BD$2,FALSE)),VLOOKUP($B25,CEIC_DATA!$I$26:$N$353,Haver_M!BD$2,FALSE),NA()) -> #N/A | BE25: =IF(ISNUMBER(VLOOKUP($B25,CEIC_DATA!$I$26:$N$353,Haver_M!BE$2,FALSE)),VLOOKUP($B25,CEIC_DATA!$I$26:$N$353,Haver_M!BE$2,FALSE),NA()) -> #N/A | BF25: 333685 | BG25: 12879 | BH25: 427949 | BI25: 61861 | BJ25: #N/A | BK25: #N/A | BL25: #N/A | BM25: #N/A | BN25: 3647 | BO25: 4372 | BP25: 47.1265 | BQ25: =IF(ISNUMBER(BJ25),BJ25/$BP25,"") | BR25: =IF(ISNUMBER(BK25),BK25/$BP25,"") | BS25: =IF(ISNUMBER(BL25),BL25/$BP25,"") | BT25: =IF(ISNUMBER(BM25),BM25/$BP25,"") | BU25: 59458
A26: 0109 | B26: 37164 | C26: 8.5 | D26: 9.1468 | E26: 96.22923 | F26: 49 | G26: #N/A | H26: 47.45 | I26: 58.18 | J26: 25.16 | K26: 59.67 | L26: #N/A | M26: 29.32 | N26: 45.08 | O26: #N/A | P26: #N/A | Q26: #N/A | R26: #N/A | S26: #N/A | T26: #N/A | U26: #N/A | V26: #N/A | W26: #N/A | X26: 8718.1143 | Y26: 3598.84 | Z26: 3848.47 | AA26: #N/A | AB26: #N/A | AC26: #N/A | AD26: #N/A | AE26: 125.07716 | AF26: #N/A | AG26: #N/A | AH26: #N/A | AI26: #N/A | AJ26: #N/A | AK26: #N/A | AL26: #N/A | AM26: #N/A | AN26: #N/A | AO26: #N/A | AP26: #N/A | AQ26: #N/A | AR26: #N/A | AS26: #N/A | AT26: #N/A | AU26: #N/A | AV26: #N/A | AW26: #N/A | AX26: #N/A | AY26: #N/A | AZ26: #N/A | BA26: 2918.28 | BB26: =IF(ISNUMBER(VLOOKUP($B26,CEIC_DATA!$I$26:$N$353,Haver_M!BB$2,FALSE)),VLOOKUP($B26,CEIC_DATA!$I$26:$N$353,Haver_M!BB$2,FALSE),NA()) -> 95.09125 | BC26: =IF(ISNUMBER(VLOOKUP($B26,CEIC_DATA!$I$26:$N$353,Haver_M!BC$2,FALSE)),VLOOKUP($B26,CEIC_DATA!$I$26:$N$353,Haver_M!BC$2,FALSE),NA()) -> 108.7 | BD26: =IF(ISNUMBER(VLOOKUP($B26,CEIC_DATA!$I$26:$N$353,Haver_M!BD$2,FALSE)),VLOOKUP($B26,CEIC_DATA!$I$26:$N$353,Haver_M!BD$2,FALSE),NA()) -> 118.9 | BE26: =IF(ISNUMBER(VLOOKUP($B26,CEIC_DATA!$I$26:$N$353,Haver_M!BE$2,FALSE)),VLOOKUP($B26,CEIC_DATA!$I$26:$N$353,Haver_M!BE$2,FALSE),NA()) -> 39.7 | BF26: 363861 | BG26: 14317 | BH26: 456341 | BI26: 59498 | BJ26: #N/A | BK26: #N/A | BL26: #N/A | BM26: #N/A | BN26: 3702 | BO26: 3902 | BP26: 47.642 | BQ26: =IF(ISNUMBER(BJ26),BJ26/$BP26,"") | BR26: =IF(ISNUMBER(BK26),BK26/$BP26,"") | BS26: =IF(ISNUMBER(BL26),BL26/$BP26,"") | BT26: =IF(ISNUMBER(BM26),BM26/$BP26,"") | BU26: 58280
A27: 0110 | B27: 37195 | C27: 8.5 | D27: 8.7893 | E27: 97.51282 | F27: 49.5 | G27: #N/A | H27: 47.3 | I27: 57.01 | J27: 25.86 | K27: 57.67 | L27: #N/A | M27: 28.64 | N27: 48.45 | O27: #N/A | P27: #N/A | Q27: #N/A | R27: #N/A | S27: #N/A | T27: #N/A | U27: #N/A | V27: #N/A | W27: #N/A | X27: 8342.8517 | Y27: 3648.16 | Z27: 3987.97 | AA27: #N/A | AB27: #N/A | AC27: #N/A | AD27: #N/A | AE27: 90.841404 | AF27: #N/A | AG27: #N/A | AH27: #N/A | AI27: #N/A | AJ27: #N/A | AK27: #N/A | AL27: #N/A | AM27: #N/A | AN27: #N/A | AO27: #N/A | AP27: #N/A | AQ27: #N/A | AR27: #N/A | AS27: #N/A | AT27: #N/A | AU27: #N/A | AV27: #N/A | AW27: #N/A | AX27: #N/A | AY27: #N/A | AZ27: #N/A | BA27: 2933.55 | BB27: =IF(ISNUMBER(VLOOKUP($B27,CEIC_DATA!$I$26:$N$353,Haver_M!BB$2,FALSE)),VLOOKUP($B27,CEIC_DATA!$I$26:$N$353,Haver_M!BB$2,FALSE),NA()) -> 93.647759 | BC27: =IF(ISNUMBER(VLOOKUP($B27,CEIC_DATA!$I$26:$N$353,Haver_M!BC$2,FALSE)),VLOOKUP($B27,CEIC_DATA!$I$26:$N$353,Haver_M!BC$2,FALSE),NA()) -> #N/A | BD27: =IF(ISNUMBER(VLOOKUP($B27,CEIC_DATA!$I$26:$N$353,Haver_M!BD$2,FALSE)),VLOOKUP($B27,CEIC_DATA!$I$26:$N$353,Haver_M!BD$2,FALSE),NA()) -> #N/A | BE27: =IF(ISNUMBER(VLOOKUP($B27,CEIC_DATA!$I$26:$N$353,Haver_M!BE$2,FALSE)),VLOOKUP($B27,CEIC_DATA!$I$26:$N$353,Haver_M!BE$2,FALSE),NA()) -> #N/A | BF27: 412952 | BG27: 12982 | BH27: 497907 | BI27: 52195 | BJ27: #N/A | BK27: #N/A | BL27: #N/A | BM27: #N/A | BN27: 3718 | BO27: 4093 | BP27: 48.0198 | BQ27: =IF(ISNUMBER(BJ27),BJ27/$BP27,"") | BR27: =IF(ISNUMBER(BK27),BK27/$BP27,"") | BS27: =IF(ISNUMBER(BL27),BL27/$BP27,"") | BT27: =IF(ISNUMBER(BM27),BM27/$BP27,"") | BU27: 62302
A28: 0111 | B28: 37225 | C28: 8.5 | D28: 7.9239 | E28: 98.42142 | F28: 49.9 | G28: #N/A | H28: 48.28 | I28: 57.59 | J28: 26.81 | K28: 59.24 | L28: #N/A | M28: 27.83 | N28: 53.35 | O28: #N/A | P28: #N/A | Q28: #N/A | R28: #N/A | S28: #N/A | T28: #N/A | U28: #N/A | V28: #N/A | W28: #N/A | X28: 8378.7635 | Y28: 3782.36 | Z28: 4251.75 | AA28: #N/A | AB28: #N/A | AC28: #N/A | AD28: #N/A | AE28: 109.01473 | AF28: #N/A | AG28: #N/A | AH28: #N/A | AI28: #N/A | AJ28: #N/A | AK28: #N/A | AL28: #N/A | AM28: #N/A | AN28: #N/A | AO28: #N/A | AP28: #N/A | AQ28: #N/A | AR28: #N/A | AS28: #N/A | AT28: #N/A | AU28: #N/A | AV28: #N/A | AW28: #N/A | AX28: #N/A | AY28: #N/A | AZ28: #N/A | BA28: 3164.25 | BB28: =IF(ISNUMBER(VLOOKUP($B28,CEIC_DATA!$I$26:$N$353,Haver_M!BB$2,FALSE)),VLOOKUP($B28,CEIC_DATA!$I$26:$N$353,Haver_M!BB$2,FALSE),NA()) -> 93.0552 | BC28: =IF(ISNUMBER(VLOOKUP($B28,CEIC_DATA!$I$26:$N$353,Haver_M!BC$2,FALSE)),VLOOKUP($B28,CEIC_DATA!$I$26:$N$353,Haver_M!BC$2,FALSE),NA()) -> #N/A | BD28: =IF(ISNUMBER(VLOOKUP($B28,CEIC_DATA!$I$26:$N$353,Haver_M!BD$2,FALSE)),VLOOKUP($B28,CEIC_DATA!$I$26:$N$353,Haver_M!BD$2,FALSE),NA()) -> #N/A | BE28: =IF(ISNUMBER(VLOOKUP($B28,CEIC_DATA!$I$26:$N$353,Haver_M!BE$2,FALSE)),VLOOKUP($B28,CEIC_DATA!$I$26:$N$353,Haver_M!BE$2,FALSE),NA()) -> #N/A | BF28: 388194 | BG28: 12691 | BH28: 473105 | BI28: 54957 | BJ28: #N/A | BK28: #N/A | BL28: #N/A | BM28: #N/A | BN28: 3576 | BO28: 4158 | BP28: 47.9947 | BQ28: =IF(ISNUMBER(BJ28),BJ28/$BP28,"") | BR28: =IF(ISNUMBER(BK28),BK28/$BP28,"") | BS28: =IF(ISNUMBER(BL28),BL28/$BP28,"") | BT28: =IF(ISNUMBER(BM28),BM28/$BP28,"") | BU28: 59150
A29: 0112 | B29: 37256 | C29: 8.5 | D29: 8.2666 | E29: 99.12557 | F29: 49.7 | G29: #N/A | H29: 48.15 | I29: 57.2 | J29: 25.9 | K29: 59.14 | L29: #N/A | M29: 27.57 | N29: 51.56 | O29: #N/A | P29: #N/A | Q29: #N/A | R29: #N/A | S29: #N/A | T29: #N/A | U29: #N/A | V29: #N/A | W29: #N/A | X29: 8324.8962 | Y29: 3418.02 | Z29: 4108.9 | AA29: #N/A | AB29: #N/A | AC29: #N/A | AD29: #N/A | AE29: 92.307133 | AF29: #N/A | AG29: #N/A | AH29: #N/A | AI29: #N/A | AJ29: #N/A | AK29: #N/A | AL29: #N/A | AM29: #N/A | AN29: #N/A | AO29: #N/A | AP29: #N/A | AQ29: #N/A | AR29: #N/A | AS29: #N/A | AT29: #N/A | AU29: #N/A | AV29: #N/A | AW29: #N/A | AX29: #N/A | AY29: #N/A | AZ29: #N/A | BA29: 3314.88 | BB29: =IF(ISNUMBER(VLOOKUP($B29,CEIC_DATA!$I$26:$N$353,Haver_M!BB$2,FALSE)),VLOOKUP($B29,CEIC_DATA!$I$26:$N$353,Haver_M!BB$2,FALSE),NA()) -> 93.110436 | BC29: =IF(ISNUMBER(VLOOKUP($B29,CEIC_DATA!$I$26:$N$353,Haver_M!BC$2,FALSE)),VLOOKUP($B29,CEIC_DATA!$I$26:$N$353,Haver_M!BC$2,FALSE),NA()) -> 100.7 | BD29: =IF(ISNUMBER(VLOOKUP($B29,CEIC_DATA!$I$26:$N$353,Haver_M!BD$2,FALSE)),VLOOKUP($B29,CEIC_DATA!$I$26:$N$353,Haver_M!BD$2,FALSE),NA()) -> 119.5 | BE29: =IF(ISNUMBER(VLOOKUP($B29,CEIC_DATA!$I$26:$N$353,Haver_M!BE$2,FALSE)),VLOOKUP($B29,CEIC_DATA!$I$26:$N$353,Haver_M!BE$2,FALSE),NA()) -> 42.9 | BF29: 355262 | BG29: 12643 | BH29: 435699 | BI29: 50374 | BJ29: #N/A | BK29: #N/A | BL29: #N/A | BM29: #N/A | BN29: 3250 | BO29: 4079 | BP29: 47.9176 | BQ29: =IF(ISNUMBER(BJ29),BJ29/$BP29,"") | BR29: =IF(ISNUMBER(BK29),BK29/$BP29,"") | BS29: =IF(ISNUMBER(BL29),BL29/$BP29,"") | BT29: =IF(ISNUMBER(BM29),BM29/$BP29,"") | BU29: 58112
A30: 0201 | B30: 37287 | C30: 8.5 | D30: 7.6474 | E30: 98.43303 | F30: 49.5 | G30: #N/A | H30: 48.15 | I30: 57.31 | J30: 25.77 | K30: 59.01 | L30: #N/A | M30: 28.3 | N30: 51.69 | O30: #N/A | P30: #N/A | Q30: #N/A | R30: #N/A | S30: #N/A | T30: #N/A | U30: #N/A | V30: #N/A | W30: #N/A | X30: 8351.6856 | Y30: 4201.29 | Z30: 4221.94 | AA30: #N/A | AB30: #N/A | AC30: #N/A | AD30: #N/A | AE30: 104.03095 | AF30: #N/A | AG30: #N/A | AH30: #N/A | AI30: #N/A | AJ30: #N/A | AK30: #N/A | AL30: #N/A | AM30: #N/A | AN30: #N/A | AO30: #N/A | AP30: #N/A | AQ30: #N/A | AR30: #N/A | AS30: #N/A | AT30: #N/A | AU30: #N/A | AV30: #N/A | AW30: #N/A | AX30: #N/A | AY30: #N/A | AZ30: #N/A | BA30: 3353.31 | BB30: =IF(ISNUMBER(VLOOKUP($B30,CEIC_DATA!$I$26:$N$353,Haver_M!BB$2,FALSE)),VLOOKUP($B30,CEIC_DATA!$I$26:$N$353,Haver_M!BB$2,FALSE),NA()) -> 93.477945 | BC30: =IF(ISNUMBER(VLOOKUP($B30,CEIC_DATA!$I$26:$N$353,Haver_M!BC$2,FALSE)),VLOOKUP($B30,CEIC_DATA!$I$26:$N$353,Haver_M!BC$2,FALSE),NA()) -> #N/A | BD30: =IF(ISNUMBER(VLOOKUP($B30,CEIC_DATA!$I$26:$N$353,Haver_M!BD$2,FALSE)),VLOOKUP($B30,CEIC_DATA!$I$26:$N$353,Haver_M!BD$2,FALSE),NA()) -> #N/A | BE30: =IF(ISNUMBER(VLOOKUP($B30,CEIC_DATA!$I$26:$N$353,Haver_M!BE$2,FALSE)),VLOOKUP($B30,CEIC_DATA!$I$26:$N$353,Haver_M!BE$2,FALSE),NA()) -> #N/A | BF30: 391060 | BG30: 14987 | BH30: 493693 | BI30: 68609 | BJ30: #N/A | BK30: #N/A | BL30: #N/A | BM30: #N/A | BN30: 4253 | BO30: 4243 | BP30: 48.3287 | BQ30: =IF(ISNUMBER(BJ30),BJ30/$BP30,"") | BR30: =IF(ISNUMBER(BK30),BK30/$BP30,"") | BS30: =IF(ISNUMBER(BL30),BL30/$BP30,"") | BT30: =IF(ISNUMBER(BM30),BM30/$BP30,"") | BU30: 56426
A31: 0202 | B31: 37315 | C31: 8.5 | D31: 7.4725 | E31: 98.15047 | F31: 49.4 | G31: #N/A | H31: 48.46 | I31: 57.37 | J31: 26.9 | K31: 59.81 | L31: #N/A | M31: 28.53 | N31: 51.58 | O31: #N/A | P31: #N/A | Q31: #N/A | R31: #N/A | S31: #N/A | T31: #N/A | U31: #N/A | V31: #N/A | W31: #N/A | X31: 8216.0009 | Y31: 3569.87 | Z31: 4104.46 | AA31: #N/A | AB31: #N/A | AC31: #N/A | AD31: #N/A | AE31: 103.68668 | AF31: #N/A | AG31: #N/A | AH31: #N/A | AI31: #N/A | AJ31: #N/A | AK31: #N/A | AL31: #N/A | AM31: #N/A | AN31: #N/A | AO31: #N/A | AP31: #N/A | AQ31: #N/A | AR31: #N/A | AS31: #N/A | AT31: #N/A | AU31: #N/A | AV31: #N/A | AW31: #N/A | AX31: #N/A | AY31: #N/A | AZ31: #N/A | BA31: 3528.58 | BB31: =IF(ISNUMBER(VLOOKUP($B31,CEIC_DATA!$I$26:$N$353,Haver_M!BB$2,FALSE)),VLOOKUP($B31,CEIC_DATA!$I$26:$N$353,Haver_M!BB$2,FALSE),NA()) -> 93.8853 | BC31: =IF(ISNUMBER(VLOOKUP($B31,CEIC_DATA!$I$26:$N$353,Haver_M!BC$2,FALSE)),VLOOKUP($B31,CEIC_DATA!$I$26:$N$353,Haver_M!BC$2,FALSE),NA()) -> #N/A | BD31: =IF(ISNUMBER(VLOOKUP($B31,CEIC_DATA!$I$26:$N$353,Haver_M!BD$2,FALSE)),VLOOKUP($B31,CEIC_DATA!$I$26:$N$353,Haver_M!BD$2,FALSE),NA()) -> #N/A | BE31: =IF(ISNUMBER(VLOOKUP($B31,CEIC_DATA!$I$26:$N$353,Haver_M!BE$2,FALSE)),VLOOKUP($B31,CEIC_DATA!$I$26:$N$353,Haver_M!BE$2,FALSE),NA()) -> #N/A | BF31: 373003 | BG31: 15080 | BH31: 472336 | BI31: 65627 | BJ31: #N/A | BK31: #N/A | BL31: #N/A | BM31: #N/A | BN31: 3535 | BO31: 3759 | BP31: 48.6893 | BQ31: =IF(ISNUMBER(BJ31),BJ31/$BP31,"") | BR31: =IF(ISNUMBER(BK31),BK31/$BP31,"") | BS31: =IF(ISNUMBER(BL31),BL31/$BP31,"") | BT31: =IF(ISNUMBER(BM31),BM31/$BP31,"") | BU31: 54524
A32: 0203 | B32: 37346 | C32: 8 | D32: 7.3437 | E32: 97.70782 | F32: 49.8 | G32: #N/A | H32: 48.59 | I32: 57.44 | J32: 27.22 | K32: 58.66 | L32: #N/A | M32: 28.32 | N32: 52.87 | O32: #N/A | P32: #N/A | Q32: #N/A | R32: #N/A | S32: #N/A | T32: #N/A | U32: #N/A | V32: #N/A | W32: #N/A | X32: 8430.5678 | Y32: 3548.09 | Z32: 4129.8 | AA32: #N/A | AB32: #N/A | AC32: #N/A | AD32: #N/A | AE32: 75.320646 | AF32: #N/A | AG32: #N/A | AH32: #N/A | AI32: #N/A | AJ32: #N/A | AK32: #N/A | AL32: #N/A | AM32: #N/A | AN32: #N/A | AO32: #N/A | AP32: #N/A | AQ32: #N/A | AR32: #N/A | AS32: #N/A | AT32: #N/A | AU32: #N/A | AV32: #N/A | AW32: #N/A | AX32: #N/A | AY32: #N/A | AZ32: #N/A | BA32: 3580.73 | BB32: =IF(ISNUMBER(VLOOKUP($B32,CEIC_DATA!$I$26:$N$353,Haver_M!BB$2,FALSE)),VLOOKUP($B32,CEIC_DATA!$I$26:$N$353,Haver_M!BB$2,FALSE),NA()) -> 94.096981 | BC32: =IF(ISNUMBER(VLOOKUP($B32,CEIC_DATA!$I$26:$N$353,Haver_M!BC$2,FALSE)),VLOOKUP($B32,CEIC_DATA!$I$26:$N$353,Haver_M!BC$2,FALSE),NA()) -> 108.4 | BD32: =IF(ISNUMBER(VLOOKUP($B32,CEIC_DATA!$I$26:$N$353,Haver_M!BD$2,FALSE)),VLOOKUP($B32,CEIC_DATA!$I$26:$N$353,Haver_M!BD$2,FALSE),NA()) -> 105.3 | BE32: =IF(ISNUMBER(VLOOKUP($B32,CEIC_DATA!$I$26:$N$353,Haver_M!BE$2,FALSE)),VLOOKUP($B32,CEIC_DATA!$I$26:$N$353,Haver_M!BE$2,FALSE),NA()) -> 28.5 | BF32: 401274 | BG32: 21893 | BH32: 529126 | BI32: 84668 | BJ32: #N/A | BK32: #N/A | BL32: #N/A | BM32: #N/A | BN32: 4141 | BO32: 4433 | BP32: 48.7371 | BQ32: =IF(ISNUMBER(BJ32),BJ32/$BP32,"") | BR32: =IF(ISNUMBER(BK32),BK32/$BP32,"") | BS32: =IF(ISNUMBER(BL32),BL32/$BP32,"") | BT32: =IF(ISNUMBER(BM32),BM32/$BP32,"") | BU32: 51023
A33: 0204 | B33: 37376 | C33: 8 | D33: 7.3952 | E33: 96.44598 | F33: 50 | G33: #N/A | H33: 49.07 | I33: 58.21 | J33: 27.71 | K33: 60.01 | L33: #N/A | M33: 27.56 | N33: 53 | O33: #N/A | P33: #N/A | Q33: #N/A | R33: #N/A | S33: #N/A | T33: #N/A | U33: #N/A | V33: #N/A | W33: #N/A | X33: 8637.3255 | Y33: 4196.67 | Z33: 4324.17 | AA33: #N/A | AB33: #N/A | AC33: #N/A | AD33: #N/A | AE33: 69.959349 | AF33: #N/A | AG33: #N/A | AH33: #N/A | AI33: #N/A | AJ33: #N/A | AK33: #N/A | AL33: #N/A | AM33: #N/A | AN33: #N/A | AO33: #N/A | AP33: #N/A | AQ33: #N/A | AR33: #N/A | AS33: #N/A | AT33: #N/A | AU33: #N/A | AV33: #N/A | AW33: #N/A | AX33: #N/A | AY33: #N/A | AZ33: #N/A | BA33: 3435.13 | BB33: =IF(ISNUMBER(VLOOKUP($B33,CEIC_DATA!$I$26:$N$353,Haver_M!BB$2,FALSE)),VLOOKUP($B33,CEIC_DATA!$I$26:$N$353,Haver_M!BB$2,FALSE),NA()) -> 93.985893 | BC33: =IF(ISNUMBER(VLOOKUP($B33,CEIC_DATA!$I$26:$N$353,Haver_M!BC$2,FALSE)),VLOOKUP($B33,CEIC_DATA!$I$26:$N$353,Haver_M!BC$2,FALSE),NA()) -> #N/A | BD33: =IF(ISNUMBER(VLOOKUP($B33,CEIC_DATA!$I$26:$N$353,Haver_M!BD$2,FALSE)),VLOOKUP($B33,CEIC_DATA!$I$26:$N$353,Haver_M!BD$2,FALSE),NA()) -> #N/A | BE33: =IF(ISNUMBER(VLOOKUP($B33,CEIC_DATA!$I$26:$N$353,Haver_M!BE$2,FALSE)),VLOOKUP($B33,CEIC_DATA!$I$26:$N$353,Haver_M!BE$2,FALSE),NA()) -> #N/A | BF33: 394382 | BG33: 11965 | BH33: 473400 | BI33: 48351 | BJ33: #N/A | BK33: #N/A | BL33: #N/A | BM33: #N/A | BN33: 4035 | BO33: 4207 | BP33: 48.9183 | BQ33: =IF(ISNUMBER(BJ33),BJ33/$BP33,"") | BR33: =IF(ISNUMBER(BK33),BK33/$BP33,"") | BS33: =IF(ISNUMBER(BL33),BL33/$BP33,"") | BT33: =IF(ISNUMBER(BM33),BM33/$BP33,"") | BU33: 62547
... A56: 0403 | B56: 38077 | C56: 6 | D56: 5.1542 | E56: 95.01288 | F56: 54 | G56: #N/A | H56: 55.09 | I56: 63.75 | J56: 36.36 | K56: 66.21 | L56: #N/A | M56: 31.37 | N56: 59.67 | O56: #N/A | P56: #N/A | Q56: #N/A | R56: #N/A | S56: #N/A | T56: #N/A | U56: #N/A | V56: #N/A | W56: #N/A | X56: 9375.2288 | Y56: 6560.68 | Z56: 7564.6 | AA56: #N/A | AB56: #N/A | AC56: #N/A | AD56: #N/A | AE56: 27.892834 | AF56: #N/A | AG56: #N/A | AH56: #N/A | AI56: #N/A | AJ56: #N/A | AK56: #N/A | AL56: #N/A | AM56: #N/A | AN56: #N/A | AO56: #N/A | AP56: #N/A | AQ56: #N/A | AR56: #N/A | AS56: #N/A | AT56: #N/A | AU56: #N/A | AV56: #N/A | AW56: #N/A | AX56: #N/A | AY56: #N/A | AZ56: #N/A | BA56: 5612.92 | BB56: =IF(ISNUMBER(VLOOKUP($B56,CEIC_DATA!$I$26:$N$353,Haver_M!BB$2,FALSE)),VLOOKUP($B56,CEIC_DATA!$I$26:$N$353,Haver_M!BB$2,FALSE),NA()) -> 103.01402 | BC56: =IF(ISNUMBER(VLOOKUP($B56,CEIC_DATA!$I$26:$N$353,Haver_M!BC$2,FALSE)),VLOOKUP($B56,CEIC_DATA!$I$26:$N$353,Haver_M!BC$2,FALSE),NA()) -> 121.4 | BD56: =IF(ISNUMBER(VLOOKUP($B56,CEIC_DATA!$I$26:$N$353,Haver_M!BD$2,FALSE)),VLOOKUP($B56,CEIC_DATA!$I$26:$N$353,Haver_M!BD$2,FALSE),NA()) -> 122.2 | BE56: =IF(ISNUMBER(VLOOKUP($B56,CEIC_DATA!$I$26:$N$353,Haver_M!BE$2,FALSE)),VLOOKUP($B56,CEIC_DATA!$I$26:$N$353,Haver_M!BE$2,FALSE),NA()) -> 49 | BF56: 505972 | BG56: 33606 | BH56: 687884 | BI56: 115133 | BJ56: #N/A | BK56: #N/A | BL56: #N/A | BM56: #N/A | BN56: 7863 | BO56: 8034 | BP56: 45.0179 | BQ56: =IF(ISNUMBER(BJ56),BJ56/$BP56,"") | BR56: =IF(ISNUMBER(BK56),BK56/$BP56,"") | BS56: =IF(ISNUMBER(BL56),BL56/$BP56,"") | BT56: =IF(ISNUMBER(BM56),BM56/$BP56,"") | BU56: 20647
A57: 0404 | B57: 38107 | C57: 6 | D57: 5.1461 | E57: 98.13307 | F57: 54.2 | G57: #N/A | H57: 57.6 | I57: 64.21 | J57: 36.12 | K57: 72.62 | L57: #N/A | M57: 31.79 | N57: 61.9 | O57: 68.4 | P57: 69.961 | Q57: 88.808 | R57: 67.34 | S57: 77.878 | T57: 94.878 | U57: 53.828 | V57: 54.691 | W57: 66.228 | X57: 9389.9489 | Y57: 5912.58 | Z57: 7229.86 | AA57: #N/A | AB57: #N/A | AC57: #N/A | AD57: #N/A | AE57: 63.386356 | AF57: #N/A | AG57: #N/A | AH57: #N/A | AI57: #N/A | AJ57: #N/A | AK57: #N/A | AL57: #N/A | AM57: #N/A | AN57: #N/A | AO57: #N/A | AP57: #N/A | AQ57: #N/A | AR57: #N/A | AS57: #N/A | AT57: #N/A | AU57: #N/A | AV57: #N/A | AW57: #N/A | AX57: #N/A | AY57: #N/A | AZ57: #N/A | BA57: 5806.24 | BB57: =IF(ISNUMBER(VLOOKUP($B57,CEIC_DATA!$I$26:$N$353,Haver_M!BB$2,FALSE)),VLOOKUP($B57,CEIC_DATA!$I$26:$N$353,Haver_M!BB$2,FALSE),NA()) -> 100.49399 | BC57: =IF(ISNUMBER(VLOOKUP($B57,CEIC_DATA!$I$26:$N$353,Haver_M!BC$2,FALSE)),VLOOKUP($B57,CEIC_DATA!$I$26:$N$353,Haver_M!BC$2,FALSE),NA()) -> #N/A | BD57: =IF(ISNUMBER(VLOOKUP($B57,CEIC_DATA!$I$26:$N$353,Haver_M!BD$2,FALSE)),VLOOKUP($B57,CEIC_DATA!$I$26:$N$353,Haver_M!BD$2,FALSE),NA()) -> #N/A | BE57: =IF(ISNUMBER(VLOOKUP($B57,CEIC_DATA!$I$26:$N$353,Haver_M!BE$2,FALSE)),VLOOKUP($B57,CEIC_DATA!$I$26:$N$353,Haver_M!BE$2,FALSE),NA()) -> #N/A | BF57: 467834 | BG57: 21055 | BH57: 597610 | BI57: 82999 | BJ57: #N/A | BK57: #N/A | BL57: #N/A | BM57: #N/A | BN57: 5643 | BO57: 6987 | BP57: 43.9311 | BQ57: =IF(ISNUMBER(BJ57),BJ57/$BP57,"") | BR57: =IF(ISNUMBER(BK57),BK57/$BP57,"") | BS57: =IF(ISNUMBER(BL57),BL57/$BP57,"") | BT57: =IF(ISNUMBER(BM57),BM57/$BP57,"") | BU57: 32389
A58: 0405 | B58: 38138 | C58: 6 | D58: 5.3016 | E58: 96.01057 | F58: 54.6 | G58: #N/A | H58: 57.31 | I58: 63.23 | J58: 37.35 | K58: 70.5 | L58: #N/A | M58: 32.03 | N58: 62.47 | O58: 67.8 | P58: 66.488 | Q58: 89.065 | R58: 65.87 | S58: 78.308 | T58: 94.387 | U58: 57.314 | V58: 53.905 | W58: 63.202 | X58: 9210.2181 | Y58: 5963.27 | Z58: 7471.15 | AA58: #N/A | AB58: #N/A | AC58: #N/A | AD58: #N/A | AE58: 237.18243 | AF58: #N/A | AG58: #N/A | AH58: #N/A | AI58: #N/A | AJ58: #N/A | AK58: #N/A | AL58: #N/A | AM58: #N/A | AN58: #N/A | AO58: #N/A | AP58: #N/A | AQ58: #N/A | AR58: #N/A | AS58: #N/A | AT58: #N/A | AU58: #N/A | AV58: #N/A | AW58: #N/A | AX58: #N/A | AY58: #N/A | AZ58: #N/A | BA58: 5204.65 | BB58: =IF(ISNUMBER(VLOOKUP($B58,CEIC_DATA!$I$26:$N$353,Haver_M!BB$2,FALSE)),VLOOKUP($B58,CEIC_DATA!$I$26:$N$353,Haver_M!BB$2,FALSE),NA()) -> 97.78932 | BC58: =IF(ISNUMBER(VLOOKUP($B58,CEIC_DATA!$I$26:$N$353,Haver_M!BC$2,FALSE)),VLOOKUP($B58,CEIC_DATA!$I$26:$N$353,Haver_M!BC$2,FALSE),NA()) -> #N/A | BD58: =IF(ISNUMBER(VLOOKUP($B58,CEIC_DATA!$I$26:$N$353,Haver_M!BD$2,FALSE)),VLOOKUP($B58,CEIC_DATA!$I$26:$N$353,Haver_M!BD$2,FALSE),NA()) -> #N/A | BE58: =IF(ISNUMBER(VLOOKUP($B58,CEIC_DATA!$I$26:$N$353,Haver_M!BE$2,FALSE)),VLOOKUP($B58,CEIC_DATA!$I$26:$N$353,Haver_M!BE$2,FALSE),NA()) -> #N/A | BF58: 488541 | BG58: 25055 | BH58: 632123 | BI58: 92176 | BJ58: #N/A | BK58: #N/A | BL58: #N/A | BM58: #N/A | BN58: 5963 | BO58: 8073 | BP58: 45.2508 | BQ58: =IF(ISNUMBER(BJ58),BJ58/$BP58,"") | BR58: =IF(ISNUMBER(BK58),BK58/$BP58,"") | BS58: =IF(ISNUMBER(BL58),BL58/$BP58,"") | BT58: =IF(ISNUMBER(BM58),BM58/$BP58,"") | BU58: 32282
A59: 0406 | B59: 38168 | C59: 6 | D59: 5.8677 | E59: 94.83225 | F59: 55 | G59: #N/A | H59: 57.43 | I59: 63.67 | J59: 38.18 | K59: 71.48 | L59: #N/A | M59: 33.47 | N59: 62.42 | O59: 68.2 | P59: 70.015 | Q59: 88.932 | R59: 65.72 | S59: 76.438 | T59: 98.254 | U59: 57.04 | V59: 52.938 | W59: 64.325 | X59: 9201.7495 | Y59: 6244.49 | Z59: 8944.15 | AA59: #N/A | AB59: #N/A | AC59: #N/A | AD59: #N/A | AE59: 51.625346 | AF59: #N/A | AG59: #N/A | AH59: #N/A | AI59: #N/A | AJ59: #N/A | AK59: #N/A | AL59: #N/A | AM59: #N/A | AN59: #N/A | AO59: #N/A | AP59: #N/A | AQ59: #N/A | AR59: #N/A | AS59: #N/A | AT59: #N/A | AU59: #N/A | AV59: #N/A | AW59: #N/A | AX59: #N/A | AY59: #N/A | AZ59: #N/A | BA59: 4823.87 | BB59: =IF(ISNUMBER(VLOOKUP($B59,CEIC_DATA!$I$26:$N$353,Haver_M!BB$2,FALSE)),VLOOKUP($B59,CEIC_DATA!$I$26:$N$353,Haver_M!BB$2,FALSE),NA()) -> 95.78882 | BC59: =IF(ISNUMBER(VLOOKUP($B59,CEIC_DATA!$I$26:$N$353,Haver_M!BC$2,FALSE)),VLOOKUP($B59,CEIC_DATA!$I$26:$N$353,Haver_M!BC$2,FALSE),NA()) -> 118.4 | BD59: =IF(ISNUMBER(VLOOKUP($B59,CEIC_DATA!$I$26:$N$353,Haver_M!BD$2,FALSE)),VLOOKUP($B59,CEIC_DATA!$I$26:$N$353,Haver_M!BD$2,FALSE),NA()) -> 121.5 | BE59: =IF(ISNUMBER(VLOOKUP($B59,CEIC_DATA!$I$26:$N$353,Haver_M!BE$2,FALSE)),VLOOKUP($B59,CEIC_DATA!$I$26:$N$353,Haver_M!BE$2,FALSE),NA()) -> 47.9 | BF59: 505086 | BG59: 25887 | BH59: 658634 | BI59: 94928 | BJ59: #N/A | BK59: #N/A | BL59: #N/A | BM59: #N/A | BN59: 6068 | BO59: 8717 | BP59: 45.5068 | BQ59: =IF(ISNUMBER(BJ59),BJ59/$BP59,"") | BR59: =IF(ISNUMBER(BK59),BK59/$BP59,"") | BS59: =IF(ISNUMBER(BL59),BL59/$BP59,"") | BT59: =IF(ISNUMBER(BM59),BM59/$BP59,"") | BU59: 30556
