Workbook
Name _DLX1.USE: Haver_M!$A$2:$HG$5
Name _DLX2.USE: Haver_Q!$A$2:$CL$5
Name EdssBatchRange: #REF!

Sheet Haver_M
C1: RS | D1: LTY | E1: REER | F1: CPI | G1: CORE | H1: IPALL | I1: IPMINE | J1: IPUTIL | K1: IPCONST | L1: IPMANU | M1: UNR | N1: WAGE | O1: LEAD | P1: SALES_R | Q1: WHOLESALE | R1: EXPORTS | S1: IMPORTS | T1: COINCI | U1: CCI | V1: PCI | W1: PMI | X1: PMIManu | Y1: PMINO | Z1: PMIEMP | AA1: PMIDELI | AB1: PMIStocks | AC1: PMIIP | AD1: PMIPURCH | AE1: PMISTOCKS | AF1: PMINEO | AG1: PMIMPRI | AH1: PMIBACK | AI1: STOCKS | AJ1: PCONS | AK1: PCONS_D | AP1: EAI | AQ1: GFCF | AR1: TOURISM | AS1: OILPROD | AT1: OIL_X | AU1: IMEFBC | AV1: NEWS
A2: 10001 !M | B2: .excel_last | C2: N273RD@EMERGELA | D2: R273MA@EMERGELA | E2: N273XJCB@EMERGELA | F2: H273PJ@EMERGELA | G2: H273PJXQ@EMERGELA | H2: S273DW@EMERGELA | I2: S273DN@EMERGELA | J2: S273DV@EMERGELA | K2: S273DR@EMERGELA | L2: S273DM@EMERGELA | M2: H273EPAU@EMERGELA | N2: S273E9M@EMERGELA | O2: N273VLD@EMERGELA | P2: S273TRS@EMERGELA | Q2: S273TWS@EMERGELA | R2: S273TXD@EMERGELA | S2: S273TMD@EMERGELA | T2: N273VLC@EMERGELA | U2: S273VPCC@EMERGELA | V2: N273VCP@EMERGELA | W2: S273M@MKTPMI | X2: S273MG@MKTPMI | Y2: S273MO@MKTPMI | Z2: S273ME@MKTPMI | AA2: S273MD@MKTPMI | AB2: S273MSP@MKTPMI | AC2: S273MPI@MKTPMI | AD2: S273MQP@MKTPMI | AE2: S273MSF@MKTPMI | AF2: S273MX@MKTPMI | AG2: S273MPO@MKTPMI | AH2: S273MB@MKTPMI | AI2: C273KNV@EMERGELA | AJ2: S273NCPI@EMERGELA | AK2: S273NCVI@EMERGELA | AL2: S273NCUI@EMERGELA | AM2: S273NCSI@EMERGELA | AN2: S273NCMI@EMERGELA | AO2: N273TM@EMERGELA | AP2: S273GVI@EMERGELA | AQ2: S273NFI@EMERGELA | AR2: sa(N273TA55@EMERGELA) | AS2: H273IUQ@EMERGELA | AT2: C273TXUQ@EMERGELA | AU2: S273VMA@EMERGELA | AV2: sa(N273VIUC@EMERGELA) | AW2: S273VMNA@EMERGELA
A3: .DESC | C3: Mexico: Overnight Interbank Funding Rate: [Target Rate - Tasa objetivo] (EOP, %) | D3: Mexico: 10 Year Treasury Bond Mid Yield (% p.a.) | E3: Mexico: JPMorgan Real Broad Effective Exchange Rate Index, CPI Based (2010=100) | F3: Mexico: Consumer Price Index (SA, Jul 16-31, 2018=100) | G3: Mexico: Consumer Price Index: Core (SA, Jul 16-31, 2018=100) | H3: Mexico: Industrial Production (SA, 2013=100) | I3: Mexico: Industrial Production: Mining (SA, 2013=100) | J3: Mexico: Industrial Production: Utilities (SA, 2013=100) | K3: Mexico: Industrial Production: Construction (SA, 2013=100) | L3: Mexico: Industrial Production: Manufacturing (SA, 2013=100) | M3: Mexico: NES: Unemployed Population: Percent of Econ Active Pop (SA, %) | N3: Mexico: Avg Real Earnings Per Employee: Manufacturing (SA, 2013=100) | O3: Mexico: Leading Index (NSA, LT Avg=100) | P3: Mexico: Retail Sales Volume [Goods & Services] (SA, 2013=100) | Q3: Mexico: Wholesale Sales [Goods & Services] (SA, 2013=100) | R3: Mexico: Exports, fob (SA, Mil.US$) | S3: Mexico: Imports, fob (SA, Mil.US$) | T3: Mexico: Coincident Index (NSA, LT Avg=100) | U3: Mexico: Consumer Confidence (SA, 50+=Optimistic) | V3: Mexico: Producer Confidence Index (NSA, Points) | W3: Mexico PMI: Manufacturing (SA, 50+= Expansion) | X3: Mexico PMI: Manufacturing (SA, 50+= Expansion) | Y3: Mexico PMI: Manufacturing New Orders (SA, 50+= Expansion) | Z3: Mexico PMI: Manufacturing Employment (SA, 50+= Expansion) | AA3: Mexico PMI: Manufacturing Suppliers' Delivery Times (SA, 50+= Expansion) | AB3: Mexico PMI: Manufacturing Stocks of Purchases (SA, 50+= Expansion) | AC3: Mexico PMI: Manufacturing Input Prices (SA, 50+= Expansion) | AD3: Mexico PMI: Manufacturing Quantity of Purchases (SA, 50+= Expansion) | AE3: Mexico PMI: Manufacturing Stocks of Finished Goods (SA, 50+= Expansion) | AF3: Mexico PMI: Manufacturing New Export Orders (SA, 50+= Expansion) | AG3: Mexico PMI: Manufacturing Output Prices (SA, 50+= Expansion) | AH3: Mexico PMI: Manufacturing Backlogs of Work (SA, 50+= Expansion) | AI3: Mexico: Stock Price Index: IPC (Avg, 11/78=0.78) | AJ3: Mexico: Private Consumption in Domestic Market (SA, 2013=100) | AK3: Mexico: Private Consumption in Domestic Market, Total Domestic (SA, 2013=100) | AL3: Mexico: Private Consumption in Domestic Market, Domestic Goods (SA, 2013=100) | AM3: Mexico: Private Consumption in Domestic Market, Domestic Services (SA, 2013=100) | AN3: Mexico: Private Consumption in Domestic Market, Imported Goods (SA, 2013=100) | AO3: Mexico: Mfg Goods Sales: Manufacturing (NSA, Thous.Pesos) | AP3: Mexico: Economic Activity Indicator (SWDA, 2013=100) | AQ3: Mexico: Gross Fixed Capital Formation (SA, 2013=100) | AR3: Mexico: Inbound International Tourism Expenditure (NSA, Thous.US$) - Seasonal Adjustment, All | AS3: Mexico: Production of Crude Petroleum (SA, Thous.Bbls/Day) | AT3: Mexico: Petroleum Exports: Crude (Thous.Barrels/Day) | AU3: Mexico: IMEF Business Climate Index: Mfg Adj by Co Size (SA, 50+=Econ Expand) | AV3: Mexico: News Based Economic Policy Uncertainty Index (Jan 1996-Dec 2016=100) - Seasonal Adjustment, All | AW3: Mexico: IMEF Business Climate Index: Nonmfg Adj by Co Size (SA, 50+=Econ Expand)
A4: .T1 | C4: Jan-2008 | D4: Jan-2008 | E4: Jan-1970 | F4: Jan-1969 | G4: Jan-1982 | H4: Jan-1980 | I4: Jan-1980 | J4: Jan-1980 | K4: Jan-1980 | L4: Jan-1980 | M4: Apr-2000 | N4: Jan-2007 | O4: Jan-1980 | P4: Jan-1994 | Q4: Jan-2008 | R4: Jan-1980 | S4: Jan-1980 | T4: Jan-1980 | U4: Apr-2001 | V4: Jan-2004 | W4: Apr-2011 | X4: Apr-2011 | Y4: Apr-2011 | Z4: Apr-2011 | AA4: Apr-2011 | AB4: Apr-2011 | AC4: Apr-2011 | AD4: Apr-2011 | AE4: Apr-2011 | AF4: Apr-2011 | AG4: Apr-2011 | AH4: Apr-2011 | AI4: Jan-1980 | AJ4: Jan-1993 | AK4: Jan-1993 | AL4: Jan-1993 | AM4: Jan-1993 | AN4: Jan-1993 | AO4: Jan-2007 | AP4: Jan-1993 | AQ4: Jan-1993 | AR4: Jan-1980 | AS4: Jan-1984 | AT4: Jan-1980 | AU4: Jan-2005 | AV4: Jan-1996 | AW4: Jan-2005
A5: .TN | C5: Jun-2020 | D5: Jun-2020 | E5: Jun-2020 | F5: Jun-2020 | G5: Jun-2020 | H5: May-2020 | I5: May-2020 | J5: May-2020 | K5: May-2020 | L5: May-2020 | M5: May-2020 | N5: May-2020 | O5: May-2020 | P5: May-2020 | Q5: May-2020 | R5: Jun-2020 | S5: Jun-2020 | T5: Apr-2020 | U5: Mar-2020 | V5: Jun-2020 | W5: Jun-2020 | X5: Jun-2020 | Y5: Jun-2020 | Z5: Jun-2020 | AA5: Jun-2020 | AB5: Jun-2020 | AC5: Jun-2020 | AD5: Jun-2020 | AE5: Jun-2020 | AF5: Jun-2020 | AG5: Jun-2020 | AH5: Jun-2020 | AI5: Jun-2020 | AJ5: Apr-2020 | AK5: Apr-2020 | AL5: Apr-2020 | AM5: Apr-2020 | AN5: Apr-2020 | AO5: May-2020 | AP5: May-2020 | AQ5: Apr-2020 | AR5: May-2020 | AS5: May-2020 | AT5: May-2020 | AU5: Jun-2020 | AV5: May-2020 | AW5: Jun-2020
A6: 0001 | B6: 36556 | C6: #N/A | D6: #N/A | E6: 113.55455 | F6: 44.6533 | G6: 48.932 | H6: 89.3466 | I6: 101.1315 | J6: 53.8108 | K6: 85.3286 | L6: 89.9685 | M6: #N/A | N6: #N/A | O6: 101.39 | P6: 73.5288 | Q6: #N/A | R6: 13046 | S6: 13621.5 | T6: 101.2 | U6: #N/A | V6: #N/A | W6: #N/A | X6: #N/A | Y6: #N/A | Z6: #N/A | AA6: #N/A | AB6: #N/A | AC6: #N/A | AD6: #N/A | AE6: #N/A | AF6: #N/A | AG6: #N/A | AH6: #N/A | AI6: 7010.52 | AJ6: 75.869 | AK6: 79.911 | AL6: 89.059 | AM6: 70.937 | AN6: 36.914 | AO6: #N/A | AP6: 79.339849 | AQ6: 77.5 | AR6: 643302.84 | AS6: 2964 | AT6: 1517 | AU6: #N/A | AV6: 129.33691 | AW6: #N/A
A7: 0002 | B7: 36585 | C7: #N/A | D7: #N/A | E7: 115.46699 | F7: 44.999 | G7: 49.3 | H7: 89.9714 | I7: 99.6387 | J7: 54.6009 | K7: 86.2041 | L7: 90.6876 | M7: #N/A | N7: #N/A | O7: 101.49 | P7: 73.7749 | Q7: #N/A | R7: 13421.6 | S7: 13734.9 | T7: 101.34 | U7: #N/A | V7: #N/A | W7: #N/A | X7: #N/A | Y7: #N/A | Z7: #N/A | AA7: #N/A | AB7: #N/A | AC7: #N/A | AD7: #N/A | AE7: #N/A | AF7: #N/A | AG7: #N/A | AH7: #N/A | AI7: 7372.96 | AJ7: 75.635 | AK7: 79.688 | AL7: 88.186 | AM7: 71.219 | AN7: 39.045 | AO7: #N/A | AP7: 78.869914 | AQ7: 77.2 | AR7: 689953.4 | AS7: 2890 | AT7: 1531 | AU7: #N/A | AV7: 182.08916 | AW7: #N/A
A8: 0003 | B8: 36616 | C8: #N/A | D8: #N/A | E8: 117.33534 | F8: 45.3135 | G8: 49.5671 | H8: 89.9666 | I8: 101.1593 | J8: 55.207 | K8: 84.0667 | L8: 90.8005 | M8: #N/A | N8: #N/A | O8: 101.54 | P8: 71.9695 | Q8: #N/A | R8: 12899.9 | S8: 13380.6 | T8: 101.47 | U8: #N/A | V8: #N/A | W8: #N/A | X8: #N/A | Y8: #N/A | Z8: #N/A | AA8: #N/A | AB8: #N/A | AC8: #N/A | AD8: #N/A | AE8: #N/A | AF8: #N/A | AG8: #N/A | AH8: #N/A | AI8: 7958.76 | AJ8: 75.914 | AK8: 80.026 | AL8: 88.542 | AM8: 71.516 | AN8: 39.096 | AO8: #N/A | AP8: 78.657455 | AQ8: 74.6 | AR8: 692837.23 | AS8: 2956 | AT8: 1534 | AU8: #N/A | AV8: 119.76352 | AW8: #N/A
A9: 0004 | B9: 36646 | C9: #N/A | D9: #N/A | E9: 116.90303 | F9: 45.5985 | G9: 49.8246 | H9: 90.3034 | I9: 103.7515 | J9: 54.9528 | K9: 84.5754 | L9: 90.845 | M9: 2.77 | N9: #N/A | O9: 101.52 | P9: 75.7444 | Q9: #N/A | R9: 13176.4 | S9: 13844.5 | T9: 101.61 | U9: #N/A | V9: #N/A | W9: #N/A | X9: #N/A | Y9: #N/A | Z9: #N/A | AA9: #N/A | AB9: #N/A | AC9: #N/A | AD9: #N/A | AE9: #N/A | AF9: #N/A | AG9: #N/A | AH9: #N/A | AI9: 6918.29 | AJ9: 76.807 | AK9: 80.329 | AL9: 88.741 | AM9: 71.717 | AN9: 44.034 | AO9: #N/A | AP9: 79.397635 | AQ9: 77.4 | AR9: 654738.82 | AS9: 3053 | AT9: 1679 | AU9: #N/A | AV9: 108.51464 | AW9: #N/A
A10: 0005 | B10: 36677 | C10: #N/A | D10: #N/A | E10: 116.64526 | F10: 45.9655 | G10: 50.144 | H10: 91.1724 | I10: 103.1344 | J10: 55.1982 | K10: 85.5695 | L10: 91.6277 | M10: 2.72 | N10: #N/A | O10: 101.44 | P10: 76.8112 | Q10: #N/A | R10: 13561.4 | S10: 14366.8 | T10: 101.74 | U10: #N/A | V10: #N/A | W10: #N/A | X10: #N/A | Y10: #N/A | Z10: #N/A | AA10: #N/A | AB10: #N/A | AC10: #N/A | AD10: #N/A | AE10: #N/A | AF10: #N/A | AG10: #N/A | AH10: #N/A | AI10: 6067.96 | AJ10: 77.43 | AK10: 80.952 | AL10: 89.804 | AM10: 71.951 | AN10: 46.002 | AO10: #N/A | AP10: 79.856351 | AQ10: 77.5 | AR10: 676591.82 | AS10: 3044 | AT10: 1684 | AU10: #N/A | AV10: 149.59285 | AW10: #N/A
A11: 0006 | B11: 36707 | C11: #N/A | D11: #N/A | E11: 112.26979 | F11: 46.3367 | G11: 50.4345 | H11: 91.7436 | I11: 104.3887 | J11: 55.2032 | K11: 84.6837 | L11: 92.7064 | M11: 2.72 | N11: #N/A | O11: 101.34 | P11: 78.3705 | Q11: #N/A | R11: 13796 | S11: 14427.7 | T11: 101.87 | U11: #N/A | V11: #N/A | W11: #N/A | X11: #N/A | Y11: #N/A | Z11: #N/A | AA11: #N/A | AB11: #N/A | AC11: #N/A | AD11: #N/A | AE11: #N/A | AF11: #N/A | AG11: #N/A | AH11: #N/A | AI11: 6536.47 | AJ11: 77.992 | AK11: 81.209 | AL11: 90.169 | AM11: 72.097 | AN11: 49.692 | AO11: #N/A | AP11: 80.310105 | AQ11: 78.1 | AR11: 722413.11 | AS11: 3071 | AT11: 1685 | AU11: #N/A | AV11: 261.59393 | AW11: #N/A
A12: 0007 | B12: 36738 | C12: #N/A | D12: #N/A | E12: 117.72534 | F12: 46.6904 | G12: 50.7695 | H12: 91.4115 | I12: 96.7789 | J12: 54.6904 | K12: 83.3649 | L12: 96.4267 | M12: 2.39 | N12: #N/A | O12: 101.2 | P12: 78.6167 | Q12: #N/A | R12: 13930.7 | S12: 14899.4 | T12: 101.95 | U12: #N/A | V12: #N/A | W12: #N/A | X12: #N/A | Y12: #N/A | Z12: #N/A | AA12: #N/A | AB12: #N/A | AC12: #N/A | AD12: #N/A | AE12: #N/A | AF12: #N/A | AG12: #N/A | AH12: #N/A | AI12: 7063.39 | AJ12: 78.803 | AK12: 81.84 | AL12: 90.961 | AM12: 72.527 | AN12: 51.144 | AO12: #N/A | AP12: 80.417845 | AQ12: 77.9 | AR12: 695570.2 | AS12: 2844 | AT12: 1723 | AU12: #N/A | AV12: 144.08678 | AW12: #N/A
A13: 0008 | B13: 36769 | C13: #N/A | D13: #N/A | E13: 120.57772 | F13: 47.0132 | G13: 51.0742 | H13: 91.6441 | I13: 105.6175 | J13: 55.3312 | K13: 83.2526 | L13: 92.7329 | M13: 2.75 | N13: #N/A | O13: 101.01 | P13: 79.1911 | Q13: #N/A | R13: 14357.5 | S13: 15111.6 | T13: 101.99 | U13: #N/A | V13: #N/A | W13: #N/A | X13: #N/A | Y13: #N/A | Z13: #N/A | AA13: #N/A | AB13: #N/A | AC13: #N/A | AD13: #N/A | AE13: #N/A | AF13: #N/A | AG13: #N/A | AH13: #N/A | AI13: 6464.2 | AJ13: 78.075 | AK13: 81.526 | AL13: 90.201 | AM13: 72.563 | AN13: 47.797 | AO13: #N/A | AP13: 80.51353 | AQ13: 78.5 | AR13: 675626.05 | AS13: 3132 | AT13: 1756 | AU13: #N/A | AV13: 94.650131 | AW13: #N/A
A14: 0009 | B14: 36799 | C14: #N/A | D14: #N/A | E14: 120.15479 | F14: 47.2826 | G14: 51.3214 | H14: 91.508 | I14: 107.4547 | J14: 55.9557 | K14: 81.8831 | L14: 92.7816 | M14: 2.67 | N14: #N/A | O14: 100.78 | P14: 80.0938 | Q14: #N/A | R14: 14143.7 | S14: 15071.5 | T14: 101.98 | U14: #N/A | V14: #N/A | W14: #N/A | X14: #N/A | Y14: #N/A | Z14: #N/A | AA14: #N/A | AB14: #N/A | AC14: #N/A | AD14: #N/A | AE14: #N/A | AF14: #N/A | AG14: #N/A | AH14: #N/A | AI14: 6680.32 | AJ14: 78.997 | AK14: 81.93 | AL14: 90.581 | AM14: 73.171 | AN14: 51.529 | AO14: #N/A | AP14: 80.639012 | AQ14: 77.1 | AR14: 729377.6 | AS14: 3167 | AT14: 1720 | AU14: #N/A | AV14: 62.056772 | AW14: #N/A
A15: 0010 | B15: 36830 | C15: #N/A | D15: #N/A | E15: 119.1305 | F15: 47.6152 | G15: 51.6425 | H15: 90.6057 | I15: 99.7742 | J15: 56.1961 | K15: 82.128 | L15: 92.9708 | M15: 2.54 | N15: #N/A | O15: 100.49 | P15: 80.0118 | Q15: #N/A | R15: 14662.9 | S15: 15239 | T15: 101.92 | U15: #N/A | V15: #N/A | W15: #N/A | X15: #N/A | Y15: #N/A | Z15: #N/A | AA15: #N/A | AB15: #N/A | AC15: #N/A | AD15: #N/A | AE15: #N/A | AF15: #N/A | AG15: #N/A | AH15: #N/A | AI15: 6061.31 | AJ15: 79.864 | AK15: 83.003 | AL15: 92.47 | AM15: 73.157 | AN15: 52.543 | AO15: #N/A | AP15: 80.503439 | AQ15: 77.3 | AR15: 725220.49 | AS15: 2983 | AT15: 1549 | AU15: #N/A | AV15: 103.55553 | AW15: #N/A
A16: 0011 | B16: 36860 | C16: #N/A | D16: #N/A | E16: 120.55956 | F16: 47.8724 | G16: 52.0251 | H16: 89.7542 | I16: 102.3906 | J16: 56.7744 | K16: 80.4441 | L16: 91.4017 | M16: 2.32 | N16: #N/A | O16: 100.18 | P16: 78.8628 | Q16: #N/A | R16: 14474.3 | S16: 15215.5 | T16: 101.8 | U16: #N/A | V16: #N/A | W16: #N/A | X16: #N/A | Y16: #N/A | Z16: #N/A | AA16: #N/A | AB16: #N/A | AC16: #N/A | AD16: #N/A | AE16: #N/A | AF16: #N/A | AG16: #N/A | AH16: #N/A | AI16: 6125.42 | AJ16: 79.59 | AK16: 81.75 | AL16: 89.922 | AM16: 73.387 | AN16: 60.134 | AO16: #N/A | AP16: 80.239524 | AQ16: 76.1 | AR16: 732509.82 | AS16: 3006 | AT16: 1697 | AU16: #N/A | AV16: 174.553 | AW16: #N/A
A17: 0012 | B17: 36891 | C17: #N/A | D17: #N/A | E17: 121.8344 | F17: 48.2735 | G17: 52.3128 | H17: 88.622 | I17: 102.9357 | J17: 56.5097 | K17: 79.6392 | L17: 89.54 | M17: 2.6 | N17: #N/A | O17: 99.9 | P17: 78.6167 | Q17: #N/A | R17: 14552.2 | S17: 15425.6 | T17: 101.64 | U17: #N/A | V17: #N/A | W17: #N/A | X17: #N/A | Y17: #N/A | Z17: #N/A | AA17: #N/A | AB17: #N/A | AC17: #N/A | AD17: #N/A | AE17: #N/A | AF17: #N/A | AG17: #N/A | AH17: #N/A | AI17: 5601.73 | AJ17: 79.504 | AK17: 81.911 | AL17: 90.466 | AM17: 73.082 | AN17: 56.216 | AO17: #N/A | AP17: 79.790284 | AQ17: 74.5 | AR17: 684800.22 | AS17: 3023 | AT17: 1749 | AU17: #N/A | AV17: 88.497361 | AW17: #N/A
A18: 0101 | B18: 36922 | C18: #N/A | D18: #N/A | E18: 117.98875 | F18: 48.2937 | G18: 52.493 | H18: 89.9924 | I18: 103.8013 | J18: 56.3833 | K18: 78.4819 | L18: 92.7053 | M18: 2.56 | N18: #N/A | O18: 99.66 | P18: 80.5862 | Q18: #N/A | R18: 13864.3 | S18: 14668.1 | T18: 101.45 | U18: #N/A | V18: #N/A | W18: #N/A | X18: #N/A | Y18: #N/A | Z18: #N/A | AA18: #N/A | AB18: #N/A | AC18: #N/A | AD18: #N/A | AE18: #N/A | AF18: #N/A | AG18: #N/A | AH18: #N/A | AI18: 6118.06 | AJ18: 78.996 | AK18: 81.899 | AL18: 89.823 | AM18: 74.055 | AN18: 54.143 | AO18: #N/A | AP18: 79.773189 | AQ18: 73.4 | AR18: 725886.24 | AS18: 3017 | AT18: 1750 | AU18: #N/A | AV18: 123.11118 | AW18: #N/A
A19: 0102 | B19: 36950 | C19: #N/A | D19: #N/A | E19: 118.65244 | F19: 48.2383 | G19: 52.726 | H19: 89.5158 | I19: 107.1877 | J19: 56.8557 | K19: 77.0956 | L19: 91.2698 | M19: 3.15 | N19: #N/A | O19: 99.49 | P19: 80.2579 | Q19: #N/A | R19: 13631 | S19: 14363.3 | T19: 101.25 | U19: #N/A | V19: #N/A | W19: #N/A | X19: #N/A | Y19: #N/A | Z19: #N/A | AA19: #N/A | AB19: #N/A | AC19: #N/A | AD19: #N/A | AE19: #N/A | AF19: #N/A | AG19: #N/A | AH19: #N/A | AI19: 6276.83 | AJ19: 79.123 | AK19: 81.784 | AL19: 89.31 | AM19: 74.245 | AN19: 54.224 | AO19: #N/A | AP19: 79.570087 | AQ19: 72.5 | AR19: 723385.62 | AS19: 3137 | AT19: 1759 | AU19: #N/A | AV19: 103.7103 | AW19: #N/A
A20: 0103 | B20: 36981 | C20: #N/A | D20: #N/A | E20: 121.48672 | F20: 48.5948 | G20: 52.9991 | H20: 89.1202 | I20: 105.9494 | J20: 57.0714 | K20: 76.6878 | L20: 90.157 | M20: 2.66 | N20: #N/A | O20: 99.41 | P20: 80.9965 | Q20: #N/A | R20: 13987.5 | S20: 14776.7 | T20: 101.06 | U20: #N/A | V20: #N/A | W20: #N/A | X20: #N/A | Y20: #N/A | Z20: #N/A | AA20: #N/A | AB20: #N/A | AC20: #N/A | AD20: #N/A | AE20: #N/A | AF20: #N/A | AG20: #N/A | AH20: #N/A | AI20: 5926.31 | AJ20: 79.448 | AK20: 82.053 | AL20: 89.535 | AM20: 74.531 | AN20: 55.48 | AO20: #N/A | AP20: 79.525193 | AQ20: 71.2 | AR20: 728591.12 | AS20: 3122 | AT20: 1757 | AU20: #N/A | AV20: 120.51498 | AW20: #N/A
A21: 0104 | B21: 37011 | C21: #N/A | D21: #N/A | E21: 125.89816 | F21: 48.886 | G21: 53.2653 | H21: 87.0186 | I21: 102.5126 | J21: 57.7249 | K21: 73.4465 | L21: 89.5538 | M21: 2.7 | N21: #N/A | O21: 99.41 | P21: 79.3552 | Q21: #N/A | R21: 13782.2 | S21: 14722.7 | T21: 100.88 | U21: 46.9 | V21: #N/A | W21: #N/A | X21: #N/A | Y21: #N/A | Z21: #N/A | AA21: #N/A | AB21: #N/A | AC21: #N/A | AD21: #N/A | AE21: #N/A | AF21: #N/A | AG21: #N/A | AH21: #N/A | AI21: 5884.99 | AJ21: 79.203 | AK21: 82.21 | AL21: 89.77 | AM21: 74.362 | AN21: 51.584 | AO21: #N/A | AP21: 79.364557 | AQ21: 69.8 | AR21: 745852.66 | AS21: 3018 | AT21: 1716 | AU21: #N/A | AV21: 132.17547 | AW21: #N/A
A22: 0105 | B22: 37042 | C22: #N/A | D22: #N/A | E22: 128.21088 | F22: 49.2175 | G22: 53.5588 | H22: 88.1817 | I22: 102.2353 | J22: 57.4636 | K22: 75.1537 | L22: 90.2907 | M22: 2.79 | N22: #N/A | O22: 99.49 | P22: 79.6014 | Q22: #N/A | R22: 13153.3 | S22: 14034.9 | T22: 100.71 | U22: 44.4 | V22: #N/A | W22: #N/A | X22: #N/A | Y22: #N/A | Z22: #N/A | AA22: #N/A | AB22: #N/A | AC22: #N/A | AD22: #N/A | AE22: #N/A | AF22: #N/A | AG22: #N/A | AH22: #N/A | AI22: 6351.16 | AJ22: 79.227 | AK22: 82.155 | AL22: 89.733 | AM22: 74.376 | AN22: 53.341 | AO22: #N/A | AP22: 79.182549 | AQ22: 69.6 | AR22: 744680.72 | AS22: 3043 | AT22: 1719 | AU22: #N/A | AV22: 165.55541 | AW22: #N/A
A23: 0106 | B23: 37072 | C23: #N/A | D23: #N/A | E23: 129.65588 | F23: 49.4256 | G23: 53.8522 | H23: 88.5819 | I23: 105.7305 | J23: 58.0391 | K23: 76.1192 | L23: 89.4682 | M23: 2.75 | N23: #N/A | O23: 99.57 | P23: 79.8476 | Q23: #N/A | R23: 13360.1 | S23: 13983.2 | T23: 100.57 | U23: 44 | V23: #N/A | W23: #N/A | X23: #N/A | Y23: #N/A | Z23: #N/A | AA23: #N/A | AB23: #N/A | AC23: #N/A | AD23: #N/A | AE23: #N/A | AF23: #N/A | AG23: #N/A | AH23: #N/A | AI23: 6642.04 | AJ23: 80.569 | AK23: 83.3 | AL23: 91.774 | AM23: 74.659 | AN23: 55.313 | AO23: #N/A | AP23: 79.518017 | AQ23: 70.7 | AR23: 734358.78 | AS23: 3142 | AT23: 1716 | AU23: #N/A | AV23: 115.99765 | AW23: #N/A
A24: 0107 | B24: 37103 | C24: #N/A | D24: #N/A | E24: 128.51874 | F24: 49.4591 | G24: 54.0828 | H24: 89.2125 | I24: 106.2793 | J24: 57.5581 | K24: 78.8768 | L24: 89.0838 | M24: 2.77 | N24: #N/A | O24: 99.61 | P24: 79.1911 | Q24: #N/A | R24: 12794.8 | S24: 13532.5 | T24: 100.43 | U24: 46.1 | V24: #N/A | W24: #N/A | X24: #N/A | Y24: #N/A | Z24: #N/A | AA24: #N/A | AB24: #N/A | AC24: #N/A | AD24: #N/A | AE24: #N/A | AF24: #N/A | AG24: #N/A | AH24: #N/A | AI24: 6552.96 | AJ24: 79.39 | AK24: 82.258 | AL24: 89.494 | AM24: 74.749 | AN24: 53.263 | AO24: #N/A | AP24: 79.625331 | AQ24: 72.5 | AR24: 715506.87 | AS24: 3157 | AT24: 1711 | AU24: #N/A | AV24: 97.896514 | AW24: #N/A
A25: 0108 | B25: 37134 | C25: #N/A | D25: #N/A | E25: 128.89868 | F25: 49.7791 | G25: 54.3248 | H25: 88.8813 | I25: 105.8388 | J25: 59.0452 | K25: 79.0235 | L25: 88.5506 | M25: 2.27 | N25: #N/A | O25: 99.63 | P25: 79.7656 | Q25: #N/A | R25: 13049.5 | S25: 13691.3 | T25: 100.29 | U25: 47.4 | V25: #N/A | W25: #N/A | X25: #N/A | Y25: #N/A | Z25: #N/A | AA25: #N/A | AB25: #N/A | AC25: #N/A | AD25: #N/A | AE25: #N/A | AF25: #N/A | AG25: #N/A | AH25: #N/A | AI25: 6466.42 | AJ25: 79.983 | AK25: 82.755 | AL25: 90.667 | AM25: 74.743 | AN25: 55.675 | AO25: #N/A | AP25: 79.936959 | AQ25: 72 | AR25: 709838.95 | AS25: 3140 | AT25: 1648 | AU25: #N/A | AV25: 113.21612 | AW25: #N/A
A26: 0109 | B26: 37164 | C26: #N/A | D26: #N/A | E26: 125.62601 | F26: 50.1473 | G26: 54.5723 | H26: 88.8659 | I26: 106.7873 | J26: 58.8933 | K26: 78.2627 | L26: 88.8807 | M26: 2.53 | N26: #N/A | O26: 99.65 | P26: 80.5041 | Q26: #N/A | R26: 12984.4 | S26: 13768.8 | T26: 100.13 | U26: 44.7 | V26: #N/A | W26: #N/A | X26: #N/A | Y26: #N/A | Z26: #N/A | AA26: #N/A | AB26: #N/A | AC26: #N/A | AD26: #N/A | AE26: #N/A | AF26: #N/A | AG26: #N/A | AH26: #N/A | AI26: 5546.51 | AJ26: 80.283 | AK26: 82.963 | AL26: 91.326 | AM26: 74.514 | AN26: 55.267 | AO26: #N/A | AP26: 79.732419 | AQ26: 72.4 | AR26: 572489.08 | AS26: 3166 | AT26: 1648 | AU26: #N/A | AV26: 246.23597 | AW26: #N/A
A27: 0110 | B27: 37195 | C27: #N/A | D27: #N/A | E27: 127.92358 | F27: 50.3546 | G27: 54.7521 | H27: 86.7493 | I27: 103.8515 | J27: 59.4714 | K27: 76.0367 | L27: 87.0561 | M27: 2.92 | N27: #N/A | O27: 99.75 | P27: 79.6835 | Q27: #N/A | R27: 12825.1 | S27: 13721.4 | T27: 99.95 | U27: 42.3 | V27: #N/A | W27: #N/A | X27: #N/A | Y27: #N/A | Z27: #N/A | AA27: #N/A | AB27: #N/A | AC27: #N/A | AD27: #N/A | AE27: #N/A | AF27: #N/A | AG27: #N/A | AH27: #N/A | AI27: 5567.04 | AJ27: 80.043 | AK27: 82.841 | AL27: 91.205 | AM27: 74.257 | AN27: 55.412 | AO27: #N/A | AP27: 78.823013 | AQ27: 69.3 | AR27: 608237.91 | AS27: 3113 | AT27: 1734 | AU27: #N/A | AV27: 284.99277 | AW27: #N/A
A28: 0111 | B28: 37225 | C28: #N/A | D28: #N/A | E28: 130.33858 | F28: 50.3609 | G28: 54.9241 | H28: 88.3928 | I28: 108.2167 | J28: 60.1631 | K28: 76.7226 | L28: 87.457 | M28: 2.93 | N28: #N/A | O28: 99.91 | P28: 79.9297 | Q28: #N/A | R28: 12544.6 | S28: 13468 | T28: 99.79 | U28: 42.8 | V28: #N/A | W28: #N/A | X28: #N/A | Y28: #N/A | Z28: #N/A | AA28: #N/A | AB28: #N/A | AC28: #N/A | AD28: #N/A | AE28: #N/A | AF28: #N/A | AG28: #N/A | AH28: #N/A | AI28: 5707.32 | AJ28: 80.088 | AK28: 82.736 | AL28: 91.068 | AM28: 74.263 | AN28: 56.808 | AO28: #N/A | AP28: 79.396361 | AQ28: 71.3 | AR28: 665944.53 | AS28: 3213 | AT28: 1682 | AU28: #N/A | AV28: 190.50982 | AW28: #N/A
A29: 0112 | B29: 37256 | C29: #N/A | D29: #N/A | E29: 131.60927 | F29: 50.3568 | G29: 55.0658 | H29: 88.454 | I29: 109.0177 | J29: 60.4354 | K29: 78.331 | L29: 86.7558 | M29: 3.07 | N29: #N/A | O29: 100.1 | P29: 79.5194 | Q29: #N/A | R29: 12930.8 | S29: 13602.3 | T29: 99.64 | U29: 42.7 | V29: #N/A | W29: #N/A | X29: #N/A | Y29: #N/A | Z29: #N/A | AA29: #N/A | AB29: #N/A | AC29: #N/A | AD29: #N/A | AE29: #N/A | AF29: #N/A | AG29: #N/A | AH29: #N/A | AI29: 6214.49 | AJ29: 80.615 | AK29: 82.918 | AL29: 91.293 | AM29: 74.259 | AN29: 58.127 | AO29: #N/A | AP29: 79.326697 | AQ29: 72.3 | AR29: 669154.73 | AS29: 3243 | AT29: 1685 | AU29: #N/A | AV29: 221.31069 | AW29: #N/A
A30: 0201 | B30: 37287 | C30: #N/A | D30: #N/A | E30: 133.14067 | F30: 50.64 | G30: 55.1898 | H30: 86.7948 | I30: 106.2968 | J30: 56.7137 | K30: 74.2768 | L30: 86.8879 | M30: 3.42 | N30: #N/A | O30: 100.26 | P30: 79.3552 | Q30: #N/A | R30: 12757.2 | S30: 13146.5 | T30: 99.52 | U30: 36.8 | V30: #N/A | W30: #N/A | X30: #N/A | Y30: #N/A | Z30: #N/A | AA30: #N/A | AB30: #N/A | AC30: #N/A | AD30: #N/A | AE30: #N/A | AF30: #N/A | AG30: #N/A | AH30: #N/A | AI30: 6633.51 | AJ30: 79.621 | AK30: 82.66 | AL30: 91.073 | AM30: 74.161 | AN30: 54.924 | AO30: #N/A | AP30: 77.93077 | AQ30: 68.5 | AR30: 694656.74 | AS30: 3189 | AT30: 1793 | AU30: #N/A | AV30: 165.2789 | AW30: #N/A
A31: 0202 | B31: 37315 | C31: #N/A | D31: #N/A | E31: 134.08656 | F31: 50.6002 | G31: 55.4317 | H31: 86.156 | I31: 106.0989 | J31: 57.167 | K31: 74.2369 | L31: 86.3616 | M31: 2.97 | N31: #N/A | O31: 100.35 | P31: 79.6014 | Q31: #N/A | R31: 12968 | S31: 13765.6 | T31: 99.45 | U31: 38.3 | V31: #N/A | W31: #N/A | X31: #N/A | Y31: #N/A | Z31: #N/A | AA31: #N/A | AB31: #N/A | AC31: #N/A | AD31: #N/A | AE31: #N/A | AF31: #N/A | AG31: #N/A | AH31: #N/A | AI31: 6685.32 | AJ31: 79.697 | AK31: 82.434 | AL31: 91.082 | AM31: 73.828 | AN31: 54.226 | AO31: #N/A | AP31: 78.493449 | AQ31: 69.8 | AR31: 685134.11 | AS31: 3143 | AT31: 1714 | AU31: #N/A | AV31: 132.92212 | AW31: #N/A
A32: 0203 | B32: 37346 | C32: #N/A | D32: #N/A | E32: 134.75093 | F32: 50.8282 | G32: 55.5789 | H32: 86.2015 | I32: 104.2174 | J32: 57.0083 | K32: 70.4627 | L32: 87.5605 | M32: 3.02 | N32: #N/A | O32: 100.35 | P32: 79.5194 | Q32: #N/A | R32: 13240.3 | S32: 14250.7 | T32: 99.42 | U32: 39.5 | V32: #N/A | W32: #N/A | X32: #N/A | Y32: #N/A | Z32: #N/A | AA32: #N/A | AB32: #N/A | AC32: #N/A | AD32: #N/A | AE32: #N/A | AF32: #N/A | AG32: #N/A | AH32: #N/A | AI32: 7233.28 | AJ32: 80.857 | AK32: 83.426 | AL32: 92.811 | AM32: 74.204 | AN32: 57.206 | AO32: #N/A | AP32: 78.826568 | AQ32: 67.4 | AR32: 739576.84 | AS32: 3113 | AT32: 1699 | AU32: #N/A | AV32: 137.79895 | AW32: #N/A
... A53: 0312 | B53: 37986 | C53: #N/A | D53: #N/A | E53: 107.20342 | F53: 55.2661 | G53: 59.4819 | H53: 90.5486 | I53: 113.2776 | J53: 61.4197 | K53: 79.09 | L53: 87.7296 | M53: 3.36 | N53: #N/A | O53: 100.12 | P53: 85.0177 | Q53: #N/A | R53: 14662.7 | S53: 15009.2 | T53: 98.68 | U53: 39 | V53: #N/A | W53: #N/A | X53: #N/A | Y53: #N/A | Z53: #N/A | AA53: #N/A | AB53: #N/A | AC53: #N/A | AD53: #N/A | AE53: #N/A | AF53: #N/A | AG53: #N/A | AH53: #N/A | AI53: 8546.41 | AJ53: 85.32 | AK53: 87.353 | AL53: 95.167 | AM53: 79.154 | AN53: 63.534 | AO53: #N/A | AP53: 81.713458 | AQ53: 71 | AR53: 824793.48 | AS53: 3417 | AT53: 2141 | AU53: #N/A | AV53: 221.73944 | AW53: #N/A
A54: 0401 | B54: 38017 | C54: #N/A | D54: #N/A | E54: 110.05424 | F54: 55.523 | G54: 59.6376 | H54: 91.0236 | I54: 112.8947 | J54: 65.2599 | K54: 85.6989 | L54: 87.1305 | M54: 3.81 | N54: #N/A | O54: 100.2 | P54: 85.1817 | Q54: #N/A | R54: 14676.1 | S54: 14719 | T54: 98.8 | U54: 39.5 | V54: 99.02 | W54: #N/A | X54: #N/A | Y54: #N/A | Z54: #N/A | AA54: #N/A | AB54: #N/A | AC54: #N/A | AD54: #N/A | AE54: #N/A | AF54: #N/A | AG54: #N/A | AH54: #N/A | AI54: 9267.79 | AJ54: 83.436 | AK54: 86.602 | AL54: 93.871 | AM54: 79.123 | AN54: 57.276 | AO54: #N/A | AP54: 82.175198 | AQ54: 75.2 | AR54: 843411.59 | AS54: 3387 | AT54: 1897 | AU54: #N/A | AV54: 99.450043 | AW54: #N/A
A55: 0402 | B55: 38046 | C55: #N/A | D55: #N/A | E55: 109.61216 | F55: 55.859 | G55: 59.8034 | H55: 90.8923 | I55: 112.5663 | J55: 65.5862 | K55: 82.4612 | L55: 87.4015 | M55: 3.98 | N55: #N/A | O55: 100.25 | P55: 85.1817 | Q55: #N/A | R55: 14822.2 | S55: 15436.3 | T55: 98.91 | U55: 40 | V55: 99.11 | W55: #N/A | X55: #N/A | Y55: #N/A | Z55: #N/A | AA55: #N/A | AB55: #N/A | AC55: #N/A | AD55: #N/A | AE55: #N/A | AF55: #N/A | AG55: #N/A | AH55: #N/A | AI55: 9897.86 | AJ55: 84.782 | AK55: 87.262 | AL55: 95.277 | AM55: 79.196 | AN55: 63.156 | AO55: #N/A | AP55: 82.483083 | AQ55: 73.3 | AR55: 877687.7 | AS55: 3367 | AT55: 1752 | AU55: #N/A | AV55: 103.41336 | AW55: #N/A
A56: 0403 | B56: 38077 | C56: #N/A | D56: #N/A | E56: 110.33435 | F56: 56.0447 | G56: 59.9896 | H56: 92.234 | I56: 112.233 | J56: 67.3091 | K56: 83.6237 | L56: 89.5256 | M56: 3.95 | N56: #N/A | O56: 100.24 | P56: 87.1513 | Q56: #N/A | R56: 15204.5 | S56: 15662.9 | T56: 99.02 | U56: 39.1 | V56: 99.21 | W56: #N/A | X56: #N/A | Y56: #N/A | Z56: #N/A | AA56: #N/A | AB56: #N/A | AC56: #N/A | AD56: #N/A | AE56: #N/A | AF56: #N/A | AG56: #N/A | AH56: #N/A | AI56: 10104.65 | AJ56: 86.26 | AK56: 88.325 | AL56: 96.96 | AM56: 79.588 | AN56: 66.785 | AO56: #N/A | AP56: 83.43584 | AQ56: 74.6 | AR56: 847649.37 | AS56: 3385 | AT56: 1789 | AU56: #N/A | AV56: 102.82116 | AW56: #N/A
A57: 0404 | B57: 38107 | C57: #N/A | D57: #N/A | E57: 107.86164 | F57: 56.1758 | G57: 60.2041 | H57: 92.2939 | I57: 114.2347 | J57: 66.6832 | K57: 83.991 | L57: 89.0112 | M57: 3.96 | N57: #N/A | O57: 100.21 | P57: 87.7257 | Q57: #N/A | R57: 15043.2 | S57: 15752.4 | T57: 99.1 | U57: 39.9 | V57: 99.35 | W57: #N/A | X57: #N/A | Y57: #N/A | Z57: #N/A | AA57: #N/A | AB57: #N/A | AC57: #N/A | AD57: #N/A | AE57: #N/A | AF57: #N/A | AG57: #N/A | AH57: #N/A | AI57: 10580.25 | AJ57: 85.597 | AK57: 87.822 | AL57: 95.547 | AM57: 79.929 | AN57: 66.266 | AO57: #N/A | AP57: 83.253844 | AQ57: 75.9 | AR57: 877004.86 | AS57: 3419 | AT57: 1766 | AU57: #N/A | AV57: 89.289902 | AW57: #N/A
A58: 0405 | B58: 38138 | C58: #N/A | D58: #N/A | E58: 105.60213 | F58: 56.3759 | G58: 60.4125 | H58: 92.0734 | I58: 112.9062 | J58: 66.1061 | K58: 83.1413 | L58: 89.0902 | M58: 3.85 | N58: #N/A | O58: 100.14 | P58: 88.7105 | Q58: #N/A | R58: 16039 | S58: 16545.2 | T58: 99.17 | U58: 40.5 | V58: 99.48 | W58: #N/A | X58: #N/A | Y58: #N/A | Z58: #N/A | AA58: #N/A | AB58: #N/A | AC58: #N/A | AD58: #N/A | AE58: #N/A | AF58: #N/A | AG58: #N/A | AH58: #N/A | AI58: 9882.5 | AJ58: 86.214 | AK58: 88.067 | AL58: 96.168 | AM58: 79.928 | AN58: 69.377 | AO58: #N/A | AP58: 83.805945 | AQ58: 75.6 | AR58: 879905.3 | AS58: 3399 | AT58: 1967 | AU58: #N/A | AV58: 127.32442 | AW58: #N/A
A59: 0406 | B59: 38168 | C59: #N/A | D59: #N/A | E59: 106.28859 | F59: 56.5879 | G59: 60.6345 | H59: 92.2275 | I59: 113.7036 | J59: 66.4504 | K59: 83.3064 | L59: 89.0239 | M59: 3.93 | N59: #N/A | O59: 100.06 | P59: 87.9719 | Q59: #N/A | R59: 15502.3 | S59: 16288.8 | T59: 99.2 | U59: 40.8 | V59: 99.6 | W59: #N/A | X59: #N/A | Y59: #N/A | Z59: #N/A | AA59: #N/A | AB59: #N/A | AC59: #N/A | AD59: #N/A | AE59: #N/A | AF59: #N/A | AG59: #N/A | AH59: #N/A | AI59: 10161.72 | AJ59: 86.721 | AK59: 88.674 | AL59: 96.698 | AM59: 80.364 | AN59: 67.433 | AO59: #N/A | AP59: 83.627714 | AQ59: 75.6 | AR59: 867285.34 | AS59: 3395 | AT59: 1846 | AU59: #N/A | AV59: 80.301644 | AW59: #N/A
A60: 0407 | B60: 38199 | C60: #N/A | D60: #N/A | E60: 105.45391 | F60: 56.8084 | G60: 60.8206 | H60: 91.831 | I60: 111.2628 | J60: 66.7924 | K60: 82.8433 | L60: 89.6807 | M60: 3.82 | N60: #N/A | O60: 99.99 | P60: 89.367 | Q60: #N/A | R60: 15657.8 | S60: 16533 | T60: 99.24 | U60: 39.6 | V60: 99.69 | W60: #N/A | X60: #N/A | Y60: #N/A | Z60: #N/A | AA60: #N/A | AB60: #N/A | AC60: #N/A | AD60: #N/A | AE60: #N/A | AF60: #N/A | AG60: #N/A | AH60: #N/A | AI60: 10036.76 | AJ60: 87.153 | AK60: 89.254 | AL60: 97.401 | AM60: 81.009 | AN60: 68.295 | AO60: #N/A | AP60: 83.213987 | AQ60: 75.6 | AR60: 884296.7 | AS60: 3373 | AT60: 1805 | AU60: #N/A | AV60: 93.797958 | AW60: #N/A
...

Sheet Haver_Q
C1: GDP | E1: GDPGOVT | F1: GDPPRIV | H1: GDPGFCF | I1: GDPX | J1: GDPM | K1: GPMGDP
A2: 1001 !Q | B2: .excel_last | C2: difa%(S273NGPC@EMERGELA) | D2: difa%(S273NCC@EMERGELA) | E2: difa%(S273NCGC@EMERGELA) | F2: difa%(S273NCPC@EMERGELA) | G2: difa%(S273NBC@EMERGELA) | H2: difa%(S273NFC@EMERGELA) | I2: difa%(S273NXC@EMERGELA) | J2: difa%(S273NMC@EMERGELA)
A3: .DESC | C3: Mexico: Gross Domestic Product, Market Prices (SAAR, 2013.NewPesos) % Change - Annual Rate | D3: Mexico: GDP: Total Consumption (SAAR, 2013.NewPesos) % Change - Annual Rate | E3: Mexico: GDP: Government Consumption (SAAR, 2013.NewPesos) % Change - Annual Rate | F3: Mexico: GDP: Private Consumption (SAAR, 2013.NewPesos) % Change - Annual Rate | G3: Mexico: GDP: Change in Inventories (SAAR, 2013.NewPesos) % Change - Annual Rate | H3: Mexico: GDP: Gross Fixed Capital Formation (SAAR, 2013.NewPesos) % Change - Annual Rate | I3: Mexico: GDP: Exports of Goods and Services (SAAR, 2013.NewPesos) % Change - Annual Rate | J3: Mexico: GDP: Imports of Goods and Services (SAAR, 2013.NewPesos) % Change - Annual Rate
A4: .T1 | C4: Q1-1980 | D4: Q1-1993 | E4: Q1-1993 | F4: Q1-1993 | G4: Q1-1993 | H4: Q1-1993 | I4: Q1-1993 | J4: Q1-1993
A5: .TN | C5: Q1-2020 | D5: Q1-2020 | E5: Q1-2020 | F5: Q1-2020 | G5: Q1-2020 | H5: Q1-2020 | I5: Q1-2020 | J5: Q1-2020
A6: 001 | B6: 36616 | C6: 0.078908208 | D6: 0.096133268 | E6: 0.12149992 | F6: 0.096004588 | G6: 0.044602791 | H6: 0.14079916 | I6: 0.17042392 | J6: 0.2754633 | K6: 5.3384295
A7: 002 | B7: 36707 | C7: 0.062703483 | D7: 0.073046384 | E7: -0.020346867 | F7: 0.088398814 | G7: 0.036853635 | H7: 0.057696005 | I7: 0.12937207 | J7: 0.12211141 | K7: 5.031488
A8: 003 | B8: 36799 | C8: 0.031479804 | D8: 0.060657067 | E8: 0.0026588307 | F8: 0.072302863 | G8: -0.61591445 | H8: -0.016482029 | I8: 0.12589966 | J8: 0.30634637 | K8: 3.1388242
A9: 004 | B9: 36891 | C9: -0.026232726 | D9: 0.033403463 | E9: -0.02427157 | F9: 0.044443038 | G9: -0.69108115 | H9: -0.091565594 | I9: 0.054053264 | J9: 0.037157616 | K9: 2.831619
A10: 011 | B10: 36981 | C10: 0.002761665 | D10: -0.016846107 | E10: -0.09129194 | F10: 0.0020262783 | G10: 1.5981973 | H10: -0.15457791 | I10: -0.062618244 | J10: -0.0897092 | K10: 1.8286258
A11: 012 | B11: 37072 | C11: -0.021975885 | D11: 0.0064594971 | E11: -0.0071002921 | F11: 0.0059673562 | G11: -0.67361092 | H11: -0.1251323 | I11: -0.018460077 | J11: -0.08156603 | K11: 1.9835864
A12: 013 | B12: 37164 | C12: 0.0010251254 | D12: 0.014354559 | E12: 0.026648864 | F12: 0.010978292 | G12: -0.17817914 | H12: 0.09574572 | I12: -0.11416183 | J12: -0.08425753 | K12: 0.88840616
A13: 014 | B13: 37256 | C13: -0.018571058 | D13: 0.02415084 | E13: -0.0012273665 | F13: 0.029383994 | G13: -0.74355978 | H13: -0.049084195 | I13: -0.033634967 | J13: 0.01754401 | K13: 1.8425459
A14: 021 | B14: 37346 | C14: -0.02622608 | D14: 0.0060969934 | E14: -0.0027802238 | F14: 0.010964823 | G14: -0.76102295 | H14: -0.10533267 | I14: 0.04046553 | J14: 0.084662852 | K14: 3.3692314
A15: 022 | B15: 37437 | C15: 0.036368636 | D15: 0.033474102 | E15: -0.01860815 | F15: 0.040853518 | G15: 136.15934 | H15: 0.034664389 | I15: 0.056535939 | J15: 0.10651387 | K15: 4.3446296
A16: 023 | B16: 37529 | C16: 0.027976816 | D16: 0.011859253 | E16: 0.049431331 | F16: 0.0036862307 | G16: 1.3022546 | H16: 0.049917225 | I16: 0.049356051 | J16: 0.010177188 | K16: 3.4716421
A17: 024 | B17: 37621 | C17: 0.01253326 | D17: -0.018626536 | E17: -0.015509685 | F17: -0.017693341 | G17: -0.75578781 | H17: -0.0050157728 | I17: 0.0069513695 | J17: -0.22869353 | K17: 2.4451578
... A85: 194 | B85: 43830 | C85: -0.022543674 | D85: -0.0074105785 | E85: 0.028018082 | F85: -0.015155554 | G85: -0.44635392 | H85: -0.065926735 | I85: -0.14793567 | J85: -0.10175143 | K85: 2.6073257
A86: 201 | B86: 43921 | C86: -0.048722731 | D86: -0.029057321 | E86: 0.13430904 | F86: -0.056732311 | G86: -0.98890473 | H86: -0.083393377 | I86: 0.13026239 | J86: -0.073409822
A87: 202 | B87: 44012

Sheet Bloomberg_m
C1: BALTIC | D1: WCIFREIGHT | E1: SHANGHAI | F1: RUSSELL | L1: WTI
C2: BDI Baltic Exchange Dry Index | D2: WCI Composite Container Freight Benchmark Rate per 40 Foot Box | E2: Shanghai Shipping Exchange Shanghai (Export) Containerized Freight Index | F2: Russell 3000 Shipping Index | G2: Shanghai Shipping Exchange China (Export) Containerized Freight Index | H2: Dow Jones Global Shipping USD Index | I2: Philadelphia Stock Exchange Marine Shipping Index | J2: RGUSPSSH Index | K2: Oslo Shipping Index | L2: WTI Price
A3: 0 | B3: Security | C3: BDIY Index | D3: WCIDCOMP Index | E3: SHSPSCFI Index | F3: RGUSPSH Index | G3: SHSPCCFI Index | H3: DJGSH Index | I3: PHLXSHX Index | J3: RGUSPSSH Index | K3: OSLSHX Index | L3: USCRWTIC Index
A4: 2 | B4: Fields | C4: px_last | D4: =C4 -> px_last | E4: =D4 -> px_last | F4: =E4 -> px_last | G4: =F4 -> px_last | H4: =G4 -> px_last | I4: =H4 -> px_last | J4: =I4 -> px_last | K4: =J4 -> px_last | L4: =K4 -> px_last
A5: 3 | B5: Start Date | C5: 36523 | D5: =$C$5 -> 36523 | E5: =$C$5 -> 36523 | F5: =$C$5 -> 36523 | G5: =$C$5 -> 36523 | H5: =$C$5 -> 36523 | I5: =$C$5 -> 36523 | J5: =$C$5 -> 36523 | K5: =$C$5 -> 36523 | L5: =$C$5 -> 36523
A6: 4 | B6: End Date
A7: D,W,M,Q,S,Y | B7: Per= | C7: m | D7: =$C$7 -> m | E7: =$C$7 -> m | F7: =$C$7 -> m | G7: =$C$7 -> m | H7: =$C$7 -> m | I7: =$C$7 -> m | J7: =$C$7 -> m | K7: =$C$7 -> m | L7: =$C$7 -> m
A8: N,C,T,W,A | B8: Days= | C8: N | D8: =$C$8 -> N | E8: =$C$8 -> N | F8: =$C$8 -> N | G8: =$C$8 -> N | H8: =$C$8 -> N | I8: =$C$8 -> N | J8: =$C$8 -> N | K8: =$C$8 -> N | L8: =$C$8 -> N
A9: C,P,E,B | B9: Fill= | C9: B | D9: =$C$9 -> B | E9: =$C$9 -> B | F9: =$C$9 -> B | G9: =$C$9 -> B | H9: =$C$9 -> B | I9: =$C$9 -> B | J9: =$C$9 -> B | K9: =$C$9 -> B | L9: =$C$9 -> B
A10: TRUE,FALSE | B10: Dts= | C10: TRUE | D10: FALSE | E10: FALSE | F10: FALSE | G10: FALSE | H10: FALSE | I10: FALSE | J10: FALSE | K10: FALSE | L10: FALSE
A11: P,Y | B11: QtTyp=
A12: C,A,R,D | B12: Sort=
A13: USD | B13: Curr=
A14: G=Avg C=Last | B14: Quote= | C14: G | D14: =$C$14 -> G | E14: =$C$14 -> G | F14: =$C$14 -> G | G14: =$C$14 -> G | H14: =$C$14 -> G | I14: =$C$14 -> G | J14: =$C$14 -> G | K14: =$C$14 -> G | L14: =$C$14 -> G
A15: Units | C15: =_xll.BDP(C3,"indx_units") -> #N/A Connection | D15: =_xll.BDP(D3,"indx_units") -> #N/A Connection | E15: =_xll.BDP(E3,"indx_units") -> #N/A Connection | F15: =_xll.BDP(F3,"indx_units") -> #N/A Connection | G15: =_xll.BDP(G3,"indx_units") -> #N/A Connection | H15: =_xll.BDP(H3,"indx_units") -> #N/A Connection | I15: =_xll.BDP(I3,"indx_units") -> #N/A Connection | J15: =_xll.BDP(J3,"indx_units") -> #N/A Connection | ... L15: =_xll.BDP(L3,"indx_units") -> #N/A Connection
A16: Bloomberg Description | C16: =_xll.BDP(C3,"long_comp_name") -> #N/A Connection | D16: =_xll.BDP(D3,"long_comp_name") -> #N/A Connection | E16: =_xll.BDP(E3,"long_comp_name") -> #N/A Connection | F16: =_xll.BDP(F3,"long_comp_name") -> #N/A Connection | G16: =_xll.BDP(G3,"long_comp_name") -> #N/A Connection | H16: =_xll.BDP(H3,"long_comp_name") -> #N/A Connection | I16: =_xll.BDP(I3,"long_comp_name") -> #N/A Connection | J16: =_xll.BDP(J3,"long_comp_name") -> #N/A Connection | ... L16: =_xll.BDP(L3,"long_comp_name") -> #N/A Connection
B17: =_xll.BDH(C3,C4,C5,C6,$B$7&C7,$B$8&C8,$B$9&C9,$B$10&C10,$B$11&C11,$B$12&C12,$B$13&C13,$B$14&C14,"cols=2;rows=247") -> 36525 | C17: 1343 | D17: =_xll.BDH(D3,D4,D5,D6,$B$7&D7,$B$8&D8,$B$9&D9,$B$10&D10,$B$11&D11,$B$12&D12,$B$13&D13,$B$14&D14,"cols=1;rows=247") | E17: =_xll.BDH(E3,E4,E5,E6,$B$7&E7,$B$8&E8,$B$9&E9,$B$10&E10,$B$11&E11,$B$12&E12,$B$13&E13,$B$14&E14,"cols=1;rows=247") | F17: =_xll.BDH(F3,F4,F5,F6,$B$7&F7,$B$8&F8,$B$9&F9,$B$10&F10,$B$11&F11,$B$12&F12,$B$13&F13,$B$14&F14,"cols=1;rows=247") | G17: =_xll.BDH(G3,G4,G5,G6,$B$7&G7,$B$8&G8,$B$9&G9,$B$10&G10,$B$11&G11,$B$12&G12,$B$13&G13,$B$14&G14,"cols=1;rows=247") | H17: =_xll.BDH(H3,H4,H5,H6,$B$7&H7,$B$8&H8,$B$9&H9,$B$10&H10,$B$11&H11,$B$12&H12,$B$13&H13,$B$14&H14,"cols=1;rows=247") | I17: =_xll.BDH(I3,I4,I5,I6,$B$7&I7,$B$8&I8,$B$9&I9,$B$10&I10,$B$11&I11,$B$12&I12,$B$13&I13,$B$14&I14,"cols=1;rows=247") | J17: =_xll.BDH(J3,J4,J5,J6,$B$7&J7,$B$8&J8,$B$9&J9,$B$10&J10,$B$11&J11,$B$12&J12,$B$13&J13,$B$14&J14,"cols=1;rows=247") | K17: =_xll.BDH(K3,K4,K5,K6,$B$7&K7,$B$8&K8,$B$9&K9,$B$10&K10,$B$11&K11,$B$12&K12,$B$13&K13,$B$14&K14,"cols=1;rows=247") | L17: =_xll.BDH(L3,L4,L5,L6,$B$7&L7,$B$8&L8,$B$9&L9,$B$10&L10,$B$11&L11,$B$12&L12,$B$13&L13,$B$14&L14,"cols=1;rows=247") -> 26.08
B18: 36556 | C18: 1371 | L18: 27.27
B19: 36585 | C19: 1393 | L19: 29.35
B20: 36616 | C20: 1621 | L20: 29.89
B21: 36644 | C21: 1667 | L21: 25.78
B22: 36677 | C22: 1602 | L22: 28.78
B23: 36707 | C23: 1589 | L23: 31.86
B24: 36738 | C24: 1618 | L24: 29.7
B25: 36769 | C25: 1639 | L25: 31.31
B26: 36798 | C26: 1712 | L26: 33.89
B27: 36830 | C27: 1734 | L27: 33.05
B28: 36860 | C28: 1722 | L28: 34.37
B29: 36889 | C29: 1609 | L29: 28.4
... B88: 38686 | C88: 2916 | L88: 58.28
B89: 38716 | C89: 2600 | H89: 1000 | L89: 59.41
B90: 38748 | C90: 2262 | H90: 1020.48 | L90: 65.48
B91: 38776 | C91: 2444 | H91: 1025.57 | L91: 61.62
B92: 38807 | C92: 2599 | H92: 1003.46 | L92: 62.89
B93: 38835 | C93: 2465 | H93: 1007.59 | L93: 69.54
B94: 38868 | C94: 2442 | H94: 984.88 | L94: 70.93
B95: 38898 | C95: 2718 | H95: 940.01 | L95: 70.93
B96: 38929 | C96: 3050 | H96: 1019.9 | L96: 74.4
B97: 38960 | C97: 3687 | H97: 1088.73 | L97: 73.04
B98: 38989 | C98: 4039 | H98: 1066.98 | L98: 63.82
...

Sheet data
B1: GDP | C1: GDPGOVT | D1: GDPPRIV | E1: GDPGFCF | F1: GDPX | G1: GDPM | H1: GPMGDP | I1: BALTIC | J1: WCIFREIGHT | K1: SHANGHAI | L1: WTI | M1: RS | N1: LTY | O1: REER | P1: CPI | Q1: CORE | R1: IPALL | S1: IPMINE | T1: IPUTIL | U1: IPCONST | V1: IPMANU | W1: UNR | X1: WAGE | Y1: LEAD | Z1: SALES_R | AA1: WHOLESALE | AB1: EXPORTS | AC1: IMPORTS | AD1: COINCI | AE1: CCI | AF1: PCI | AG1: PMI | AH1: PMIManu | AI1: PMINO | AJ1: PMIEMP | AK1: PMIDELI | AL1: PMIStocks | AM1: PMIIP | AN1: PMIPURCH | AO1: PMISTOCKS | AP1: PMINEO | AQ1: PMIMPRI | AR1: PMIBACK | AS1: STOCKS | AT1: PCONS | AU1: EAI | AV1: GFCF | AW1: TOURISM | AX1: OILPROD | AY1: OIL_X | AZ1: IMEFBC | BA1: NEWS
A2: 36556 | B2: =IF(ISNUMBER(INDEX(Haver_Q!$B$1:$BD$1000,MATCH(data!$A2,Haver_Q!$B$1:$B$1000,0),MATCH(data!B$1,Haver_Q!$B$1:$BD$1,0))),100*INDEX(Haver_Q!$B$1:$BD$1000,MATCH(data!$A2,Haver_Q!$B$1:$B$1000,0),MATCH(data!B$1,Haver_Q!$B$1:$BD$1,0)),"na") -> na | C2: =IF(ISNUMBER(INDEX(Haver_Q!$B$1:$BD$1000,MATCH(data!$A2,Haver_Q!$B$1:$B$1000,0),MATCH(data!C$1,Haver_Q!$B$1:$BD$1,0))),100*INDEX(Haver_Q!$B$1:$BD$1000,MATCH(data!$A2,Haver_Q!$B$1:$B$1000,0),MATCH(data!C$1,Haver_Q!$B$1:$BD$1,0)),"na") -> na | D2: =IF(ISNUMBER(INDEX(Haver_Q!$B$1:$BD$1000,MATCH(data!$A2,Haver_Q!$B$1:$B$1000,0),MATCH(data!D$1,Haver_Q!$B$1:$BD$1,0))),100*INDEX(Haver_Q!$B$1:$BD$1000,MATCH(data!$A2,Haver_Q!$B$1:$B$1000,0),MATCH(data!D$1,Haver_Q!$B$1:$BD$1,0)),"na") -> na | E2: =IF(ISNUMBER(INDEX(Haver_Q!$B$1:$BD$1000,MATCH(data!$A2,Haver_Q!$B$1:$B$1000,0),MATCH(data!E$1,Haver_Q!$B$1:$BD$1,0))),100*INDEX(Haver_Q!$B$1:$BD$1000,MATCH(data!$A2,Haver_Q!$B$1:$B$1000,0),MATCH(data!E$1,Haver_Q!$B$1:$BD$1,0)),"na") -> na | F2: =IF(ISNUMBER(INDEX(Haver_Q!$B$1:$BD$1000,MATCH(data!$A2,Haver_Q!$B$1:$B$1000,0),MATCH(data!F$1,Haver_Q!$B$1:$BD$1,0))),100*INDEX(Haver_Q!$B$1:$BD$1000,MATCH(data!$A2,Haver_Q!$B$1:$B$1000,0),MATCH(data!F$1,Haver_Q!$B$1:$BD$1,0)),"na") -> na | G2: =IF(ISNUMBER(INDEX(Haver_Q!$B$1:$BD$1000,MATCH(data!$A2,Haver_Q!$B$1:$B$1000,0),MATCH(data!G$1,Haver_Q!$B$1:$BD$1,0))),100*INDEX(Haver_Q!$B$1:$BD$1000,MATCH(data!$A2,Haver_Q!$B$1:$B$1000,0),MATCH(data!G$1,Haver_Q!$B$1:$BD$1,0)),"na") -> na | H2: =IF(ISNUMBER(INDEX(Haver_Q!$B$1:$BD$1000,MATCH(data!$A2,Haver_Q!$B$1:$B$1000,0),MATCH(data!H$1,Haver_Q!$B$1:$BD$1,0))),100*INDEX(Haver_Q!$B$1:$BD$1000,MATCH(data!$A2,Haver_Q!$B$1:$B$1000,0),MATCH(data!H$1,Haver_Q!$B$1:$BD$1,0)),"na") -> na | I2: =IF(ISNUMBER(Bloomberg_m!C18),Bloomberg_m!C18,"na") -> 1371 | J2: =IF(ISNUMBER(Bloomberg_m!D18),Bloomberg_m!D18,"na") -> na | K2: =IF(ISNUMBER(Bloomberg_m!E18),Bloomberg_m!E18,"na") -> na | L2: =IF(ISNUMBER(Bloomberg_m!L18),Bloomberg_m!L18,"na") -> 27.27 | M2: =IF(ISNUMBER(INDEX(Haver_M!$B$1:$ZN$1000,MATCH(data!$A2,Haver_M!$B$1:$B$1000,0),MATCH(data!M$1,Haver_M!$B$1:$ZN$1,0))),INDEX(Haver_M!$B$1:$ZN$1000,MATCH(data!$A2,Haver_M!$B$1:$B$1000,0),MATCH(data!M$1,Haver_M!$B$1:$ZN$1,0)),"na") -> na | N2: =IF(ISNUMBER(INDEX(Haver_M!$B$1:$ZN$1000,MATCH(data!$A2,Haver_M!$B$1:$B$1000,0),MATCH(data!N$1,Haver_M!$B$1:$ZN$1,0))),INDEX(Haver_M!$B$1:$ZN$1000,MATCH(data!$A2,Haver_M!$B$1:$B$1000,0),MATCH(data!N$1,Haver_M!$B$1:$ZN$1,0)),"na") -> na | O2: =IF(ISNUMBER(INDEX(Haver_M!$B$1:$ZN$1000,MATCH(data!$A2,Haver_M!$B$1:$B$1000,0),MATCH(data!O$1,Haver_M!$B$1:$ZN$1,0))),INDEX(Haver_M!$B$1:$ZN$1000,MATCH(data!$A2,Haver_M!$B$1:$B$1000,0),MATCH(data!O$1,Haver_M!$B$1:$ZN$1,0)),"na") -> 113.55455 | P2: =IF(ISNUMBER(INDEX(Haver_M!$B$1:$ZN$1000,MATCH(data!$A2,Haver_M!$B$1:$B$1000,0),MATCH(data!P$1,Haver_M!$B$1:$ZN$1,0))),INDEX(Haver_M!$B$1:$ZN$1000,MATCH(data!$A2,Haver_M!$B$1:$B$1000,0),MATCH(data!P$1,Haver_M!$B$1:$ZN$1,0)),"na") -> 44.6533 | Q2: =IF(ISNUMBER(INDEX(Haver_M!$B$1:$ZN$1000,MATCH(data!$A2,Haver_M!$B$1:$B$1000,0),MATCH(data!Q$1,Haver_M!$B$1:$ZN$1,0))),INDEX(Haver_M!$B$1:$ZN$1000,MATCH(data!$A2,Haver_M!$B$1:$B$1000,0),MATCH(data!Q$1,Haver_M!$B$1:$ZN$1,0)),"na") -> 48.932 | R2: =IF(ISNUMBER(INDEX(Haver_M!$B$1:$ZN$1000,MATCH(data!$A2,Haver_M!$B$1:$B$1000,0),MATCH(data!R$1,Haver_M!$B$1:$ZN$1,0))),INDEX(Haver_M!$B$1:$ZN$1000,MATCH(data!$A2,Haver_M!$B$1:$B$1000,0),MATCH(data!R$1,Haver_M!$B$1:$ZN$1,0)),"na") -> 89.3466 | S2: =IF(ISNUMBER(INDEX(Haver_M!$B$1:$ZN$1000,MATCH(data!$A2,Haver_M!$B$1:$B$1000,0),MATCH(data!S$1,Haver_M!$B$1:$ZN$1,0))),INDEX(Haver_M!$B$1:$ZN$1000,MATCH(data!$A2,Haver_M!$B$1:$B$1000,0),MATCH(data!S$1,Haver_M!$B$1:$ZN$1,0)),"na") -> 101.1315 | T2: =IF(ISNUMBER(INDEX(Haver_M!$B$1:$ZN$1000,MATCH(data!$A2,Haver_M!$B$1:$B$1000,0),MATCH(data!T$1,Haver_M!$B$1:$ZN$1,0))),INDEX(Haver_M!$B$1:$ZN$1000,MATCH(data!$A2,Haver_M!$B$1:$B$1000,0),MATCH(data!T$1,Haver_M!$B$1:$ZN$1,0)),"na") -> 53.8108 | ... BA2: =IF(ISNUMBER(INDEX(Haver_M!$B$1:$ZN$1000,MATCH(data!$A2,Haver_M!$B$1:$B$1000,0),MATCH(data!BA$1,Haver_M!$B$1:$ZN$1,0))),INDEX(Haver_M!$B$1:$ZN$1000,MATCH(data!$A2,Haver_M!$B$1:$B$1000,0),MATCH(data!BA$1,Haver_M!$B$1:$ZN$1,0)),"na") -> 129.33691 | BB2: =IF(ISNUMBER(INDEX(Haver_M!$B$1:$ZN$1000,MATCH(data!$A2,Haver_M!$B$1:$B$1000,0),MATCH(data!BB$1,Haver_M!$B$1:$ZN$1,0))),INDEX(Haver_M!$B$1:$ZN$1000,MATCH(data!$A2,Haver_M!$B$1:$B$1000,0),MATCH(data!BB$1,Haver_M!$B$1:$ZN$1,0)),"")
A3: 36585 | B3: =IF(ISNUMBER(INDEX(Haver_Q!$B$1:$BD$1000,MATCH(data!$A3,Haver_Q!$B$1:$B$1000,0),MATCH(data!B$1,Haver_Q!$B$1:$BD$1,0))),100*INDEX(Haver_Q!$B$1:$BD$1000,MATCH(data!$A3,Haver_Q!$B$1:$B$1000,0),MATCH(data!B$1,Haver_Q!$B$1:$BD$1,0)),"na") -> na | C3: =IF(ISNUMBER(INDEX(Haver_Q!$B$1:$BD$1000,MATCH(data!$A3,Haver_Q!$B$1:$B$1000,0),MATCH(data!C$1,Haver_Q!$B$1:$BD$1,0))),100*INDEX(Haver_Q!$B$1:$BD$1000,MATCH(data!$A3,Haver_Q!$B$1:$B$1000,0),MATCH(data!C$1,Haver_Q!$B$1:$BD$1,0)),"na") -> na | D3: =IF(ISNUMBER(INDEX(Haver_Q!$B$1:$BD$1000,MATCH(data!$A3,Haver_Q!$B$1:$B$1000,0),MATCH(data!D$1,Haver_Q!$B$1:$BD$1,0))),100*INDEX(Haver_Q!$B$1:$BD$1000,MATCH(data!$A3,Haver_Q!$B$1:$B$1000,0),MATCH(data!D$1,Haver_Q!$B$1:$BD$1,0)),"na") -> na | E3: =IF(ISNUMBER(INDEX(Haver_Q!$B$1:$BD$1000,MATCH(data!$A3,Haver_Q!$B$1:$B$1000,0),MATCH(data!E$1,Haver_Q!$B$1:$BD$1,0))),100*INDEX(Haver_Q!$B$1:$BD$1000,MATCH(data!$A3,Haver_Q!$B$1:$B$1000,0),MATCH(data!E$1,Haver_Q!$B$1:$BD$1,0)),"na") -> na | F3: =IF(ISNUMBER(INDEX(Haver_Q!$B$1:$BD$1000,MATCH(data!$A3,Haver_Q!$B$1:$B$1000,0),MATCH(data!F$1,Haver_Q!$B$1:$BD$1,0))),100*INDEX(Haver_Q!$B$1:$BD$1000,MATCH(data!$A3,Haver_Q!$B$1:$B$1000,0),MATCH(data!F$1,Haver_Q!$B$1:$BD$1,0)),"na") -> na | G3: =IF(ISNUMBER(INDEX(Haver_Q!$B$1:$BD$1000,MATCH(data!$A3,Haver_Q!$B$1:$B$1000,0),MATCH(data!G$1,Haver_Q!$B$1:$BD$1,0))),100*INDEX(Haver_Q!$B$1:$BD$1000,MATCH(data!$A3,Haver_Q!$B$1:$B$1000,0),MATCH(data!G$1,Haver_Q!$B$1:$BD$1,0)),"na") -> na | H3: =IF(ISNUMBER(INDEX(Haver_Q!$B$1:$BD$1000,MATCH(data!$A3,Haver_Q!$B$1:$B$1000,0),MATCH(data!H$1,Haver_Q!$B$1:$BD$1,0))),100*INDEX(Haver_Q!$B$1:$BD$1000,MATCH(data!$A3,Haver_Q!$B$1:$B$1000,0),MATCH(data!H$1,Haver_Q!$B$1:$BD$1,0)),"na") -> na | I3: =IF(ISNUMBER(Bloomberg_m!C19),Bloomberg_m!C19,"na") -> 1393 | J3: =IF(ISNUMBER(Bloomberg_m!D19),Bloomberg_m!D19,"na") -> na | K3: =IF(ISNUMBER(Bloomberg_m!E19),Bloomberg_m!E19,"na") -> na | L3: =IF(ISNUMBER(Bloomberg_m!L19),Bloomberg_m!L19,"na") -> 29.35 | M3: =IF(ISNUMBER(INDEX(Haver_M!$B$1:$ZN$1000,MATCH(data!$A3,Haver_M!$B$1:$B$1000,0),MATCH(data!M$1,Haver_M!$B$1:$ZN$1,0))),INDEX(Haver_M!$B$1:$ZN$1000,MATCH(data!$A3,Haver_M!$B$1:$B$1000,0),MATCH(data!M$1,Haver_M!$B$1:$ZN$1,0)),"na") -> na | N3: =IF(ISNUMBER(INDEX(Haver_M!$B$1:$ZN$1000,MATCH(data!$A3,Haver_M!$B$1:$B$1000,0),MATCH(data!N$1,Haver_M!$B$1:$ZN$1,0))),INDEX(Haver_M!$B$1:$ZN$1000,MATCH(data!$A3,Haver_M!$B$1:$B$1000,0),MATCH(data!N$1,Haver_M!$B$1:$ZN$1,0)),"na") -> na | O3: =IF(ISNUMBER(INDEX(Haver_M!$B$1:$ZN$1000,MATCH(data!$A3,Haver_M!$B$1:$B$1000,0),MATCH(data!O$1,Haver_M!$B$1:$ZN$1,0))),INDEX(Haver_M!$B$1:$ZN$1000,MATCH(data!$A3,Haver_M!$B$1:$B$1000,0),MATCH(data!O$1,Haver_M!$B$1:$ZN$1,0)),"na") -> 115.46699 | P3: =IF(ISNUMBER(INDEX(Haver_M!$B$1:$ZN$1000,MATCH(data!$A3,Haver_M!$B$1:$B$1000,0),MATCH(data!P$1,Haver_M!$B$1:$ZN$1,0))),INDEX(Haver_M!$B$1:$ZN$1000,MATCH(data!$A3,Haver_M!$B$1:$B$1000,0),MATCH(data!P$1,Haver_M!$B$1:$ZN$1,0)),"na") -> 44.999 | Q3: =IF(ISNUMBER(INDEX(Haver_M!$B$1:$ZN$1000,MATCH(data!$A3,Haver_M!$B$1:$B$1000,0),MATCH(data!Q$1,Haver_M!$B$1:$ZN$1,0))),INDEX(Haver_M!$B$1:$ZN$1000,MATCH(data!$A3,Haver_M!$B$1:$B$1000,0),MATCH(data!Q$1,Haver_M!$B$1:$ZN$1,0)),"na") -> 49.3 | R3: =IF(ISNUMBER(INDEX(Haver_M!$B$1:$ZN$1000,MATCH(data!$A3,Haver_M!$B$1:$B$1000,0),MATCH(data!R$1,Haver_M!$B$1:$ZN$1,0))),INDEX(Haver_M!$B$1:$ZN$1000,MATCH(data!$A3,Haver_M!$B$1:$B$1000,0),MATCH(data!R$1,Haver_M!$B$1:$ZN$1,0)),"na") -> 89.9714 | S3: =IF(ISNUMBER(INDEX(Haver_M!$B$1:$ZN$1000,MATCH(data!$A3,Haver_M!$B$1:$B$1000,0),MATCH(data!S$1,Haver_M!$B$1:$ZN$1,0))),INDEX(Haver_M!$B$1:$ZN$1000,MATCH(data!$A3,Haver_M!$B$1:$B$1000,0),MATCH(data!S$1,Haver_M!$B$1:$ZN$1,0)),"na") -> 99.6387 | T3: =IF(ISNUMBER(INDEX(Haver_M!$B$1:$ZN$1000,MATCH(data!$A3,Haver_M!$B$1:$B$1000,0),MATCH(data!T$1,Haver_M!$B$1:$ZN$1,0))),INDEX(Haver_M!$B$1:$ZN$1000,MATCH(data!$A3,Haver_M!$B$1:$B$1000,0),MATCH(data!T$1,Haver_M!$B$1:$ZN$1,0)),"na") -> 54.6009 | ... BA3: =IF(ISNUMBER(INDEX(Haver_M!$B$1:$ZN$1000,MATCH(data!$A3,Haver_M!$B$1:$B$1000,0),MATCH(data!BA$1,Haver_M!$B$1:$ZN$1,0))),INDEX(Haver_M!$B$1:$ZN$1000,MATCH(data!$A3,Haver_M!$B$1:$B$1000,0),MATCH(data!BA$1,Haver_M!$B$1:$ZN$1,0)),"na") -> 182.08916 | BB3: =IF(ISNUMBER(INDEX(Haver_M!$B$1:$ZN$1000,MATCH(data!$A3,Haver_M!$B$1:$B$1000,0),MATCH(data!BB$1,Haver_M!$B$1:$ZN$1,0))),INDEX(Haver_M!$B$1:$ZN$1000,MATCH(data!$A3,Haver_M!$B$1:$B$1000,0),MATCH(data!BB$1,Haver_M!$B$1:$ZN$1,0)),"")
A4: 36616 | B4: =IF(ISNUMBER(INDEX(Haver_Q!$B$1:$BD$1000,MATCH(data!$A4,Haver_Q!$B$1:$B$1000,0),MATCH(data!B$1,Haver_Q!$B$1:$BD$1,0))),100*INDEX(Haver_Q!$B$1:$BD$1000,MATCH(data!$A4,Haver_Q!$B$1:$B$1000,0),MATCH(data!B$1,Haver_Q!$B$1:$BD$1,0)),"na") -> 7.8908208 | C4: =IF(ISNUMBER(INDEX(Haver_Q!$B$1:$BD$1000,MATCH(data!$A4,Haver_Q!$B$1:$B$1000,0),MATCH(data!C$1,Haver_Q!$B$1:$BD$1,0))),100*INDEX(Haver_Q!$B$1:$BD$1000,MATCH(data!$A4,Haver_Q!$B$1:$B$1000,0),MATCH(data!C$1,Haver_Q!$B$1:$BD$1,0)),"na") -> 12.149992 | D4: =IF(ISNUMBER(INDEX(Haver_Q!$B$1:$BD$1000,MATCH(data!$A4,Haver_Q!$B$1:$B$1000,0),MATCH(data!D$1,Haver_Q!$B$1:$BD$1,0))),100*INDEX(Haver_Q!$B$1:$BD$1000,MATCH(data!$A4,Haver_Q!$B$1:$B$1000,0),MATCH(data!D$1,Haver_Q!$B$1:$BD$1,0)),"na") -> 9.6004588 | E4: =IF(ISNUMBER(INDEX(Haver_Q!$B$1:$BD$1000,MATCH(data!$A4,Haver_Q!$B$1:$B$1000,0),MATCH(data!E$1,Haver_Q!$B$1:$BD$1,0))),100*INDEX(Haver_Q!$B$1:$BD$1000,MATCH(data!$A4,Haver_Q!$B$1:$B$1000,0),MATCH(data!E$1,Haver_Q!$B$1:$BD$1,0)),"na") -> 14.079916 | F4: =IF(ISNUMBER(INDEX(Haver_Q!$B$1:$BD$1000,MATCH(data!$A4,Haver_Q!$B$1:$B$1000,0),MATCH(data!F$1,Haver_Q!$B$1:$BD$1,0))),100*INDEX(Haver_Q!$B$1:$BD$1000,MATCH(data!$A4,Haver_Q!$B$1:$B$1000,0),MATCH(data!F$1,Haver_Q!$B$1:$BD$1,0)),"na") -> 17.042392 | G4: =IF(ISNUMBER(INDEX(Haver_Q!$B$1:$BD$1000,MATCH(data!$A4,Haver_Q!$B$1:$B$1000,0),MATCH(data!G$1,Haver_Q!$B$1:$BD$1,0))),100*INDEX(Haver_Q!$B$1:$BD$1000,MATCH(data!$A4,Haver_Q!$B$1:$B$1000,0),MATCH(data!G$1,Haver_Q!$B$1:$BD$1,0)),"na") -> 27.54633 | H4: =IF(ISNUMBER(INDEX(Haver_Q!$B$1:$BD$1000,MATCH(data!$A4,Haver_Q!$B$1:$B$1000,0),MATCH(data!H$1,Haver_Q!$B$1:$BD$1,0))),100*INDEX(Haver_Q!$B$1:$BD$1000,MATCH(data!$A4,Haver_Q!$B$1:$B$1000,0),MATCH(data!H$1,Haver_Q!$B$1:$BD$1,0)),"na") -> 533.84295 | I4: =IF(ISNUMBER(Bloomberg_m!C20),Bloomberg_m!C20,"na") -> 1621 | J4: =IF(ISNUMBER(Bloomberg_m!D20),Bloomberg_m!D20,"na") -> na | K4: =IF(ISNUMBER(Bloomberg_m!E20),Bloomberg_m!E20,"na") -> na | L4: =IF(ISNUMBER(Bloomberg_m!L20),Bloomberg_m!L20,"na") -> 29.89 | M4: =IF(ISNUMBER(INDEX(Haver_M!$B$1:$ZN$1000,MATCH(data!$A4,Haver_M!$B$1:$B$1000,0),MATCH(data!M$1,Haver_M!$B$1:$ZN$1,0))),INDEX(Haver_M!$B$1:$ZN$1000,MATCH(data!$A4,Haver_M!$B$1:$B$1000,0),MATCH(data!M$1,Haver_M!$B$1:$ZN$1,0)),"na") -> na | N4: =IF(ISNUMBER(INDEX(Haver_M!$B$1:$ZN$1000,MATCH(data!$A4,Haver_M!$B$1:$B$1000,0),MATCH(data!N$1,Haver_M!$B$1:$ZN$1,0))),INDEX(Haver_M!$B$1:$ZN$1000,MATCH(data!$A4,Haver_M!$B$1:$B$1000,0),MATCH(data!N$1,Haver_M!$B$1:$ZN$1,0)),"na") -> na | O4: =IF(ISNUMBER(INDEX(Haver_M!$B$1:$ZN$1000,MATCH(data!$A4,Haver_M!$B$1:$B$1000,0),MATCH(data!O$1,Haver_M!$B$1:$ZN$1,0))),INDEX(Haver_M!$B$1:$ZN$1000,MATCH(data!$A4,Haver_M!$B$1:$B$1000,0),MATCH(data!O$1,Haver_M!$B$1:$ZN$1,0)),"na") -> 117.33534 | P4: =IF(ISNUMBER(INDEX(Haver_M!$B$1:$ZN$1000,MATCH(data!$A4,Haver_M!$B$1:$B$1000,0),MATCH(data!P$1,Haver_M!$B$1:$ZN$1,0))),INDEX(Haver_M!$B$1:$ZN$1000,MATCH(data!$A4,Haver_M!$B$1:$B$1000,0),MATCH(data!P$1,Haver_M!$B$1:$ZN$1,0)),"na") -> 45.3135 | Q4: =IF(ISNUMBER(INDEX(Haver_M!$B$1:$ZN$1000,MATCH(data!$A4,Haver_M!$B$1:$B$1000,0),MATCH(data!Q$1,Haver_M!$B$1:$ZN$1,0))),INDEX(Haver_M!$B$1:$ZN$1000,MATCH(data!$A4,Haver_M!$B$1:$B$1000,0),MATCH(data!Q$1,Haver_M!$B$1:$ZN$1,0)),"na") -> 49.5671 | R4: =IF(ISNUMBER(INDEX(Haver_M!$B$1:$ZN$1000,MATCH(data!$A4,Haver_M!$B$1:$B$1000,0),MATCH(data!R$1,Haver_M!$B$1:$ZN$1,0))),INDEX(Haver_M!$B$1:$ZN$1000,MATCH(data!$A4,Haver_M!$B$1:$B$1000,0),MATCH(data!R$1,Haver_M!$B$1:$ZN$1,0)),"na") -> 89.9666 | S4: =IF(ISNUMBER(INDEX(Haver_M!$B$1:$ZN$1000,MATCH(data!$A4,Haver_M!$B$1:$B$1000,0),MATCH(data!S$1,Haver_M!$B$1:$ZN$1,0))),INDEX(Haver_M!$B$1:$ZN$1000,MATCH(data!$A4,Haver_M!$B$1:$B$1000,0),MATCH(data!S$1,Haver_M!$B$1:$ZN$1,0)),"na") -> 101.1593 | T4: =IF(ISNUMBER(INDEX(Haver_M!$B$1:$ZN$1000,MATCH(data!$A4,Haver_M!$B$1:$B$1000,0),MATCH(data!T$1,Haver_M!$B$1:$ZN$1,0))),INDEX(Haver_M!$B$1:$ZN$1000,MATCH(data!$A4,Haver_M!$B$1:$B$1000,0),MATCH(data!T$1,Haver_M!$B$1:$ZN$1,0)),"na") -> 55.207 | ... BA4: =IF(ISNUMBER(INDEX(Haver_M!$B$1:$ZN$1000,MATCH(data!$A4,Haver_M!$B$1:$B$1000,0),MATCH(data!BA$1,Haver_M!$B$1:$ZN$1,0))),INDEX(Haver_M!$B$1:$ZN$1000,MATCH(data!$A4,Haver_M!$B$1:$B$1000,0),MATCH(data!BA$1,Haver_M!$B$1:$ZN$1,0)),"na") -> 119.76352 | BB4: =IF(ISNUMBER(INDEX(Haver_M!$B$1:$ZN$1000,MATCH(data!$A4,Haver_M!$B$1:$B$1000,0),MATCH(data!BB$1,Haver_M!$B$1:$ZN$1,0))),INDEX(Haver_M!$B$1:$ZN$1000,MATCH(data!$A4,Haver_M!$B$1:$B$1000,0),MATCH(data!BB$1,Haver_M!$B$1:$ZN$1,0)),"")
A5: 36646 | B5: =IF(ISNUMBER(INDEX(Haver_Q!$B$1:$BD$1000,MATCH(data!$A5,Haver_Q!$B$1:$B$1000,0),MATCH(data!B$1,Haver_Q!$B$1:$BD$1,0))),100*INDEX(Haver_Q!$B$1:$BD$1000,MATCH(data!$A5,Haver_Q!$B$1:$B$1000,0),MATCH(data!B$1,Haver_Q!$B$1:$BD$1,0)),"na") -> na | C5: =IF(ISNUMBER(INDEX(Haver_Q!$B$1:$BD$1000,MATCH(data!$A5,Haver_Q!$B$1:$B$1000,0),MATCH(data!C$1,Haver_Q!$B$1:$BD$1,0))),100*INDEX(Haver_Q!$B$1:$BD$1000,MATCH(data!$A5,Haver_Q!$B$1:$B$1000,0),MATCH(data!C$1,Haver_Q!$B$1:$BD$1,0)),"na") -> na | D5: =IF(ISNUMBER(INDEX(Haver_Q!$B$1:$BD$1000,MATCH(data!$A5,Haver_Q!$B$1:$B$1000,0),MATCH(data!D$1,Haver_Q!$B$1:$BD$1,0))),100*INDEX(Haver_Q!$B$1:$BD$1000,MATCH(data!$A5,Haver_Q!$B$1:$B$1000,0),MATCH(data!D$1,Haver_Q!$B$1:$BD$1,0)),"na") -> na | E5: =IF(ISNUMBER(INDEX(Haver_Q!$B$1:$BD$1000,MATCH(data!$A5,Haver_Q!$B$1:$B$1000,0),MATCH(data!E$1,Haver_Q!$B$1:$BD$1,0))),100*INDEX(Haver_Q!$B$1:$BD$1000,MATCH(data!$A5,Haver_Q!$B$1:$B$1000,0),MATCH(data!E$1,Haver_Q!$B$1:$BD$1,0)),"na") -> na | F5: =IF(ISNUMBER(INDEX(Haver_Q!$B$1:$BD$1000,MATCH(data!$A5,Haver_Q!$B$1:$B$1000,0),MATCH(data!F$1,Haver_Q!$B$1:$BD$1,0))),100*INDEX(Haver_Q!$B$1:$BD$1000,MATCH(data!$A5,Haver_Q!$B$1:$B$1000,0),MATCH(data!F$1,Haver_Q!$B$1:$BD$1,0)),"na") -> na | G5: =IF(ISNUMBER(INDEX(Haver_Q!$B$1:$BD$1000,MATCH(data!$A5,Haver_Q!$B$1:$B$1000,0),MATCH(data!G$1,Haver_Q!$B$1:$BD$1,0))),100*INDEX(Haver_Q!$B$1:$BD$1000,MATCH(data!$A5,Haver_Q!$B$1:$B$1000,0),MATCH(data!G$1,Haver_Q!$B$1:$BD$1,0)),"na") -> na | H5: =IF(ISNUMBER(INDEX(Haver_Q!$B$1:$BD$1000,MATCH(data!$A5,Haver_Q!$B$1:$B$1000,0),MATCH(data!H$1,Haver_Q!$B$1:$BD$1,0))),100*INDEX(Haver_Q!$B$1:$BD$1000,MATCH(data!$A5,Haver_Q!$B$1:$B$1000,0),MATCH(data!H$1,Haver_Q!$B$1:$BD$1,0)),"na") -> na | I5: =IF(ISNUMBER(Bloomberg_m!C21),Bloomberg_m!C21,"na") -> 1667 | J5: =IF(ISNUMBER(Bloomberg_m!D21),Bloomberg_m!D21,"na") -> na | K5: =IF(ISNUMBER(Bloomberg_m!E21),Bloomberg_m!E21,"na") -> na | L5: =IF(ISNUMBER(Bloomberg_m!L21),Bloomberg_m!L21,"na") -> 25.78 | M5: =IF(ISNUMBER(INDEX(Haver_M!$B$1:$ZN$1000,MATCH(data!$A5,Haver_M!$B$1:$B$1000,0),MATCH(data!M$1,Haver_M!$B$1:$ZN$1,0))),INDEX(Haver_M!$B$1:$ZN$1000,MATCH(data!$A5,Haver_M!$B$1:$B$1000,0),MATCH(data!M$1,Haver_M!$B$1:$ZN$1,0)),"na") -> na | N5: =IF(ISNUMBER(INDEX(Haver_M!$B$1:$ZN$1000,MATCH(data!$A5,Haver_M!$B$1:$B$1000,0),MATCH(data!N$1,Haver_M!$B$1:$ZN$1,0))),INDEX(Haver_M!$B$1:$ZN$1000,MATCH(data!$A5,Haver_M!$B$1:$B$1000,0),MATCH(data!N$1,Haver_M!$B$1:$ZN$1,0)),"na") -> na | O5: =IF(ISNUMBER(INDEX(Haver_M!$B$1:$ZN$1000,MATCH(data!$A5,Haver_M!$B$1:$B$1000,0),MATCH(data!O$1,Haver_M!$B$1:$ZN$1,0))),INDEX(Haver_M!$B$1:$ZN$1000,MATCH(data!$A5,Haver_M!$B$1:$B$1000,0),MATCH(data!O$1,Haver_M!$B$1:$ZN$1,0)),"na") -> 116.90303 | P5: =IF(ISNUMBER(INDEX(Haver_M!$B$1:$ZN$1000,MATCH(data!$A5,Haver_M!$B$1:$B$1000,0),MATCH(data!P$1,Haver_M!$B$1:$ZN$1,0))),INDEX(Haver_M!$B$1:$ZN$1000,MATCH(data!$A5,Haver_M!$B$1:$B$1000,0),MATCH(data!P$1,Haver_M!$B$1:$ZN$1,0)),"na") -> 45.5985 | Q5: =IF(ISNUMBER(INDEX(Haver_M!$B$1:$ZN$1000,MATCH(data!$A5,Haver_M!$B$1:$B$1000,0),MATCH(data!Q$1,Haver_M!$B$1:$ZN$1,0))),INDEX(Haver_M!$B$1:$ZN$1000,MATCH(data!$A5,Haver_M!$B$1:$B$1000,0),MATCH(data!Q$1,Haver_M!$B$1:$ZN$1,0)),"na") -> 49.8246 | R5: =IF(ISNUMBER(INDEX(Haver_M!$B$1:$ZN$1000,MATCH(data!$A5,Haver_M!$B$1:$B$1000,0),MATCH(data!R$1,Haver_M!$B$1:$ZN$1,0))),INDEX(Haver_M!$B$1:$ZN$1000,MATCH(data!$A5,Haver_M!$B$1:$B$1000,0),MATCH(data!R$1,Haver_M!$B$1:$ZN$1,0)),"na") -> 90.3034 | S5: =IF(ISNUMBER(INDEX(Haver_M!$B$1:$ZN$1000,MATCH(data!$A5,Haver_M!$B$1:$B$1000,0),MATCH(data!S$1,Haver_M!$B$1:$ZN$1,0))),INDEX(Haver_M!$B$1:$ZN$1000,MATCH(data!$A5,Haver_M!$B$1:$B$1000,0),MATCH(data!S$1,Haver_M!$B$1:$ZN$1,0)),"na") -> 103.7515 | T5: =IF(ISNUMBER(INDEX(Haver_M!$B$1:$ZN$1000,MATCH(data!$A5,Haver_M!$B$1:$B$1000,0),MATCH(data!T$1,Haver_M!$B$1:$ZN$1,0))),INDEX(Haver_M!$B$1:$ZN$1000,MATCH(data!$A5,Haver_M!$B$1:$B$1000,0),MATCH(data!T$1,Haver_M!$B$1:$ZN$1,0)),"na") -> 54.9528 | ... BA5: =IF(ISNUMBER(INDEX(Haver_M!$B$1:$ZN$1000,MATCH(data!$A5,Haver_M!$B$1:$B$1000,0),MATCH(data!BA$1,Haver_M!$B$1:$ZN$1,0))),INDEX(Haver_M!$B$1:$ZN$1000,MATCH(data!$A5,Haver_M!$B$1:$B$1000,0),MATCH(data!BA$1,Haver_M!$B$1:$ZN$1,0)),"na") -> 108.51464 | BB5: =IF(ISNUMBER(INDEX(Haver_M!$B$1:$ZN$1000,MATCH(data!$A5,Haver_M!$B$1:$B$1000,0),MATCH(data!BB$1,Haver_M!$B$1:$ZN$1,0))),INDEX(Haver_M!$B$1:$ZN$1000,MATCH(data!$A5,Haver_M!$B$1:$B$1000,0),MATCH(data!BB$1,Haver_M!$B$1:$ZN$1,0)),"")
